Workbook

Sheet 2018 raw
A1: idBeneficiaire | B1: montant | C1: nomBénéficiaire | D1: referenceDecision | E1: dateConvention | F1: objet | G1: nature | H1: conditionsVerse ment | I1: datesPériodeVersement | J1: idRAE | K1: notification UE | L1: pourcenta geSubvent ion
A2: PUBLICATION DU 28/02/2018
A3: ADIL (asso. départ. pour information sur logement) | B3: 97 740,00 | C3: 305378234 | D3: 2017/739_2017-11-24 | E3: 43069 | F3: fonctionnement | G3: aide en numéraire | H3: échelonné | I3: 2017-11-30_2018-05-30 | J3: sans objet | K3: non | L3: 1
A4: COMPAGNONS BATISSEURS | B4: 95 932,00 | C4: 488566613 | D4: 2017/837_2017-12-22 | E4: 43091 | F4: actions de formation | G4: aide en numéraire | H4: échelonné | I4: 2017-12-22_2018-06-22 | J4: sans objet | K4: non | L4: 1
A5: FABRIQUE POLA | B5: 114 000,00 | C5: 444337588 | D5: 2017/747_2017-11-24 | E5: 43112 | F5: fonctionnement 2017 | G5: aide en numéraire | H5: échelonné | I5: 2018-01-12_2018-07-12 | J5: sans objet | K5: non | L5: 1
A6: UNML (UNION NATIONALE DES MISSIONS LOCALES) | B6: 5 000,00 | C6: 434066577 | D6: 2017/686_2017-11-24 | E6: 43077 | F6: fonctionnement | G6: aide en numéraire | H6: échelonné | I6: 2017-12-08_2018-06-08 | J6: sans objet | K6: non | L6: 1
A7: ADMAA (ASSO DEFENSE MUSIQUES ALTERNATIVES) | B7: 40 000,00 | C7: 489563072 | D7: 2017/348_2017-05-19 | E7: 43133 | F7: été métropolitain 2017 | G7: aide en numéraire | H7: échelonné | I7: 2018-02-02_2018-08-08 | J7: sans objet | K7: non | L7: 1
A8: PUBLICATION DU 26/04/2018
A9: COS PERSONNEL Bordeaux Metropole | B9: 1 680 000,00 | C9: 483013405 | D9: 2017/810_2017-12-22 | E9: 43091 | F9: fonctionnement | G9: aide en numéraire | H9: échelonné | I9: 2017-12-22_2018-06-22 | J9: sans objet | K9: non | L9: 1
A10: UFASEC | B10: 10 870,00 | C10: 789105954 | D10: 2017/800_2017-22-12 | E10: 43091 | F10: fonctionnement | G10: aide en numéraire | H10: 1 versement | I10: 2017-12-22_2018-06-22 | J10: sans objet | K10: non | L10: 1
A11: ARTS & LOISIRS D'ARLAC | B11: 7 900,00 | C11: 306040312 | D11: 2017/603_2017-11-24 | E11: 43130 | F11: fonctionnement | G11: aide en numéraire | H11: échelonné | I11: 2018-01-30_2018-07-30 | J11: sans objet | K11: non | L11: 1
A12: CIJA | B12: 32 000,00 | C12: 306564279 | D12: 2018/001_2018-01-26 | E12: 43126 | F12: fonctionnement | G12: aide en numéraire | H12: échelonné | I12: 2018-01-26_2018-26-07 | J12: sans objet | K12: non | L12: 1
A13: MÉMOIRE DE BORDEAUX | B13: 96 187,50 | C13: 342215456 | D13: 2018/002_2018-01-26 | E13: 43126 | F13: fonctionnement | G13: aide en numéraire | H13: échelonné | I13: 2018-01-26_2018-07-26 | J13: sans objet | K13: non | L13: 1
A14: AURBA | B14: 4 372 007,00 | C14: 781814488 | D14: 2017/833_2017-12-22 | E14: 43136 | F14: fonctionnement | G14: aide en numéraire | H14: échelonné | I14: 2018-02-05_2018-07-05- | J14: sans objet | K14: non | L14: 1
A15: UBM | B15: 77 000,00 | C15: 418921409 | D15: 2017/801_2017-12-22 | E15: 43143 | F15: fonctionnement | G15: aide en numéraire | H15: échelonné | I15: 2018-02-12_2018-08-02 | J15: sans objet | K15: non | L15: 1
A16: JIB (JUMPING INTERNATIONAL DE BORDEAUX) | B16: 34 000,00 | C16: 420252348 | D16: 2018/003_2018-01-26 | E16: 43160 | F16: 22e salon du cheval | G16: aide en numéraire | H16: échelonné | I16: 2018-03-01_2018-09-01 | J16: sans objet | K16: non | L16: 1
A17: CSDL (caisse sociale de dév local) | B17: 38 000,00 | C17: 419009105 | D17: 2017/204_2017-04-14 | E17: 43161 | F17: fonctionnement | G17: aide en numéraire | H17: échelonné | I17: 2018-03-02_2018-09-02 | J17: sans objet | K17: non | L17: 1
A18: PAIN ET PARTAGE SAS | B18: 60 000,00 | C18: 832333181 | D18: 2018/005_2018-01-26 | E18: 43161 | F18: aide à l'investissement | G18: aide en numéraire | H18: échelonné | I18: 2018-03-02_2018-09-02 | J18: sans objet | K18: non | L18: 1
A19: FABRIQUE POLA | B19: 114 000,00 | C19: 444337588 | D19: 2018/41_2018-01-26 | E19: 43172 | F19: fonctionnement | G19: aide en numéraire | H19: échelonné | I19: 2018-03-13_2018-10-13 | J19: sans objet | K19: non | L19: 1
A20: MUSIQUES DE NUIT DIFFUSION | B20: 35 000,00 | C20: 341693190 | D20: 2018-42_2018-01-26 | E20: 43174 | F20: Festival afro new bell | G20: aide en numéraire | H20: échelonné | I20: 2018-03-15_2018-09-15 | J20: sans objet | K20: non | L20: 1
A21: idBeneficiaire | B21: montant | C21: nomBénéficiaire | D21: referenceDecision | E21: dateConvention | F21: objet | G21: nature | H21: conditionsVerse ment | I21: datesPériodeVersement | J21: idRAE | K21: notification UE | L21: pourcenta geSubvent ion
A22: ASSO EUROPEENNE DU FILM ANIMATION | B22: 150 000,00 | C22: 509079794 | D22: 2018/49_2018-02-16 | E22: 43185 | F22: Cartoon movie | G22: aide en numéraire | H22: échelonné | I22: 2018-03-26_2018-09-26 | J22: sans objet | K22: non | L22: 1
A23: PUBLICATION du 03/07/2018
A24: UNIS CITES | B24: 49 000,00 | C24: 398191569 | D24: 2017/736_2018-01-17 | E24: 43124 | F24: fonctionnement | G24: aide en numéraire | H24: échelonné | I24: 2018-01-24_2018-07-24 | J24: sans objet | K24: non | L24: 1
A25: STADE BORDELAIS ASPTT | B25: 65 000,00 | C25: 781843594 | D25: 2017/184_2018-03-23 | E25: 43182 | F25: marathon 2018 | G25: aide en numéraire | H25: échelonné | I25: 2018-03-23_2018-09-23 | J25: sans objet | K25: non | L25: 1
A26: SEMER LE DOUTE | B26: 15 000,00 | C26: 533896825 | D26: 2018/182_2018-03-23 | E26: 43222 | F26: FIFIB le coureur 2018 | G26: aide en numéraire | H26: échelonné | I26: 2018-05-02_2018-11-02 | J26: sans objet | K26: non | L26: 1
A27: SUPERCOOP SAS | B27: 24 176,00 | C27: 825241318 | D27: 2018/103_2018-03-23 | E27: 43208 | F27: fonctionnement | G27: aide en numéraire | H27: échelonné | I27: 2018-04-18_2018-10-18 | J27: sans objet | K27: non | L27: 1
A28: ALEC agence locale de l'énergie | B28: 137 000,00 | C28: 495009441 | D28: 2018/278_2018-04-27 | E28: 43235 | F28: fonctionnement | G28: aide en numéraire | H28: échelonné | I28: 2018-05-15_2018-11-15 | J28: sans objet | K28: non | L28: 1
A29: BORDEAUX OPEN AIR | B29: 10 000,00 | C29: 821354933 | D29: 2018/283_2018-04-27 | E29: 43244 | F29: été métropolitain | G29: aide en numéraire | H29: échelonné | I29: 2018-05-24_2018-11-24 | J29: sans objet | K29: non | L29: 1
A30: IDDAC | B30: 17 500,00 | C30: 383890233 | D30: 2018/177_2018-03-23 | E30: 43248 | F30: journées juniors dév.durable (JDD) | G30: aide en numéraire | H30: échelonné | I30: 2018-05-28_2018-11-28 | J30: sans objet | K30: non | L30: 1
A31: TRAFIC | B31: 10 000,00 | C31: 789632254 | D31: 2018/283_2018-04-27 | E31: 43250 | F31: été métropolitain | G31: aide en numéraire | H31: échelonné | I31: 2018-05-30_2018-11-30 | J31: sans objet | K31: non | L31: 1
A32: ARIANE PRODUCTIONS | B32: 9 610,00 | C32: 438794034 | D32: 2018/283_2018-04-27 | E32: 43244 | F32: été métropolitain | G32: aide en numéraire | H32: échelonné | I32: 2018-05-24_2018-11-24 | J32: sans objet | K32: non | L32: 1
A33: CSDL (caisse sociale dév local) | B33: 38 000,00 | C33: 419009105 | D33: 2018/208-2018-04-27 | E33: 43252 | F33: ESS | G33: aide en numéraire | H33: échelonné | I33: 2018-06-01_2018-12-01 | J33: sans objet | K33: non | L33: 1
A34: IDDAC | B34: 17 000,00 | C34: 383890233 | D34: 2018/283_2018-04-27 | E34: 43252 | F34: été métropolitain | G34: aide en numéraire | H34: échelonné | I34: 2018-06-01_2018-12-01 | J34: sans objet | K34: non | L34: 1
A35: ATIS | B35: 42 750,00 | C35: 522896091 | D35: 2018/208-2018-04-27 | E35: 43255 | F35: ESS | G35: aide en numéraire | H35: échelonné | I35: 2018-06-04_2018-12-04 | J35: sans objet | K35: non | L35: 1
... A43: THE DESK | B43: 11 000,00 | C43: 824274781 | D43: 2018/283_2018-04-27 | E43: 43252 | F43: été métropolitain | G43: aide en numéraire | H43: échelonné | I43: 2018-06-01_2018-12-01 | J43: sans objet | K43: non | L43: 1
A44: idBeneficiaire | B44: montant | C44: nomBénéficiaire | D44: referenceDecision | E44: dateConvention | F44: objet | G44: nature | H44: conditionsVerse ment | I44: datesPériodeVersement | J44: idRAE | K44: notification UE | L44: pourcenta geSubvent ion
A45: SEMER LE DOUTE | B45: 26 000,00 | C45: 533896825 | D45: 2018/284_2018-04-27 | E45: 43257 | F45: contrat codev | G45: aide en numéraire | H45: échelonné | I45: 2018-06-06_2018-12-06 | J45: sans objet | K45: non | L45: 1
A46: LETTRES DU MONDE | B46: 5 000,00 | C46: 452274798 | D46: 2018/283_2018-04-27 | E46: 43250 | F46: été métropolitain | G46: aide en numéraire | H46: échelonné | I46: 2018-05-30_2018-11-30 | J46: sans objet | K46: non | L46: 1
A47: L'IRREGULIERE | B47: 8 000,00 | C47: 833920077 | D47: 2018/283_2018-04-27 | E47: 43257 | F47: été métropolitain | G47: aide en numéraire | H47: échelonné | I47: 2018-06-06_2018-12-06 | J47: sans objet | K47: non | L47: 1
...

Sheet etape1
A1: idBeneficiaire | B1: montant | E1: nomBénéficiaire | F1: referenceDecision | G1: dateConvention | H1: objet | I1: nature | J1: conditionsVerse ment | K1: datesPériodeVersement | L1: idRAE | M1: notification UE | N1: pourcenta geSubvent ion
A2: idBeneficiaire | B2: montant | C2: =substitute(SUBSTITUTE(B2," ",""),",",".") -> montant | E2: nomBénéficiaire | F2: referenceDecision | G2: dateConvention | H2: objet | I2: nature | J2: conditionsVerse ment | K2: datesPériodeVersement | L2: idRAE | M2: notification UE | N2: pourcenta geSubvent ion
A3: idBeneficiaire | B3: montant | C3: =substitute(SUBSTITUTE(B3," ",""),",",".") -> montant | E3: nomBénéficiaire | F3: referenceDecision | G3: dateConvention | H3: objet | I3: nature | J3: conditionsVerse ment | K3: datesPériodeVersement | L3: idRAE | M3: notification UE | N3: pourcenta geSubvent ion
A4: idBeneficiaire | B4: montant | C4: =substitute(SUBSTITUTE(B4," ",""),",",".") -> montant | E4: nomBénéficiaire | F4: referenceDecision | G4: dateConvention | H4: objet | I4: nature | J4: conditionsVerse ment | K4: datesPériodeVersement | L4: idRAE | M4: notification UE | N4: pourcenta geSubvent ion
A5: idBeneficiaire | B5: montant | C5: =substitute(SUBSTITUTE(B5," ",""),",",".") -> montant | E5: nomBénéficiaire | F5: referenceDecision | G5: dateConvention | H5: objet | I5: nature | J5: conditionsVerse ment | K5: datesPériodeVersement | L5: idRAE | M5: notification UE | N5: pourcenta geSubvent ion
A6: idBeneficiaire | B6: montant | C6: =substitute(SUBSTITUTE(B6," ",""),",",".") -> montant | E6: nomBénéficiaire | F6: referenceDecision | G6: dateConvention | H6: objet | I6: nature | J6: conditionsVerse ment | K6: datesPériodeVersement | L6: idRAE | M6: notification UE | N6: pourcenta geSubvent ion
A7: idBeneficiaire | B7: montant | C7: =substitute(SUBSTITUTE(B7," ",""),",",".") -> montant | E7: nomBénéficiaire | F7: referenceDecision | G7: dateConvention | H7: objet | I7: nature | J7: conditionsVerse ment | K7: datesPériodeVersement | L7: idRAE | M7: notification UE | N7: pourcenta geSubvent ion
A8: idBeneficiaire | B8: montant | C8: =substitute(SUBSTITUTE(B8," ",""),",",".") -> montant | E8: nomBénéficiaire | F8: referenceDecision | G8: dateConvention | H8: objet | I8: nature | J8: conditionsVerse ment | K8: datesPériodeVersement | L8: idRAE | M8: notification UE | N8: pourcenta geSubvent ion
A9: idBeneficiaire | B9: montant | C9: =substitute(SUBSTITUTE(B9," ",""),",",".") -> montant | E9: nomBénéficiaire | F9: referenceDecision | G9: dateConvention | H9: objet | I9: nature | J9: conditionsVerse ment | K9: datesPériodeVersement | L9: idRAE | M9: notification UE | N9: pourcenta geSubvent ion
A10: LA MECANIQUE GENERALE | B10: 9 900,00 | C10: =substitute(SUBSTITUTE(B10," ",""),",",".") -> 9900.00 | E10: 824698500 | F10: 2018/283_2018-04-27 | G10: 43266 | H10: fonctionnement | I10: aide en numéraire | J10: échelonné | K10: 2018-06-15_2018-12-15 | L10: sans objet | M10: non | N10: 1
A11: ADIL (asso. départ. pour information sur logement) | B11: 97 740,00 | C11: =substitute(SUBSTITUTE(B11," ",""),",",".") -> 97740.00 | D11: 97740 | E11: 305378234 | F11: 2017/739_2017-11-24 | G11: 43069 | H11: fonctionnement | I11: aide en numéraire | J11: échelonné | K11: 2017-11-30_2018-05-30 | L11: sans objet | M11: non | N11: 1
A12: MÉMOIRE DE BORDEAUX | B12: 96 187,50 | C12: =substitute(SUBSTITUTE(B12," ",""),",",".") -> 96187.50 | D12: 96187.5 | E12: 342215456 | F12: 2018/002_2018-01-26 | G12: 43126 | H12: fonctionnement | I12: aide en numéraire | J12: échelonné | K12: 2018-01-26_2018-07-26 | L12: sans objet | M12: non | N12: 1
A13: ARIANE PRODUCTIONS | B13: 9 610,00 | C13: =substitute(SUBSTITUTE(B13," ",""),",",".") -> 9610.00 | D13: 9610 | E13: 438794034 | F13: 2018/283_2018-04-27 | G13: 43244 | H13: été métropolitain | I13: aide en numéraire | J13: échelonné | K13: 2018-05-24_2018-11-24 | L13: sans objet | M13: non | N13: 1
A14: COMPAGNONS BATISSEURS | B14: 95 932,00 | C14: =substitute(SUBSTITUTE(B14," ",""),",",".") -> 95932.00 | D14: 95932 | E14: 488566613 | F14: 2017/837_2017-12-22 | G14: 43091 | H14: actions de formation | I14: aide en numéraire | J14: échelonné | K14: 2017-12-22_2018-06-22 | L14: sans objet | M14: non | N14: 1
A15: LETTRES DU MONDE | B15: 9 500,00 | C15: =substitute(SUBSTITUTE(B15," ",""),",",".") -> 9500.00 | D15: 9500 | E15: 45227479800035 | F15: 2018/587_2018-09-28 | G15: 43406 | H15: manifestation création littéraire | I15: aide en numéraire | J15: échelonné | K15: 2018-11-02_2019-05-02 | L15: sans objet | M15: non | N15: 1
A16: AEROSPACE VALLEY | B16: 90 000,00 | C16: =substitute(SUBSTITUTE(B16," ",""),",",".") -> 90000.00 | D16: 90000 | E16: 48428452600072 | F16: 2018/487_2018-09-28 | G16: 43417 | H16: fonctionnement | I16: aide en numéraire | J16: échelonné | K16: 2018-11-13_2019-05-13 | L16: sans objet | M16: non | N16: 1
A17: CREAC DE BEGLES | B17: 9 000,00 | C17: =substitute(SUBSTITUTE(B17," ",""),",",".") -> 9000.00 | D17: 9000 | E17: 37809063300017 | F17: 2018/367-2018-06-15 | G17: 43306 | H17: programme d'actions | I17: aide en numéraire | J17: échelonné | K17: 2018-07-25_2019-01-25 | L17: sans objet | M17: non | N17: 1
A18: CCIB | B18: 9 000,00 | C18: =substitute(SUBSTITUTE(B18," ",""),",",".") -> 9000.00 | D18: 9000 | E18: 13002285800019 | F18: 2018/380_2018-07-06 | G18: 43342 | H18: Manacom | I18: aide en numéraire | J18: échelonné | K18: 2018-08-30_2019-02-30 | L18: sans objet | M18: non | N18: 1
A19: ADAV 33 | B19: 87 400,00 | C19: =substitute(SUBSTITUTE(B19," ",""),",",".") -> 87400.00 | D19: 87400 | E19: 30091783800025 | F19: 2018/579_2018-09-28 | G19: 43385 | H19: fonctionnement | I19: aide en numéraire | J19: échelonné | K19: 2018-10-12_2019-04-12 | L19: sans objet | M19: non | N19: 1
A20: CCIB | B20: 8 500,00 | C20: =substitute(SUBSTITUTE(B20," ",""),",",".") -> 8500.00 | D20: 8500 | E20: 13002285800018 | F20: 2018/380_2018-07-06 | G20: 43342 | H20: Ronde de Gironde | I20: aide en numéraire | J20: échelonné | K20: 2018-08-30_2019-02-30 | L20: sans objet | M20: non | N20: 1
A21: L'IRREGULIERE | B21: 8 000,00 | C21: =substitute(SUBSTITUTE(B21," ",""),",",".") -> 8000.00 | D21: 8000 | E21: 833920077 | F21: 2018/283_2018-04-27 | G21: 43257 | H21: été métropolitain | I21: aide en numéraire | J21: échelonné | K21: 2018-06-06_2018-12-06 | L21: sans objet | M21: non | N21: 1
A22: DATCHA | B22: 8 000,00 | C22: =substitute(SUBSTITUTE(B22," ",""),",",".") -> 8000.00 | D22: 8000 | E22: 811411560 | F22: 2018/283_2018-04-27 | G22: 43263 | H22: été metropolitain | I22: aide en numéraire | J22: échelonné | K22: 2018-06-12_2018-12-12 | L22: sans objet | M22: non | N22: 1
... A150: MOM'OUEST | B150: 10 000,00 | C150: =substitute(SUBSTITUTE(B150," ",""),",",".") -> 10000.00 | D150: 10000 | E150: 82213407800010 | F150: 2018/302-2018-06-15 | G150: 43299 | H150: investissement | I150: aide en numéraire | J150: échelonné | K150: 2018-07-18_2018-01-18 | L150: sans objet | M150: non | N150: 1
A151: IUFM | B151: 10 000,00 | C151: =substitute(SUBSTITUTE(B151," ",""),",",".") -> 10000.00 | D151: 10000 | E151: 75198395800024 | F151: 2018/178_2018-03-23 | G151: 43276 | H151: transition énergétique | I151: aide en numéraire | J151: échelonné | K151: 2018-06-25_2018-12-25 | L151: sans objet | M151: non | N151: 1-
A152: COMPAGNONS BATISSEURS | B152: 10 000,00 | C152: =substitute(SUBSTITUTE(B152," ",""),",",".") -> 10000.00 | D152: 10000 | E152: 48856661300037 | F152: 2018/40_2018-01-26 | G152: 43285 | H152: plateforme SOLIBAT | I152: aide en numéraire | J152: échelonné | K152: 2018-07-04_2019-01-04 | L152: sans objet | M152: non | N152: 1
A153: PUBLICATION DU 26/04/2018 | C153: =substitute(SUBSTITUTE(B153," ",""),",",".")
A154: PUBLICATION du 03/07/2018 | C154: =substitute(SUBSTITUTE(B154," ",""),",",".")
A155: PUBLICATION du 18/09/2018 | C155: =substitute(SUBSTITUTE(B155," ",""),",",".")
A156: PUBLICATION du 20 novembre 2018 | C156: =substitute(SUBSTITUTE(B156," ",""),",",".")
A157: PUBLICATION DU 28/02/2018 | C157: =substitute(SUBSTITUTE(B157," ",""),",",".")

Sheet etape2
A1: idBeneficiaire | B1: montant | C1: nomBénéficiaire | D1: referenceDecision | E1: dateConvention | F1: objet | G1: nature | H1: conditionsVerse ment | I1: datesPériodeVersement | J1: idRAE | K1: notification UE | L1: pourcenta geSubvent ion
A2: AURBA | B2: 4372007 | C2: 781814488 | D2: 2017/833_2017-12-22 | E2: 43136 | F2: fonctionnement | G2: aide en numéraire | H2: échelonné | I2: 2018-02-05_2018-07-05- | J2: sans objet | K2: non | L2: 1
A3: OTCM Office Tourisme & Congrès Métropolitains | B3: 3000000 | C3: 78180455400017 | D3: 2018/48_2018-02-16 | E3: 43145 | F3: fonctionnement | G3: aide en numéraire | H3: échelonné | I3: 2018-02-14_2018-08-14 | J3: sans objet | K3: non | L3: 1
A4: COS PERSONNEL Bordeaux Metropole | B4: 1680000 | C4: 483013405 | D4: 2017/810_2017-12-22 | E4: 43091 | F4: fonctionnement | G4: aide en numéraire | H4: échelonné | I4: 2017-12-22_2018-06-22 | J4: sans objet | K4: non | L4: 1
A5: BORDEAUX TECHNOWEST | B5: 420000 | C5: 37781852100025 | D5: 2018/368-2018-07-06 | E5: 43306 | F5: fonctionnement | G5: aide en numéraire | H5: échelonné | I5: 2018-07-25_2019-01-25 | J5: sans objet | K5: non | L5: 1
A6: ARC EN REVE | B6: 407253 | C6: 321237034 | D6: 2018/161_2018-03-23 | E6: 43259 | F6: fonctionnement | G6: aide en numéraire | H6: échelonné | I6: 2018-06-08_2018-12-08 | J6: sans objet | K6: non | L6: 1
A7: INVEST IN BORDEAUX | B7: 332775 | C7: 409199817 | D7: 2018/283-2018-04-27 | E7: 43271 | F7: fonctionnement | G7: aide en numéraire | H7: échelonné | I7: 2018-06-20_2018-12-20 | J7: sans objet | K7: non | L7: 1
A8: CAP SCIENCES | B8: 320000 | C8: 39988425300036 | D8: 2018/359_2018-07-06 | E8: 43353 | F8: fonctionnement | G8: aide en numéraire | H8: échelonné | I8: 2018-09-10_2019-03-10 | J8: sans objet | K8: non | L8: 1
A9: MAISON DE L'EMPLOI DE BX | B9: 230000 | C9: 49058526200069 | D9: 2018/99_2018-03-23 | E9: 43182 | F9: fonctionnement | G9: aide en numéraire | H9: échelonné | I9: 2018-03-23_2018-09-23 | J9: sans objet | K9: non | L9: 1
A10: BORDEAUX GRANDS EVENEMENTS | B10: 200000 | C10: 48875025800011 | D10: 2018/200-2018-04-27 | E10: 43285 | F10: fête du vin 2018 | G10: aide en numéraire | H10: échelonné | I10: 2018-07-04_2019-01-04 | J10: sans objet | K10: non | L10: 1
A11: FRENCHTECH | B11: 180000 | C11: 818313264 | D11: 2018/195_2018-04-27 | E11: 43271 | F11: fonctionnement | G11: aide en numéraire | H11: échelonné | I11: 2018-06-20_2018-12-20 | J11: sans objet | K11: non | L11: 1
A12: AGENCE DEVELOP. TOURISTIQUE GDE | B12: 180000 | C12: 78184375000048 | D12: 2018/50_2018-02-16 | E12: 43182 | F12: fonctionnement | G12: aide en numéraire | H12: échelonné | I12: 2018-03-23_2018-09-23 | J12: sans objet | K12: non | L12: 1
A13: FESTIVAL DES ARTS DE BORDEAUX FAB | B13: 160000 | C13: 420089567 | D13: 2018/284_2018-04-27 | E13: 43269 | F13: codev festival | G13: aide en numéraire | H13: échelonné | I13: 2018-06-18_2018-12-18 | J13: sans objet | K13: non | L13: 1
... A110: MOM'OUEST | B110: 10000 | C110: 82213407800010 | D110: 2018/302-2018-06-15 | E110: 43299 | F110: investissement | G110: aide en numéraire | H110: échelonné | I110: 2018-07-18_2018-01-18 | J110: sans objet | K110: non | L110: 1
A111: IUFM | B111: 10000 | C111: 75198395800024 | D111: 2018/178_2018-03-23 | E111: 43276 | F111: transition énergétique | G111: aide en numéraire | H111: échelonné | I111: 2018-06-25_2018-12-25 | J111: sans objet | K111: non | L111: 1-
A112: COMPAGNONS BATISSEURS | B112: 10000 | C112: 48856661300037 | D112: 2018/40_2018-01-26 | E112: 43285 | F112: plateforme SOLIBAT | G112: aide en numéraire | H112: échelonné | I112: 2018-07-04_2019-01-04 | J112: sans objet | K112: non | L112: 1
A113: ARIANE PRODUCTIONS | B113: 9610 | C113: 438794034 | D113: 2018/283_2018-04-27 | E113: 43244 | F113: été métropolitain | G113: aide en numéraire | H113: échelonné | I113: 2018-05-24_2018-11-24 | J113: sans objet | K113: non | L113: 1
A114: LETTRES DU MONDE | B114: 9500 | C114: 45227479800035 | D114: 2018/587_2018-09-28 | E114: 43406 | F114: manifestation création littéraire | G114: aide en numéraire | H114: échelonné | I114: 2018-11-02_2019-05-02 | J114: sans objet | K114: non | L114: 1
A115: CREAC DE BEGLES | B115: 9000 | C115: 37809063300017 | D115: 2018/367-2018-06-15 | E115: 43306 | F115: programme d'actions | G115: aide en numéraire | H115: échelonné | I115: 2018-07-25_2019-01-25 | J115: sans objet | K115: non | L115: 1
A116: CCIB | B116: 9000 | C116: 13002285800019 | D116: 2018/380_2018-07-06 | E116: 43342 | F116: Manacom | G116: aide en numéraire | H116: échelonné | I116: 2018-08-30_2019-02-30 | J116: sans objet | K116: non | L116: 1
A117: CCIB | B117: 8500 | C117: 13002285800018 | D117: 2018/380_2018-07-06 | E117: 43342 | F117: Ronde de Gironde | G117: aide en numéraire | H117: échelonné | I117: 2018-08-30_2019-02-30 | J117: sans objet | K117: non | L117: 1
A118: L'IRREGULIERE | B118: 8000 | C118: 833920077 | D118: 2018/283_2018-04-27 | E118: 43257 | F118: été métropolitain | G118: aide en numéraire | H118: échelonné | I118: 2018-06-06_2018-12-06 | J118: sans objet | K118: non | L118: 1
A119: DATCHA | B119: 8000 | C119: 811411560 | D119: 2018/283_2018-04-27 | E119: 43263 | F119: été metropolitain | G119: aide en numéraire | H119: échelonné | I119: 2018-06-12_2018-12-12 | J119: sans objet | K119: non | L119: 1
A120: MELI MEL ARTS | B120: 8000 | C120: 524259363 | D120: 2018/284_2018-04-27 | E120: 43283 | F120: codev festival | G120: aide en numéraire | H120: échelonné | I120: 2018-07-02_2019-01-02 | J120: sans objet | K120: non | L120: 1
A121: PRINC'ESS | B121: 8000 | C121: 83176796700019 | D121: 2018/302-2018-06-15 | E121: 43353 | F121: invest. immobilier | G121: aide en numéraire | H121: échelonné | I121: 2018-09-10_2019-03-10 | J121: sans objet | K121: non | L121: 1
A122: ARTS & LOISIRS D'ARLAC | B122: 7900 | C122: 306040312 | D122: 2017/603_2017-11-24 | E122: 43130 | F122: fonctionnement | G122: aide en numéraire | H122: échelonné | I122: 2018-01-30_2018-07-30 | J122: sans objet | K122: non | L122: 1
A123: ECOSITE DU BOURGAILH | B123: 7700 | C123: 444932446 | D123: 2018/294_2018-04-27 | E123: 43257 | F123: été métropolitain | G123: aide en numéraire | H123: échelonné | I123: 2018-06-06_2018-12-06 | J123: sans objet | K123: non | L123: 1
... A143: COOP ALPHA | B143: 1500 | C143: 48237148100029 | D143: 2018/40_2018-01-26 | E143: 43368 | F143: appel ZZ zéro déchets | G143: aide en numéraire | H143: 1 versement | I143: 2018-09-25_2019-03-25 | J143: sans objet | K143: non | L143: 1
A144: LA MECANIQUE GENERALE | C144: 824698500 | D144: 2018/283_2018-04-27 | E144: 43266 | F144: fonctionnement | G144: aide en numéraire | H144: échelonné | I144: 2018-06-15_2018-12-15 | J144: sans objet | K144: non | L144: 1

Sheet 2019 raw
A1: datepublication | B1: nomAttribuant | C1: idAttribuant | D1: dateConvention | E1: referenceDecision | F1: nomBénéficiaire | G1: idBeneficiaire | H1: objet | I1: montant | J1: nature | K1: conditionsVerse ment | L1: datesPériodeVersement | M1: idRAE | N1: notificationU E | O1: pourcentageS ubvention
A2: 43502 | B2: BORDEAUX METROPOLE | C2: 24330031600011 | D2: 43382 | E2: 2018/040 | F2: GIHP INSERT PERS HAND | G2: 31231100400039 | H2: Zéro déchets | I2: 5000 | J2: aide en numéraire | K2: unique | L2: 2018-10-09/2019-04-09 | M2: sans objet | N2: non | O2: 1
A3: 43502 | B3: BORDEAUX METROPOLE | C3: 24330031600011 | D3: 43298 | E3: 2018/288 | F3: ASSO LEONARD DE VINCI | G3: 40285022600018 | H3: Big Data | I3: 25000 | J3: aide en numéraire | K3: échelonné | L3: 2018-07-17/2019-01-17 | M3: sans objet | N3: non | O3: 1
A4: 43502 | B4: BORDEAUX METROPOLE | C4: 24330031600011 | D4: 43413 | E4: 2018/573 | F4: ADIL 33 | G4: 30537823400036 | H4: Fonctionnement | I4: 97740 | J4: aide en numéraire | K4: échelonné | L4: 2018-11-09/2019-05-09 | M4: sans objet | N4: non | O4: 1
A5: 43502 | B5: BORDEAUX METROPOLE | C5: 24330031600011 | D5: 43171 | E5: 2017/799 | F5: BMSL | G5: 39484466600013 | H5: Fonctionnement | I5: 88000 | J5: aide en numéraire | K5: échelonné | L5: 2018-03-12/2018-09-12 | M5: sans objet | N5: non | O5: 1
A6: 43502 | B6: BORDEAUX METROPOLE | C6: 24330031600011 | D6: 43363 | E6: 2018/40 | F6: TERRE D'ADELE | G6: 48782378300013 | H6: Zéro déchets | I6: 10000 | J6: aide en numéraire | K6: unique | L6: 2018-09-20/2019-03-20 | M6: sans objet | N6: non | O6: 1
A7: 43502 | B7: BORDEAUX METROPOLE | C7: 24330031600011 | D7: 43444 | E7: 2018/597 | F7: NANTES SUMMERCAMP | G7: 81195928700012 | H7: SOFILM | I7: 225000 | J7: aide en numéraire | K7: échelonné | L7: 2018-12-10/2019-06-10 | M7: sans objet | N7: non | O7: 1
A8: 43502 | B8: BORDEAUX METROPOLE | C8: 24330031600011 | D8: 43454 | E8: 2018/570 | F8: SOLIHA SOLIDAIRE HABITAT | G8: 78184854400032 | H8: Fonctionnement | I8: 216000 | J8: aide en numéraire | K8: échelonné | L8: 2018-12-20/2019-06-20 | M8: sans objet | N8: non | O8: 1
A9: 43502 | B9: BORDEAUX METROPOLE | C9: 24330031600011 | D9: 43452 | E9: 2018/601 | F9: LE LIVRE VERT | G9: 79493089100013 | H9: investissement | I9: 15000 | J9: aide en numéraire | K9: échelonné | L9: 2018-12-18/2019-06-18 | M9: sans objet | N9: non | O9: 1
A10: 43502 | B10: BORDEAUX METROPOLE | C10: 24330031600011 | D10: 43482 | E10: 2018/678 | F10: CARREFOURS POUR L'EMPLOI | G10: 43294548300035 | H10: Fonctionnement | I10: 18000 | J10: aide en numéraire | K10: échelonné | L10: 2019-01-17/2019-07-17 | M10: sans objet | N10: non | O10: 1
A11: 43502 | B11: BORDEAUX METROPOLE | C11: 24330031600011 | D11: 43489 | E11: 2018/578 | F11: WIMOOV GIRONDE | G11: 42213614300068 | H11: plateforme mobilité | I11: 55000 | J11: aide en numéraire | K11: échelonné | L11: 2019-01-24/2019-07-24 | M11: sans objet | N11: non | O11: 1
A12: 43502 | B12: BORDEAUX METROPOLE | C12: 24330031600011 | D12: 43480 | E12: 2018/649 | F12: AGENCE QUALITE CONSTRUCTION AQC | G12: 32721569500047 | H12: Bien construire | I12: 49000 | J12: aide en numéraire | K12: échelonné | L12: 2019-01-15/2019-07-15 | M12: sans objet | N12: non | O12: 1
A13: 43502 | B13: BORDEAUX METROPOLE | C13: 24330031600011 | D13: 43367 | E13: 2015/488 | F13: SIMOREP ET CIE | G13: 32852574600017 | H13: investissement projet butterfly | I13: 400000 | J13: aide en numéraire | K13: échelonné | L13: 2018-09-24/2019-03-24 | M13: sans objet | N13: non | O13: 1
... A26: 43557 | B26: BORDEAUX METROPOLE | C26: 24330031600011 | D26: 43532 | E26: 2019/65 | F26: OFFICE TOURISME & CONGRES BORDEAUX | G26: 78180455400017 | H26: Fonctionnement | I26: 3000000 | J26: aide en numéraire | K26: échelonné | L26: 2019-03-08/2019-09-08 | M26: sans objet | N26: non | O26: 1
A27: datepublication | B27: nomAttribuant | C27: idAttribuant | D27: dateConvention | E27: referenceDecision | F27: nomBénéficiaire | G27: idBeneficiaire | H27: objet | I27: montant | J27: nature | K27: conditionsVerse ment | L27: datesPériodeVersement | M27: idRAE | N27: notificationU E | O27: pourcentageS ubvention
A28: 43557 | B28: BORDEAUX METROPOLE | C28: 24330031600011 | D28: 43532 | E28: 2019/69 | F28: LE LAB | G28: 84217399900017 | H28: investissement travaux Lormont | I28: 7000 | J28: aide en numéraire | K28: échelonné | L28: 2019-03-08/2019-09-08 | M28: sans objet | N28: non | O28: 1
A29: 43557 | B29: BORDEAUX METROPOLE | C29: 24330031600011 | D29: 43535 | E29: 2019/53 | F29: ESPRIT DE CORPS | G29: 42008956700036 | H29: festival POUCE | I29: 20000 | J29: aide en numéraire | K29: échelonné | L29: 2019-03-11/2019-09-11 | M29: sans objet | N29: non | O29: 1
A30: 43557 | B30: BORDEAUX METROPOLE | C30: 24330031600011 | D30: 43532 | E30: 2019/63 | F30: AFEPT | G30: 30016423300029 | H30: Fonctionnement | I30: 58000 | J30: aide en numéraire | K30: échelonné | L30: 2019-03-08/2019-09-08 | M30: sans objet | N30: non | O30: 1
A31: 43557 | B31: BORDEAUX METROPOLE | C31: 24330031600011 | D31: 43500 | E31: 2019/53 | F31: PARALLELES ATTITUDE DIFFUSION | G31: 35011886500017 | H31: carnaval des 2 rives | I31: 15000 | J31: aide en numéraire | K31: échelonné | L31: 2019-02-04/2019-08-04 | M31: sans objet | N31: non | O31: 1
A32: 43557 | B32: BORDEAUX METROPOLE | C32: 24330031600011 | D32: 43518 | E32: 2019/53 | F32: CHAHUTS | G32: 40265285300069 | H32: LES ARTS DE LA PAROLE | I32: 35000 | J32: aide en numéraire | K32: échelonné | L32: 2019-02-22/2019-08-22 | M32: sans objet | N32: non | O32: 1
A33: 43557 | B33: BORDEAUX METROPOLE | C33: 24330031600011 | D33: 43508 | E33: 2019/53 | F33: MUSIQUES DE NUIT DIFFUSION | G33: 34169319000033 | H33: festival Hauts de garonne | I33: 25000 | J33: aide en numéraire | K33: échelonné | L33: 2019-02-12/2019-08-12 | M33: sans objet | N33: non | O33: 1
A34: 43557 | B34: BORDEAUX METROPOLE | C34: 24330031600011 | D34: 43441 | E34: 2018/664 | F34: MUSIQUES DE NUIT DIFFUSION | G34: 34169319000033 | H34: journées afro contemporaines | I34: 33250 | J34: aide en numéraire | K34: échelonné | L34: 2018-12-07/2019-06-07 | M34: sans objet | N34: non | O34: 1
A35: 43557 | B35: BORDEAUX METROPOLE | C35: 24330031600011 | D35: 43523 | E35: 43647 | F35: JUMPING INTERNATIONAL | G35: 42052348000016 | H35: Jumping | I35: 34000 | J35: aide en numéraire | K35: échelonné | L35: 2019-02-27/2019-08-27 | M35: sans objet | N35: non | O35: 1
A36: 43557 | B36: BORDEAUX METROPOLE | C36: 24330031600011 | D36: 43521 | E36: 2019/53 | F36: LES ARTS AU MUR | G36: 43434085700037 | H36: Arthothèque | I36: 15000 | J36: aide en numéraire | K36: échelonné | L36: 2019-02-25/2019-08-25 | M36: sans objet | N36: non | O36: 1
A37: 43557 | B37: BORDEAUX METROPOLE | C37: 24330031600011 | D37: 43530 | E37: 2019/45 | F37: AURBA | G37: 78181448800040 | H37: Fonctionnement | I37: 4372000 | J37: aide en numéraire | K37: échelonné | L37: 2019-03-06/2019-09-06 | M37: sans objet | N37: non | O37: 1
A38: 43557 | B38: BORDEAUX METROPOLE | C38: 24330031600011 | D38: 43530 | E38: 2019/53 | F38: ASSO FESTIVAL ODP | G38: 82343035000012 | H38: Festival ODP codev | I38: 40000 | J38: aide en numéraire | K38: échelonné | L38: 2019-03-06/2019-09-06 | M38: sans objet | N38: non | O38: 1
A39: 43557 | B39: BORDEAUX METROPOLE | C39: 24330031600011 | D39: 43531 | E39: 2019/64 | F39: MAISON EMPLOI INSERT ECO ENTREP. | G39: 49058526200069 | H39: Fonctionnement | I39: 230000 | J39: aide en numéraire | K39: échelonné | L39: 2019-03-07/2019-09-07 | M39: sans objet | N39: non | O39: 1
A40: 43557 | B40: BORDEAUX METROPOLE | C40: 24330031600011 | D40: 43532 | E40: 2019/92 | F40: ALEC | G40: 49500944100033 | H40: déploiement PCAET | I40: 82800 | J40: aide en numéraire | K40: échelonné | L40: 2019-03-08/2019-09-08 | M40: sans objet | N40: non | O40: 1
A41: 43557 | B41: BORDEAUX METROPOLE | C41: 24330031600011 | D41: 43514 | E41: 2019/66 | F41: AGENCE DEVELOPPEMENT TOURISTIQUE | G41: 78184375000048 | H41: Fonctionnement | I41: 180000 | J41: aide en numéraire | K41: échelonné | L41: 2019-02-18/2019-08-18 | M41: sans objet | N41: non | O41: 1
A42: 43557 | B42: BORDEAUX METROPOLE | C42: 24330031600011 | D42: 43511 | E42: 2019/77 | F42: MÉMOIRE DE BORDEAUX | G42: 34221545600043 | H42: Fonctionnement | I42: 91379 | J42: aide en numéraire | K42: échelonné | L42: 2019-02-15/2019-08-15 | M42: sans objet | N42: non | O42: 1
A43: 43557 | B43: BORDEAUX METROPOLE | C43: 24330031600011 | D43: 43514 | E43: 2019/60 | F43: ASSO.EUROPEENNE DU FILM ANIMATION | G43: 50907979400012 | H43: CARTOON MOVIE | I43: 150000 | J43: aide en numéraire | K43: échelonné | L43: 2019-02-18/2019-08-18 | M43: sans objet | N43: non | O43: 1
A44: 43636 | B44: BORDEAUX METROPOLE | C44: 24330031600011 | D44: 43557 | E44: 2019/68 | F44: LA PLANCHE | G44: 84474944000013 | H44: Investissement tiers lieu | I44: 27500 | J44: aide en numéraire | K44: échelonné | L44: 2019-04-02/2019-10-02 | M44: sans objet | N44: non | O44: 1
A45: 43636 | B45: BORDEAUX METROPOLE | C45: 24330031600011 | D45: 43556 | E45: 2019/172 | F45: ADEM | G45: 39811228400011 | H45: DECASTAR | I45: 58000 | J45: aide en numéraire | K45: échelonné | L45: 2019-04-01/2019-10-01 | M45: sans objet | N45: non | O45: 1
A46: 43636 | B46: BORDEAUX METROPOLE | C46: 24330031600011 | D46: 43574 | E46: 2019/106 | F46: CCI BORDEAUX GIRONDE | G46: 13002285800018 | H46: Fonds de soutien aux commerçants | I46: 500000 | J46: aide en numéraire | K46: échelonné | L46: 2019-04-19/2019-10-19 | M46: sans objet | N46: non | O46: 1
A47: 43636 | B47: BORDEAUX METROPOLE | C47: 24330031600011 | D47: 43579 | E47: 2018/578 | F47: SAMPE France | G47: 48428659600032 | H47: Action journées techniques | I47: 5000 | J47: aide en numéraire | K47: échelonné | L47: 2019-04-24/2019-10-24 | M47: sans objet | N47: non | O47: 1
... A49: 43636 | B49: BORDEAUX METROPOLE | C49: 24330031600011 | D49: 43546 | E49: 2019/143 | F49: CLUB CAP COM | G49: 78886877600022 | H49: FORUM | I49: 30000 | J49: aide en numéraire | K49: échelonné | L49: 2019-03-22/2019-09-22 | M49: sans objet | N49: non | O49: 1
A50: datepublication | B50: nomAttribuant | C50: idAttribuant | D50: dateConvention | E50: referenceDecision | F50: nomBénéficiaire | G50: idBeneficiaire | H50: objet | I50: montant | J50: nature | K50: conditionsVerse ment | L50: datesPériodeVersement | M50: idRAE | N50: notificationU E | O50: pourcentageS ubvention
A51: 43636 | B51: BORDEAUX METROPOLE | C51: 24330031600011 | D51: 43606 | E51: 2019/263 | F51: LETTRES DU MONDE | G51: 45227479800035 | H51: IN SITU ÉTÉ METROPOLITAIN | I51: 6000 | J51: aide en numéraire | K51: échelonné | L51: 2019-05-21/2019-11-21 | M51: sans objet | N51: non | O51: 1
A52: 43636 | B52: BORDEAUX METROPOLE | C52: 24330031600011 | D52: 43585 | E52: 2019/165 | F52: LEON A VELO | G52: 82959066000017 | H52: Fonctionnement | I52: 55000 | J52: aide en numéraire | K52: échelonné | L52: 2019-04-30/2019-10-30 | M52: sans objet | N52: non | O52: 1
A53: 43636 | B53: BORDEAUX METROPOLE | C53: 24330031600011 | D53: 43600 | E53: 2019/247 | F53: VELO CITE | G53: 43288382500031 | H53: FETE DU VELO | I53: 5000 | J53: aide en numéraire | K53: unique | L53: 2019-05-15/2019-11-15 | M53: sans objet | N53: non | O53: 1
...

Sheet 2018 clean 1
A1: idBeneficiaire | B1: idBeneficiaire_clean | C1: nomBénéficiaire | D1: referenceDecision | E1: dateConvention | F1: objet | G1: montant | H1: montant_clean | I1: nature | J1: conditionsVerse ment | K1: datesPériodeVersement | L1: idRAE | M1: notification UE | N1: pourcenta geSubvent ion
A2: PUBLICATION DU 28/02/2018
A3: ADIL (asso. départ. pour information sur logement) | B3: =SUBSTITUTE(A3,char(10)," ") -> ADIL (asso. départ. pour information sur logement) | C3: 305378234 | D3: 2017/739_2017-11-24 | E3: 43069 | F3: fonctionnement | G3: 97 740,00 | H3: =substitute( SUBSTITUTE(G3," ",""),",",".") -> 97740.00 | I3: aide en numéraire | J3: échelonné | K3: 2017-11-30_2018-05-30 | L3: sans objet | M3: non | N3: 1
A4: COMPAGNONS BATISSEURS | B4: =SUBSTITUTE(A4,char(10)," ") -> COMPAGNONS BATISSEURS | C4: 488566613 | D4: 2017/837_2017-12-22 | E4: 43091 | F4: actions de formation | G4: 95 932,00 | H4: =substitute( SUBSTITUTE(G4," ",""),",",".") -> 95932.00 | I4: aide en numéraire | J4: échelonné | K4: 2017-12-22_2018-06-22 | L4: sans objet | M4: non | N4: 1
A5: FABRIQUE POLA | B5: =SUBSTITUTE(A5,char(10)," ") -> FABRIQUE POLA | C5: 444337588 | D5: 2017/747_2017-11-24 | E5: 43112 | F5: fonctionnement 2017 | G5: 114 000,00 | H5: =substitute( SUBSTITUTE(G5," ",""),",",".") -> 114000.00 | I5: aide en numéraire | J5: échelonné | K5: 2018-01-12_2018-07-12 | L5: sans objet | M5: non | N5: 1
A6: UNML (UNION NATIONALE DES MISSIONS LOCALES) | B6: =SUBSTITUTE(A6,char(10)," ") -> UNML (UNION NATIONALE DES MISSIONS LOCALES) | C6: 434066577 | D6: 2017/686_2017-11-24 | E6: 43077 | F6: fonctionnement | G6: 5 000,00 | H6: =substitute( SUBSTITUTE(G6," ",""),",",".") -> 5000.00 | I6: aide en numéraire | J6: échelonné | K6: 2017-12-08_2018-06-08 | L6: sans objet | M6: non | N6: 1
A7: ADMAA (ASSO DEFENSE MUSIQUES ALTERNATIVES) | B7: =SUBSTITUTE(A7,char(10)," ") -> ADMAA (ASSO DEFENSE MUSIQUES ALTERNATIVES) | C7: 489563072 | D7: 2017/348_2017-05-19 | E7: 43133 | F7: été métropolitain 2017 | G7: 40 000,00 | H7: =substitute( SUBSTITUTE(G7," ",""),",",".") -> 40000.00 | I7: aide en numéraire | J7: échelonné | K7: 2018-02-02_2018-08-08 | L7: sans objet | M7: non | N7: 1
A8: PUBLICATION DU 26/04/2018 | B8: =SUBSTITUTE(A8,char(10)," ") -> PUBLICATION DU 26/04/2018 | H8: =substitute( SUBSTITUTE(G8," ",""),",",".")
A9: COS PERSONNEL Bordeaux Metropole | B9: =SUBSTITUTE(A9,char(10)," ") -> COS PERSONNEL Bordeaux Metropole | C9: 483013405 | D9: 2017/810_2017-12-22 | E9: 43091 | F9: fonctionnement | G9: 1 680 000,00 | H9: =substitute( SUBSTITUTE(G9," ",""),",",".") -> 1680000.00 | I9: aide en numéraire | J9: échelonné | K9: 2017-12-22_2018-06-22 | L9: sans objet | M9: non | N9: 1
A10: UFASEC | B10: =SUBSTITUTE(A10,char(10)," ") -> UFASEC | C10: 789105954 | D10: 2017/800_2017-22-12 | E10: 43091 | F10: fonctionnement | G10: 10 870,00 | H10: =substitute( SUBSTITUTE(G10," ",""),",",".") -> 10870.00 | I10: aide en numéraire | J10: 1 versement | K10: 2017-12-22_2018-06-22 | L10: sans objet | M10: non | N10: 1
A11: ARTS & LOISIRS D'ARLAC | B11: =SUBSTITUTE(A11,char(10)," ") -> ARTS & LOISIRS D'ARLAC | C11: 306040312 | D11: 2017/603_2017-11-24 | E11: 43130 | F11: fonctionnement | G11: 7 900,00 | H11: =substitute( SUBSTITUTE(G11," ",""),",",".") -> 7900.00 | I11: aide en numéraire | J11: échelonné | K11: 2018-01-30_2018-07-30 | L11: sans objet | M11: non | N11: 1
A12: CIJA | B12: =SUBSTITUTE(A12,char(10)," ") -> CIJA | C12: 306564279 | D12: 2018/001_2018-01-26 | E12: 43126 | F12: fonctionnement | G12: 32 000,00 | H12: =substitute( SUBSTITUTE(G12," ",""),",",".") -> 32000.00 | I12: aide en numéraire | J12: échelonné | K12: 2018-01-26_2018-26-07 | L12: sans objet | M12: non | N12: 1
A13: MÉMOIRE DE BORDEAUX | B13: =SUBSTITUTE(A13,char(10)," ") -> MÉMOIRE DE BORDEAUX | C13: 342215456 | D13: 2018/002_2018-01-26 | E13: 43126 | F13: fonctionnement | G13: 96 187,50 | H13: =substitute( SUBSTITUTE(G13," ",""),",",".") -> 96187.50 | I13: aide en numéraire | J13: échelonné | K13: 2018-01-26_2018-07-26 | L13: sans objet | M13: non | N13: 1
A14: AURBA | B14: =SUBSTITUTE(A14,char(10)," ") -> AURBA | C14: 781814488 | D14: 2017/833_2017-12-22 | E14: 43136 | F14: fonctionnement | G14: 4 372 007,00 | H14: =substitute( SUBSTITUTE(G14," ",""),",",".") -> 4372007.00 | I14: aide en numéraire | J14: échelonné | K14: 2018-02-05_2018-07-05- | L14: sans objet | M14: non | N14: 1
A15: UBM | B15: =SUBSTITUTE(A15,char(10)," ") -> UBM | C15: 418921409 | D15: 2017/801_2017-12-22 | E15: 43143 | F15: fonctionnement | G15: 77 000,00 | H15: =substitute( SUBSTITUTE(G15," ",""),",",".") -> 77000.00 | I15: aide en numéraire | J15: échelonné | K15: 2018-02-12_2018-08-02 | L15: sans objet | M15: non | N15: 1
A16: JIB (JUMPING INTERNATIONAL DE BORDEAUX) | B16: =SUBSTITUTE(A16,char(10)," ") -> JIB (JUMPING INTERNATIONAL DE BORDEAUX) | C16: 420252348 | D16: 2018/003_2018-01-26 | E16: 43160 | F16: 22e salon du cheval | G16: 34 000,00 | H16: =substitute( SUBSTITUTE(G16," ",""),",",".") -> 34000.00 | I16: aide en numéraire | J16: échelonné | K16: 2018-03-01_2018-09-01 | L16: sans objet | M16: non | N16: 1
A17: CSDL (caisse sociale de dév local) | B17: =SUBSTITUTE(A17,char(10)," ") -> CSDL (caisse sociale de dév local) | C17: 419009105 | D17: 2017/204_2017-04-14 | E17: 43161 | F17: fonctionnement | G17: 38 000,00 | H17: =substitute( SUBSTITUTE(G17," ",""),",",".") -> 38000.00 | I17: aide en numéraire | J17: échelonné | K17: 2018-03-02_2018-09-02 | L17: sans objet | M17: non | N17: 1
A18: PAIN ET PARTAGE SAS | B18: =SUBSTITUTE(A18,char(10)," ") -> PAIN ET PARTAGE SAS | C18: 832333181 | D18: 2018/005_2018-01-26 | E18: 43161 | F18: aide à l'investissement | G18: 60 000,00 | H18: =substitute( SUBSTITUTE(G18," ",""),",",".") -> 60000.00 | I18: aide en numéraire | J18: échelonné | K18: 2018-03-02_2018-09-02 | L18: sans objet | M18: non | N18: 1
A19: FABRIQUE POLA | B19: =SUBSTITUTE(A19,char(10)," ") -> FABRIQUE POLA | C19: 444337588 | D19: 2018/41_2018-01-26 | E19: 43172 | F19: fonctionnement | G19: 114 000,00 | H19: =substitute( SUBSTITUTE(G19," ",""),",",".") -> 114000.00 | I19: aide en numéraire | J19: échelonné | K19: 2018-03-13_2018-10-13 | L19: sans objet | M19: non | N19: 1
A20: MUSIQUES DE NUIT DIFFUSION | B20: =SUBSTITUTE(A20,char(10)," ") -> MUSIQUES DE NUIT DIFFUSION | C20: 341693190 | D20: 2018-42_2018-01-26 | E20: 43174 | F20: Festival afro new bell | G20: 35 000,00 | H20: =substitute( SUBSTITUTE(G20," ",""),",",".") -> 35000.00 | I20: aide en numéraire | J20: échelonné | K20: 2018-03-15_2018-09-15 | L20: sans objet | M20: non | N20: 1
A21: idBeneficiaire | B21: =SUBSTITUTE(A21,char(10)," ") -> idBeneficiaire | C21: nomBénéficiaire | D21: referenceDecision | E21: dateConvention | F21: objet | G21: montant | H21: =substitute( SUBSTITUTE(G21," ",""),",",".") -> montant | I21: nature | J21: conditionsVerse ment | K21: datesPériodeVersement | L21: idRAE | M21: notification UE | N21: pourcenta geSubvent ion
A22: ASSO EUROPEENNE DU FILM ANIMATION | B22: =SUBSTITUTE(A22,char(10)," ") -> ASSO EUROPEENNE DU FILM ANIMATION | C22: 509079794 | D22: 2018/49_2018-02-16 | E22: 43185 | F22: Cartoon movie | G22: 150 000,00 | H22: =substitute( SUBSTITUTE(G22," ",""),",",".") -> 150000.00 | I22: aide en numéraire | J22: échelonné | K22: 2018-03-26_2018-09-26 | L22: sans objet | M22: non | N22: 1
A23: PUBLICATION du 03/07/2018 | B23: =SUBSTITUTE(A23,char(10)," ") -> PUBLICATION du 03/07/2018 | H23: =substitute( SUBSTITUTE(G23," ",""),",",".")
A24: UNIS CITES | B24: =SUBSTITUTE(A24,char(10)," ") -> UNIS CITES | C24: 398191569 | D24: 2017/736_2018-01-17 | E24: 43124 | F24: fonctionnement | G24: 49 000,00 | H24: =substitute( SUBSTITUTE(G24," ",""),",",".") -> 49000.00 | I24: aide en numéraire | J24: échelonné | K24: 2018-01-24_2018-07-24 | L24: sans objet | M24: non | N24: 1
A25: STADE BORDELAIS ASPTT | B25: =SUBSTITUTE(A25,char(10)," ") -> STADE BORDELAIS ASPTT | C25: 781843594 | D25: 2017/184_2018-03-23 | E25: 43182 | F25: marathon 2018 | G25: 65 000,00 | H25: =substitute( SUBSTITUTE(G25," ",""),",",".") -> 65000.00 | I25: aide en numéraire | J25: échelonné | K25: 2018-03-23_2018-09-23 | L25: sans objet | M25: non | N25: 1
A26: SEMER LE DOUTE | B26: =SUBSTITUTE(A26,char(10)," ") -> SEMER LE DOUTE | C26: 533896825 | D26: 2018/182_2018-03-23 | E26: 43222 | F26: FIFIB le coureur 2018 | G26: 15 000,00 | H26: =substitute( SUBSTITUTE(G26," ",""),",",".") -> 15000.00 | I26: aide en numéraire | J26: échelonné | K26: 2018-05-02_2018-11-02 | L26: sans objet | M26: non | N26: 1
A27: SUPERCOOP SAS | B27: =SUBSTITUTE(A27,char(10)," ") -> SUPERCOOP SAS | C27: 825241318 | D27: 2018/103_2018-03-23 | E27: 43208 | F27: fonctionnement | G27: 24 176,00 | H27: =substitute( SUBSTITUTE(G27," ",""),",",".") -> 24176.00 | I27: aide en numéraire | J27: échelonné | K27: 2018-04-18_2018-10-18 | L27: sans objet | M27: non | N27: 1
A28: ALEC agence locale de l'énergie | B28: =SUBSTITUTE(A28,char(10)," ") -> ALEC agence locale de l'énergie | C28: 495009441 | D28: 2018/278_2018-04-27 | E28: 43235 | F28: fonctionnement | G28: 137 000,00 | H28: =substitute( SUBSTITUTE(G28," ",""),",",".") -> 137000.00 | I28: aide en numéraire | J28: échelonné | K28: 2018-05-15_2018-11-15 | L28: sans objet | M28: non | N28: 1
A29: BORDEAUX OPEN AIR | B29: =SUBSTITUTE(A29,char(10)," ") -> BORDEAUX OPEN AIR | C29: 821354933 | D29: 2018/283_2018-04-27 | E29: 43244 | F29: été métropolitain | G29: 10 000,00 | H29: =substitute( SUBSTITUTE(G29," ",""),",",".") -> 10000.00 | I29: aide en numéraire | J29: échelonné | K29: 2018-05-24_2018-11-24 | L29: sans objet | M29: non | N29: 1
A30: IDDAC | B30: =SUBSTITUTE(A30,char(10)," ") -> IDDAC | C30: 383890233 | D30: 2018/177_2018-03-23 | E30: 43248 | F30: journées juniors dév.durable (JDD) | G30: 17 500,00 | H30: =substitute( SUBSTITUTE(G30," ",""),",",".") -> 17500.00 | I30: aide en numéraire | J30: échelonné | K30: 2018-05-28_2018-11-28 | L30: sans objet | M30: non | N30: 1
A31: TRAFIC | B31: =SUBSTITUTE(A31,char(10)," ") -> TRAFIC | C31: 789632254 | D31: 2018/283_2018-04-27 | E31: 43250 | F31: été métropolitain | G31: 10 000,00 | H31: =substitute( SUBSTITUTE(G31," ",""),",",".") -> 10000.00 | I31: aide en numéraire | J31: échelonné | K31: 2018-05-30_2018-11-30 | L31: sans objet | M31: non | N31: 1
A32: ARIANE PRODUCTIONS | B32: =SUBSTITUTE(A32,char(10)," ") -> ARIANE PRODUCTIONS | C32: 438794034 | D32: 2018/283_2018-04-27 | E32: 43244 | F32: été métropolitain | G32: 9 610,00 | H32: =substitute( SUBSTITUTE(G32," ",""),",",".") -> 9610.00 | I32: aide en numéraire | J32: échelonné | K32: 2018-05-24_2018-11-24 | L32: sans objet | M32: non | N32: 1
A33: CSDL (caisse sociale dév local) | B33: =SUBSTITUTE(A33,char(10)," ") -> CSDL (caisse sociale dév local) | C33: 419009105 | D33: 2018/208-2018-04-27 | E33: 43252 | F33: ESS | G33: 38 000,00 | H33: =substitute( SUBSTITUTE(G33," ",""),",",".") -> 38000.00 | I33: aide en numéraire | J33: échelonné | K33: 2018-06-01_2018-12-01 | L33: sans objet | M33: non | N33: 1
A34: IDDAC | B34: =SUBSTITUTE(A34,char(10)," ") -> IDDAC | C34: 383890233 | D34: 2018/283_2018-04-27 | E34: 43252 | F34: été métropolitain | G34: 17 000,00 | H34: =substitute( SUBSTITUTE(G34," ",""),",",".") -> 17000.00 | I34: aide en numéraire | J34: échelonné | K34: 2018-06-01_2018-12-01 | L34: sans objet | M34: non | N34: 1
A35: ATIS | B35: =SUBSTITUTE(A35,char(10)," ") -> ATIS | C35: 522896091 | D35: 2018/208-2018-04-27 | E35: 43255 | F35: ESS | G35: 42 750,00 | H35: =substitute( SUBSTITUTE(G35," ",""),",",".") -> 42750.00 | I35: aide en numéraire | J35: échelonné | K35: 2018-06-04_2018-12-04 | L35: sans objet | M35: non | N35: 1
... A43: THE DESK | B43: =SUBSTITUTE(A43,char(10)," ") -> THE DESK | C43: 824274781 | D43: 2018/283_2018-04-27 | E43: 43252 | F43: été métropolitain | G43: 11 000,00 | H43: =substitute( SUBSTITUTE(G43," ",""),",",".") -> 11000.00 | I43: aide en numéraire | J43: échelonné | K43: 2018-06-01_2018-12-01 | L43: sans objet | M43: non | N43: 1
A44: idBeneficiaire | B44: =SUBSTITUTE(A44,char(10)," ") -> idBeneficiaire | C44: nomBénéficiaire | D44: referenceDecision | E44: dateConvention | F44: objet | G44: montant | H44: =substitute( SUBSTITUTE(G44," ",""),",",".") -> montant | I44: nature | J44: conditionsVerse ment | K44: datesPériodeVersement | L44: idRAE | M44: notification UE | N44: pourcenta geSubvent ion
A45: SEMER LE DOUTE | B45: =SUBSTITUTE(A45,char(10)," ") -> SEMER LE DOUTE | C45: 533896825 | D45: 2018/284_2018-04-27 | E45: 43257 | F45: contrat codev | G45: 26 000,00 | H45: =substitute( SUBSTITUTE(G45," ",""),",",".") -> 26000.00 | I45: aide en numéraire | J45: échelonné | K45: 2018-06-06_2018-12-06 | L45: sans objet | M45: non | N45: 1
A46: LETTRES DU MONDE | B46: =SUBSTITUTE(A46,char(10)," ") -> LETTRES DU MONDE | C46: 452274798 | D46: 2018/283_2018-04-27 | E46: 43250 | F46: été métropolitain | G46: 5 000,00 | H46: =substitute( SUBSTITUTE(G46," ",""),",",".") -> 5000.00 | I46: aide en numéraire | J46: échelonné | K46: 2018-05-30_2018-11-30 | L46: sans objet | M46: non | N46: 1
A47: L'IRREGULIERE | B47: =SUBSTITUTE(A47,char(10)," ") -> L'IRREGULIERE | C47: 833920077 | D47: 2018/283_2018-04-27 | E47: 43257 | F47: été métropolitain | G47: 8 000,00 | H47: =substitute( SUBSTITUTE(G47," ",""),",",".") -> 8000.00 | I47: aide en numéraire | J47: échelonné | K47: 2018-06-06_2018-12-06 | L47: sans objet | M47: non | N47: 1
...

Sheet 2018 clean final
A1: idBeneficiaire_clean | B1: montant_clean | C1: nomBénéficiaire | D1: referenceDecision | E1: dateConvention | F1: objet | G1: nature | H1: conditionsVerse ment | I1: datesPériodeVersement | J1: idRAE | K1: notification UE | L1: pourcenta geSubvent ion
A2: A.DE.LE | B2: 25000 | C2: 43383539400027 | D2: 2018/376_2018-07-06 | E2: 43370 | F2: OIN Euratlantique | G2: aide en numéraire | H2: échelonné | I2: 2018-09-27_2019-03-27 | J2: sans objet | K2: non | L2: 1
A3: ACTIMAGE | B3: 2100 | C3: 750447567 | D3: 2018/283-2018-04-27 | E3: 43279 | F3: été métropolitain | G3: aide en numéraire | H3: échelonné | I3: 2018-06-28_2018-12-28 | J3: sans objet | K3: non | L3: 1
A4: ADAV 33 | B4: 87400 | C4: 30091783800025 | D4: 2018/579_2018-09-28 | E4: 43385 | F4: fonctionnement | G4: aide en numéraire | H4: échelonné | I4: 2018-10-12_2019-04-12 | J4: sans objet | K4: non | L4: 1
A5: ADEM | B5: 58000 | C5: 39811228400011 | D5: 2018/468_2018-07-06 | E5: 43319 | F5: Décastar | G5: aide en numéraire | H5: échelonné | I5: 2018-08-07_2019-02-07 | J5: sans objet | K5: non | L5: 1
A6: ADI NOUVELLE AQUITAINE | B6: 24000 | C6: 82033673300010 | D6: 2018/375-2018-07-06 | E6: 43339 | F6: programme d'actions | G6: aide en numéraire | H6: 1 versement | I6: 2018-08-27_2019-02-27 | J6: sans objet | K6: non | L6: 1
A7: ADIE | B7: 45000 | C7: 352216873 | D7: 2018/208-2018-04-27 | E7: 43269 | F7: fonctionnement et soutien ESS | G7: aide en numéraire | H7: échelonné | I7: 2018-06-18_2018-12-18 | J7: sans objet | K7: non | L7: 1
A8: ADIE | B8: 5000 | C8: 35221687300211 | D8: 2018/460-2018-07-06 | E8: 43312 | F8: contrat de ville | G8: aide en numéraire | H8: 1 versement | I8: 2018-07-31_2019-01-31 | J8: sans objet | K8: non | L8: 1
A9: ADIEU PANURGE | B9: 7190 | C9: 828195339 | D9: 2018/283-2018-04-27 | E9: 43264 | F9: été métropolitain | G9: aide en numéraire | H9: échelonné | I9: 2018-06-13_2018-12-13 | J9: sans objet | K9: non | L9: 1
A10: ADIL (asso. départ. pour information sur logement) | B10: 97740 | C10: 305378234 | D10: 2017/739_2017-11-24 | E10: 43069 | F10: fonctionnement | G10: aide en numéraire | H10: échelonné | I10: 2017-11-30_2018-05-30 | J10: sans objet | K10: non | L10: 1
A11: ADMAA (ASSO DEFENSE MUSIQUES ALTERNATIVES) | B11: 40000 | C11: 489563072 | D11: 2017/348_2017-05-19 | E11: 43133 | F11: été métropolitain 2017 | G11: aide en numéraire | H11: échelonné | I11: 2018-02-02_2018-08-08 | J11: sans objet | K11: non | L11: 1
A12: ADMAA (ASSO DEFENSE MUSIQUES ALTERNATIVES) | B12: 20000 | C12: 489563072 | D12: 2018/283_2018-04-27 | E12: 43255 | F12: été métropolitain | G12: aide en numéraire | H12: échelonné | I12: 2018-06-04_2018-12-04 | J12: sans objet | K12: non | L12: 1
A13: ADMAA (ASSO DEFENSE MUSIQUES ALTERNATIVES) | B13: 15000 | C13: 48956307200020 | D13: 2018/353-2018-06-15 | E13: 43287 | F13: codev Festival Relâche | G13: aide en numéraire | H13: échelonné | I13: 2018-07-06_2019-01-06 | J13: sans objet | K13: non | L13: 1
... A91: INVEST IN BORDEAUX | B91: 332775 | C91: 409199817 | D91: 2018/283-2018-04-27 | E91: 43271 | F91: fonctionnement | G91: aide en numéraire | H91: échelonné | I91: 2018-06-20_2018-12-20 | J91: sans objet | K91: non | L91: 1
A92: IUFM | B92: 10000 | C92: 75198395800024 | D92: 2018/178_2018-03-23 | E92: 43276 | F92: transition énergétique | G92: aide en numéraire | H92: échelonné | I92: 2018-06-25_2018-12-25 | J92: sans objet | K92: non | L92: 1-
A93: JIB (JUMPING INTERNATIONAL DE BORDEAUX) | B93: 34000 | C93: 420252348 | D93: 2018/003_2018-01-26 | E93: 43160 | F93: 22e salon du cheval | G93: aide en numéraire | H93: échelonné | I93: 2018-03-01_2018-09-01 | J93: sans objet | K93: non | L93: 1
A94: L'EPHEMERE | B94: 5000 | C94: 82138441900015 | D94: 2018/40_2018-01-26 | E94: 43298 | F94: programme d'actions | G94: aide en numéraire | H94: échelonné | I94: 2018-07-17_2019-01-17 | J94: sans objet | K94: non | L94: 1
A95: L'IRREGULIERE | B95: 8000 | C95: 833920077 | D95: 2018/283_2018-04-27 | E95: 43257 | F95: été métropolitain | G95: aide en numéraire | H95: échelonné | I95: 2018-06-06_2018-12-06 | J95: sans objet | K95: non | L95: 1
A96: LA MECANIQUE GENERALE | B96: 9900 | C96: 824698500 | D96: 2018/283_2018-04-27 | E96: 43266 | F96: fonctionnement | G96: aide en numéraire | H96: échelonné | I96: 2018-06-15_2018-12-15 | J96: sans objet | K96: non | L96: 1
A97: LA RONDE DES QUARTIERS DE BX | B97: 13000 | C97: 52539664400011 | D97: 2018/491_2018-09-28 | E97: 43418 | F97: Le bon goût | G97: aide en numéraire | H97: échelonné | I97: 2018-11-14_2019-05-14 | J97: sans objet | K97: non | L97: 1
A98: LA RONDE DES QUARTIERS DE BX | B98: 15000 | C98: 52539664400011 | D98: 2018/491_2018-09-28 | E98: 43418 | F98: création nouvelles associations de commerçants | G98: aide en numéraire | H98: 1 versement | I98: 2018-11-14_2019-05-14 | J98: sans objet | K98: non | L98: 1
A99: LA RONDE DES QUARTIERS DE BX | B99: 46318 | C99: 52539664400011 | D99: 2018/491_2018-09-28 | E99: 43418 | F99: programme d'actions | G99: aide en numéraire | H99: échelonné | I99: 2018-11-14_2019-05-14 | J99: sans objet | K99: non | L99: 1
A100: LE POEME EN VOLUME | B100: 5000 | C100: 810971283 | D100: 2018/283_2018-04-27 | E100: 43269 | F100: été métropolitain | G100: aide en numéraire | H100: échelonné | I100: 2018-06-18_2018-12-18 | J100: sans objet | K100: non | L100: 1
A101: LES ARTS AU MUR | B101: 15000 | C101: 43434085700037 | D101: 2018/284_2018-04-27 | E101: 43300 | F101: fonctionnement | G101: aide en numéraire | H101: échelonné | I101: 2018-07-19_2018-01-19 | J101: sans objet | K101: non | L101: 1
A102: LES CAPRICES DE MARIANNE | B102: 14000 | C102: 809584576 | D102: 2018/283_2018-04-27 | E102: 43252 | F102: été métropolitain | G102: aide en numéraire | H102: échelonné | I102: 2018-06-01_2018-12-01 | J102: sans objet | K102: non | L102: 1
A103: LES PETITS DEBROUILLARDS | B103: 7000 | C103: 41087071100083 | D103: 2018/460-2018-07-06 | E103: 43312 | F103: contrat de ville | G103: aide en numéraire | H103: échelonné | I103: 2018-07-31_2019-01-31 | J103: sans objet | K103: non | L103: 1
A104: LES RESTAURANTS DU CŒUR | B104: 25000 | C104: 37954994200025 | D104: 2018/303-2018-06-15 | E104: 43299 | F104: fonctionnement | G104: aide en numéraire | H104: échelonné | I104: 2018-07-18_2018-01-18 | J104: sans objet | K104: non | L104: 1
... A144: VELO CITE | B144: 55000 | C144: 43288382500031 | D144: 2018/347-2018-06-15 | E144: 43304 | F144: MAMMA maison métropolitaine mobilité alternative | G144: aide en numéraire | H144: échelonné | I144: 2018-07-23_2019-01-23 | J144: sans objet | K144: non | L144: 1

Sheet 2019 clean final
A1: nomBénéficiaire | B1: montant | C1: datepublication | D1: nomAttribuant | E1: idAttribuant | F1: dateConvention | G1: referenceDecision | H1: idBeneficiaire | I1: objet | J1: nature | K1: conditionsVersement | L1: datesPériodeVersement | M1: idRAE | N1: notificationUE | O1: pourcentageSubvention
A2: ADELE | B2: 12500 | C2: 43724 | D2: BORDEAUX METROPOLE | E2: 24330031600011 | F2: 43651 | G2: 2019/206 | H2: 43383594000027 | I2: PLIE DES GRAVES | J2: aide en numéraire | K2: échelonné | L2: 2019-07-05/2020-01-05 | M2: sans objet | N2: non | O2: 1
A3: ADEM | B3: 58000 | C3: 43636 | D3: BORDEAUX METROPOLE | E3: 24330031600011 | F3: 43556 | G3: 2019/172 | H3: 39811228400011 | I3: DECASTAR | J3: aide en numéraire | K3: échelonné | L3: 2019-04-01/2019-10-01 | M3: sans objet | N3: non | O3: 1
A4: ADIE | B4: 15000 | C4: 43636 | D4: BORDEAUX METROPOLE | E4: 24330031600011 | F4: 43627 | G4: 2019/205 | H4: 35221687300211 | I4: ESS programme d'actions | J4: aide en numéraire | K4: unique | L4: 2019-06-11/2019-12-11 | M4: sans objet | N4: non | O4: 1
A5: ADIE | B5: 5000 | C5: 43724 | D5: BORDEAUX METROPOLE | E5: 24330031600011 | F5: 43677 | G5: 2019/386 | H5: 35221687300015 | I5: Fonctionnement | J5: aide en numéraire | K5: unique | L5: 2019-07-31/2020-01-31 | M5: sans objet | N5: non | O5: 1
A6: ADIL 33 | B6: 97740 | C6: 43502 | D6: BORDEAUX METROPOLE | E6: 24330031600011 | F6: 43413 | G6: 2018/573 | H6: 30537823400036 | I6: Fonctionnement | J6: aide en numéraire | K6: échelonné | L6: 2018-11-09/2019-05-09 | M6: sans objet | N6: non | O6: 1
A7: ADMAA | B7: 20000 | C7: 43636 | D7: BORDEAUX METROPOLE | E7: 24330031600011 | F7: 43612 | G7: 2019/263 | H7: 48956307200029 | I7: Eté métropolitain | J7: aide en numéraire | K7: échelonné | L7: 2019-05-27/2019-11-27 | M7: sans objet | N7: non | O7: 1
A8: ADMAA | B8: 15000 | C8: 43724 | D8: BORDEAUX METROPOLE | E8: 24330031600011 | F8: 43703 | G8: 2019/390 | H8: 48956307200029 | I8: Festival Relache | J8: aide en numéraire | K8: échelonné | L8: 2019-08-26/2020-02-26 | M8: sans objet | N8: non | O8: 1
A9: ADSI TECHNOWEST | B9: 14500 | C9: 43636 | D9: BORDEAUX METROPOLE | E9: 24330031600011 | F9: 43619 | G9: 2019/206 | H9: 43403882400042 | I9: PLIE | J9: aide en numéraire | K9: échelonné | L9: 2019-06-03/2019-12-03 | M9: sans objet | N9: non | O9: 1
A10: ADSI TECHNOWEST | B10: 25000 | C10: 43724 | D10: BORDEAUX METROPOLE | E10: 24330031600011 | F10: 43658 | G10: 2019/401 | H10: 43403882400042 | I10: OIM action emploi | J10: aide en numéraire | K10: échelonné | L10: 2019-07-12/2020-01-12 | M10: sans objet | N10: non | O10: 1
A11: AEROSPACE VALLEY | B11: 90000 | C11: 43784 | D11: BORDEAUX METROPOLE | E11: 24330031600011 | F11: 43769 | G11: 2019/489 | H11: 48428452600072 | I11: Fonctionnement | J11: aide en numéraire | K11: échelonné | L11: 2019-10-31/2020-04-31 | M11: sans objet | N11: non | O11: 1
A12: AFEPT | B12: 58000 | C12: 43557 | D12: BORDEAUX METROPOLE | E12: 24330031600011 | F12: 43532 | G12: 2019/63 | H12: 30016423300029 | I12: Fonctionnement | J12: aide en numéraire | K12: échelonné | L12: 2019-03-08/2019-09-08 | M12: sans objet | N12: non | O12: 1
A13: AGEC ET CO | B13: 14250 | C13: 43636 | D13: BORDEAUX METROPOLE | E13: 24330031600011 | F13: 43614 | G13: 2019/265 | H13: 49848483100033 | I13: projet artistique | J13: aide en numéraire | K13: échelonné | L13: 2019-05-29/2019-11-29 | M13: sans objet | N13: non | O13: 1
... A81: INVEST IN BORDEAUX | B81: 487775 | C81: 43636 | D81: BORDEAUX METROPOLE | E81: 24330031600011 | F81: 43621 | G81: 2019/187 | H81: 40919981700050 | I81: Fonctionnement | J81: aide en numéraire | K81: échelonné | L81: 2019-06-05/2019-12-05 | M81: sans objet | N81: non | O81: 1
A82: JUMPING INTERNATIONAL | B82: 34000 | C82: 43557 | D82: BORDEAUX METROPOLE | E82: 24330031600011 | F82: 43523 | G82: 43647 | H82: 42052348000016 | I82: Jumping | J82: aide en numéraire | K82: échelonné | L82: 2019-02-27/2019-08-27 | M82: sans objet | N82: non | O82: 1
A83: L'ART DANS TOUS SES ETATS | B83: 6600 | C83: 43636 | D83: BORDEAUX METROPOLE | E83: 24330031600011 | F83: 43628 | G83: 2019/263 | H83: 82155741000015 | I83: Eté métropolitain | J83: aide en numéraire | K83: échelonné | L83: 2019-06-12/2019-12-12 | M83: sans objet | N83: non | O83: 1
A84: L'ATELIER REMUMENAGE | B84: 4000 | C84: 43724 | D84: BORDEAUX METROPOLE | E84: 24330031600011 | F84: 43677 | G84: 2019/386 | H84: 33483378700011 | I84: Fonctionnement | J84: aide en numéraire | K84: unique | L84: 2019-07-31/2020-01-31 | M84: sans objet | N84: non | O84: 1
A85: L'ORANGEADE | B85: 15000 | C85: 43636 | D85: BORDEAUX METROPOLE | E85: 24330031600011 | F85: 43606 | G85: 2019/263 | H85: 80016249700039 | I85: Eté métropolitain | J85: aide en numéraire | K85: échelonné | L85: 2019-05-21/2019-11-21 | M85: sans objet | N85: non | O85: 1
A86: LA MECANIQUE GENERALE | B86: 12500 | C86: 43636 | D86: BORDEAUX METROPOLE | E86: 24330031600011 | F86: 43619 | G86: 2019/263 | H86: 82469850000017 | I86: Eté métropolitain | J86: aide en numéraire | K86: échelonné | L86: 2019-06-03/2019-12-03 | M86: sans objet | N86: non | O86: 1
