Workbook

Sheet original
A1: Une fois les chiffres extraits dans un CSV à l'aide de Tabula, on met le CSV sur Google Drive afin de l'ouvrir avec Google Sheets. Une fois ouvert dans le premier onglet, deux étapes: 1. Je renomme l'onglet pour clarifier que ce sont les données d'origine (que je ne vais pas toucher) 2. Je change l'affichage du texte pour qu'il s'adapte à la taille des cellules et qu'il y ait un retour à la ligne. Cela facilite une exploration visuelle des données. 3. Dès cette étape, si les montants présents dans la colonne B sont reconnus comme des chiffres, je peux vérifier que le total correspond au PDF source. A noter: vous ne savez jamais si le PDF originel sera toujours à l'adresse où vous l'avez trouvé. Il vaut mieux donc le mettre dans le même dossier Google Drive que le CSV, de façon à avoir tous vos documents source au même endroit.
A2: "BAMBINO BERTHELOT" ASSOCIATION DE PARENTS D'ELEVES DE | B2: 0,00 | C2: Locaux
A3: L'ECOLE MATERNELLE BERTHELOT A BORDEAUX
A4: 1001 JEUNES BORDELAIS | B4: 0,00 | C4: Matériel pour manifestations
A5: 2AA | B5: 0,00 | C5: Locaux
A6: 2SI2LA | B6: 0,00 | C6: Locaux
A7: 4 CATS | B7: 0,00 | C7: Locaux
A8: 5UN7 | B8: 1 000,00
A9: 60 000 REBONDS | B9: 1 800,00
A10: 9-33 | B10: 19 000,00 | C10: Communication, locaux
A11: A L EAU MUSIC | B11: 500,00
A12: A PART ENTIERE | B12: 2 000,00
A13: A PETIT PAS | B13: 3 000,00
A14: A TRAVERS CHANT | B14: 0,00 | C14: Locaux
A15: A2RUNNING | B15: 0,00 | C15: Locaux
A16: ABALONE CHASSE BORDEAUX | B16: 0,00 | C16: Locaux, équipements sportifs
A17: ABEILLES BORDELAISES | B17: 0,00 | C17: Locaux
A18: ACADEMIE BUSHIKAI KARATE DO | B18: 0,00 | C18: Equipements sportifs
A19: ACADEMIE DES SCIENCES, BELLES LETTRES ET ARTS DE | B19: 7 600,00 | C19: Locaux, matériel pour manifestations
A20: BORDEAUX
A21: ACADEMIE PROSPECTIVE NOUVELLES TECHNOLOGIES | B21: 0,00 | C21: Locaux
A22: ACADEMIE YOUNUS | B22: 22 000,00 | C22: Locaux, équipements sportifs, matériel pour
C23: manifestations
A24: ACCOMPAGNEMENT ET RECHERCHE PSYCHO-SOCIO EDUCATIFS | B24: 0,00 | C24: Locaux
A25: POUR LES JEUNES (ARPEJE)
A26: ACCOMPAGNEMENT PSYCHOLOGIQUE ET MEDIATION | B26: 5 000,00
A27: INTERCULTURELLE - AMI
A28: ACCOMPAGNER CONDUIRE TRANSMETTRE - ACT | B28: 300,00 | C28: Locaux
A29: ACCORDERIE BORDEAUX SUD | B29: 4 500,00 | C29: Locaux
A30: ACHATS GROUPES ASSOCIATIF POUR L'ECONOMIE SOLIDAIRE DE | B30: 0,00 | C30: Locaux
A31: BORDEAUX - AGAPES
A32: ACIDD, ASSOCIATION COMMUNICATION ET INFORMATION POUR LE | B32: 10 000,00 | C32: Locaux
A33: DEVELOPPEMENT DURABLE
A34: ACINQBYS_ESPACE 29 A5BIS | B34: 22 000,00
A35: ACTA GIRONDE - AGIR CONTRE LA TORTURE DES ANIMAUX | B35: 0,00 | C35: Locaux
A36: ACTIFS 33 | B36: 2 400,00
A37: ACTIMAGE | B37: 6 500,00
A38: ACTION CONTRE LA FAIM | B38: 0,00 | C38: Locaux
A39: ACTION INTERNATIONALE POUR LA PAIX ET LE DEVELOPPEMENT | B39: 0,00 | C39: Locaux
A40: AD LUCEM THEATRE | B40: 0,00 | C40: Locaux
...

Sheet etape1
A1: Nous voici dans la première étape de transformation des données. Après avoir observé dans les données de départ que certains noms étaient coupés en deux, il s'agit d'identifier l'ampleur du problème. Pour cela nous avons d'abord dupliqué le premier onglet de la feulle de calcul afin de ne pas travailler sur les données originelles. 1. Le nouvel onglet est renommé etape1. 2. On utilise la formule =isblank() dans la colonne D afin d'identifier les cellules vides de la colonne B, qui semblent résulter d'un nom coupé en deux. 3. on applique une mise en forme conditionnelle à la colonne D afin d'identifier visuellement les noms coupés en deux. 4. (optionnel) Dans mon cas, les montants ne sont pas reconnus en tant que chiffres car mon compte est configuré en anglais. Il s'attend donc à voir des chiffres mis en forme à l'anglaise (1,000.00) plutôt qu'à la française (1 000,00). Pour remédier à cela, je fais un simple recherche et remplacer dans la colonne B, en remplaçant les espaces par rien du tout (ce qui les supprime) et en remplaçant les virgules par des points. Cela me permet de vérifier dès cette étape que le montant total correspond bien à celui affiché dans le PDF source.
A2: "BAMBINO BERTHELOT" ASSOCIATION DE PARENTS D'ELEVES DE | B2: 0 | C2: Locaux | D2: =ISBLANK(B2) -> FALSE
A3: L'ECOLE MATERNELLE BERTHELOT A BORDEAUX | D3: =ISBLANK(B3) -> TRUE
A4: 1001 JEUNES BORDELAIS | B4: 0 | C4: Matériel pour manifestations | D4: =ISBLANK(B4) -> FALSE
A5: 2AA | B5: 0 | C5: Locaux | D5: =ISBLANK(B5) -> FALSE
A6: 2SI2LA | B6: 0 | C6: Locaux | D6: =ISBLANK(B6) -> FALSE
A7: 4 CATS | B7: 0 | C7: Locaux | D7: =ISBLANK(B7) -> FALSE
A8: 5UN7 | B8: 1000 | D8: =ISBLANK(B8) -> FALSE
A9: 60 000 REBONDS | B9: 1800 | D9: =ISBLANK(B9) -> FALSE
A10: 9-33 | B10: 19000 | C10: Communication, locaux | D10: =ISBLANK(B10) -> FALSE
A11: A L EAU MUSIC | B11: 500 | D11: =ISBLANK(B11) -> FALSE
A12: A PART ENTIERE | B12: 2000 | D12: =ISBLANK(B12) -> FALSE
A13: A PETIT PAS | B13: 3000 | D13: =ISBLANK(B13) -> FALSE
A14: A TRAVERS CHANT | B14: 0 | C14: Locaux | D14: =ISBLANK(B14) -> FALSE
A15: A2RUNNING | B15: 0 | C15: Locaux | D15: =ISBLANK(B15) -> FALSE
A16: ABALONE CHASSE BORDEAUX | B16: 0 | C16: Locaux, équipements sportifs | D16: =ISBLANK(B16) -> FALSE
A17: ABEILLES BORDELAISES | B17: 0 | C17: Locaux | D17: =ISBLANK(B17) -> FALSE
A18: ACADEMIE BUSHIKAI KARATE DO | B18: 0 | C18: Equipements sportifs | D18: =ISBLANK(B18) -> FALSE
A19: ACADEMIE DES SCIENCES, BELLES LETTRES ET ARTS DE | B19: 7600 | C19: Locaux, matériel pour manifestations | D19: =ISBLANK(B19) -> FALSE
A20: BORDEAUX | D20: =ISBLANK(B20) -> TRUE
A21: ACADEMIE PROSPECTIVE NOUVELLES TECHNOLOGIES | B21: 0 | C21: Locaux | D21: =ISBLANK(B21) -> FALSE
A22: ACADEMIE YOUNUS | B22: 22000 | C22: Locaux, équipements sportifs, matériel pour | D22: =ISBLANK(B22) -> FALSE
C23: manifestations | D23: =ISBLANK(B23) -> TRUE
A24: ACCOMPAGNEMENT ET RECHERCHE PSYCHO-SOCIO EDUCATIFS | B24: 0 | C24: Locaux | D24: =ISBLANK(B24) -> FALSE
A25: POUR LES JEUNES (ARPEJE) | D25: =ISBLANK(B25) -> TRUE
A26: ACCOMPAGNEMENT PSYCHOLOGIQUE ET MEDIATION | B26: 5000 | D26: =ISBLANK(B26) -> FALSE
A27: INTERCULTURELLE - AMI | D27: =ISBLANK(B27) -> TRUE
A28: ACCOMPAGNER CONDUIRE TRANSMETTRE - ACT | B28: 300 | C28: Locaux | D28: =ISBLANK(B28) -> FALSE
A29: ACCORDERIE BORDEAUX SUD | B29: 4500 | C29: Locaux | D29: =ISBLANK(B29) -> FALSE
A30: ACHATS GROUPES ASSOCIATIF POUR L'ECONOMIE SOLIDAIRE DE | B30: 0 | C30: Locaux | D30: =ISBLANK(B30) -> FALSE
A31: BORDEAUX - AGAPES | D31: =ISBLANK(B31) -> TRUE
A32: ACIDD, ASSOCIATION COMMUNICATION ET INFORMATION POUR LE | B32: 10000 | C32: Locaux | D32: =ISBLANK(B32) -> FALSE
A33: DEVELOPPEMENT DURABLE | D33: =ISBLANK(B33) -> TRUE
A34: ACINQBYS_ESPACE 29 A5BIS | B34: 22000 | D34: =ISBLANK(B34) -> FALSE
A35: ACTA GIRONDE - AGIR CONTRE LA TORTURE DES ANIMAUX | B35: 0 | C35: Locaux | D35: =ISBLANK(B35) -> FALSE
A36: ACTIFS 33 | B36: 2400 | D36: =ISBLANK(B36) -> FALSE
A37: ACTIMAGE | B37: 6500 | D37: =ISBLANK(B37) -> FALSE
A38: ACTION CONTRE LA FAIM | B38: 0 | C38: Locaux | D38: =ISBLANK(B38) -> FALSE
A39: ACTION INTERNATIONALE POUR LA PAIX ET LE DEVELOPPEMENT | B39: 0 | C39: Locaux | D39: =ISBLANK(B39) -> FALSE
A40: AD LUCEM THEATRE | B40: 0 | C40: Locaux | D40: =ISBLANK(B40) -> FALSE
...

Sheet etape2
A1: L'étape précédent nous a fait découvrir l'ampleur du problème. Au vu du nombre de noms affectés, il est nécessaire de passer par des formules pour automatiser la résolution du problème. Notre problème est donc que certains noms sont sur deux lignes. grâce à nos étapes précédentes, on a pu faire apparaitre TRUE (ou VRAI si votre logiciel est en Français) sur la même que la seconde partie de noms coupés en deux. Par conséquent, on sait que si TRUE apparait sur une ligne, on va trouver, sur la même ligne, la deuxième partie d'un nom coupé en deux, et sur la ligne précédente la première partie de ce nom. Cette logique fonctionne pour tous les TRUE, ce qui veut dire qu'on peut l'utiliser pour recréer les noms : Si dans la ligne 10 de la colonne D je trouve TRUE, alors je veux fusionner le contenu de la ligne 9 de la colonne A et de la ligne 10 de la colonne A. En formule, cela donne: IF(D10 = TRUE, CONCATENATE(A9,A10)) Plutôt que d'essayer de changer la colonne avec le texte existant et s'embrouiller les pinceaux, on va utiliser la colonne E, qui est vide, pour recréer les noms. En faisant commencer cette formule avec D2, A1 et A2, et en l'appliquand sur toute la colonne, on arrive en effet à fusionner les noms coupés en deux. Mais il deux points sont encore à régler : 1. Il manque un espace entre les morceaux de noms fusionnés. Pas de souci, il faut juste s'assurer que la formule rajoute cet espace: IF(D10 = TRUE, CONCATENATE(A9," ",A10)) 2. La colonne D est rempli de FALSE pour toutes les fois où la formule ne tombe pas sur un nom découpé. Dans ce cas, plutôt que un FALSE, on veut le nom original. On modifie alors la formule pour rajouter la condition finale au IF : IF(D10 = TRUE, CONCATENATE(A9," ",A10),A10) Donc si D10 est TRUE, la formule va fusionner A9 et A10 en rajoutant un espace entre les deux. Mais si D10 est FALSE, alors la formule va simplement recopier le contenu de A10.
A2: "BAMBINO BERTHELOT" ASSOCIATION DE PARENTS D'ELEVES DE | B2: 0 | C2: Locaux | D2: =ISBLANK(B2) -> FALSE | E2: =if(D3=TRUE, CONCATENATE(A2," ",A3),A2) -> "BAMBINO BERTHELOT" ASSOCIATION DE PARENTS D'ELEVES DE L'ECOLE MATERNELLE BERTHELOT A BORDEAUX
A3: L'ECOLE MATERNELLE BERTHELOT A BORDEAUX | D3: =ISBLANK(B3) -> TRUE | E3: =if(D4=TRUE, CONCATENATE(A3," ",A4),A3) -> L'ECOLE MATERNELLE BERTHELOT A BORDEAUX
A4: 1001 JEUNES BORDELAIS | B4: 0 | C4: Matériel pour manifestations | D4: =ISBLANK(B4) -> FALSE | E4: =if(D5=TRUE, CONCATENATE(A4," ",A5),A4) -> 1001 JEUNES BORDELAIS
A5: 2AA | B5: 0 | C5: Locaux | D5: =ISBLANK(B5) -> FALSE | E5: =if(D6=TRUE, CONCATENATE(A5," ",A6),A5) -> 2AA
A6: 2SI2LA | B6: 0 | C6: Locaux | D6: =ISBLANK(B6) -> FALSE | E6: =if(D7=TRUE, CONCATENATE(A6," ",A7),A6) -> 2SI2LA
A7: 4 CATS | B7: 0 | C7: Locaux | D7: =ISBLANK(B7) -> FALSE | E7: =if(D8=TRUE, CONCATENATE(A7," ",A8),A7) -> 4 CATS
A8: 5UN7 | B8: 1000 | D8: =ISBLANK(B8) -> FALSE | E8: =if(D9=TRUE, CONCATENATE(A8," ",A9),A8) -> 5UN7
A9: 60 000 REBONDS | B9: 1800 | D9: =ISBLANK(B9) -> FALSE | E9: =if(D10=TRUE, CONCATENATE(A9," ",A10),A9) -> 60 000 REBONDS
A10: 9-33 | B10: 19000 | C10: Communication, locaux | D10: =ISBLANK(B10) -> FALSE | E10: =if(D11=TRUE, CONCATENATE(A10," ",A11),A10) -> 9-33
A11: A L EAU MUSIC | B11: 500 | D11: =ISBLANK(B11) -> FALSE | E11: =if(D12=TRUE, CONCATENATE(A11," ",A12),A11) -> A L EAU MUSIC
A12: A PART ENTIERE | B12: 2000 | D12: =ISBLANK(B12) -> FALSE | E12: =if(D13=TRUE, CONCATENATE(A12," ",A13),A12) -> A PART ENTIERE
A13: A PETIT PAS | B13: 3000 | D13: =ISBLANK(B13) -> FALSE | E13: =if(D14=TRUE, CONCATENATE(A13," ",A14),A13) -> A PETIT PAS
A14: A TRAVERS CHANT | B14: 0 | C14: Locaux | D14: =ISBLANK(B14) -> FALSE | E14: =if(D15=TRUE, CONCATENATE(A14," ",A15),A14) -> A TRAVERS CHANT
A15: A2RUNNING | B15: 0 | C15: Locaux | D15: =ISBLANK(B15) -> FALSE | E15: =if(D16=TRUE, CONCATENATE(A15," ",A16),A15) -> A2RUNNING
A16: ABALONE CHASSE BORDEAUX | B16: 0 | C16: Locaux, équipements sportifs | D16: =ISBLANK(B16) -> FALSE | E16: =if(D17=TRUE, CONCATENATE(A16," ",A17),A16) -> ABALONE CHASSE BORDEAUX
A17: ABEILLES BORDELAISES | B17: 0 | C17: Locaux | D17: =ISBLANK(B17) -> FALSE | E17: =if(D18=TRUE, CONCATENATE(A17," ",A18),A17) -> ABEILLES BORDELAISES
A18: ACADEMIE BUSHIKAI KARATE DO | B18: 0 | C18: Equipements sportifs | D18: =ISBLANK(B18) -> FALSE | E18: =if(D19=TRUE, CONCATENATE(A18," ",A19),A18) -> ACADEMIE BUSHIKAI KARATE DO
A19: ACADEMIE DES SCIENCES, BELLES LETTRES ET ARTS DE | B19: 7600 | C19: Locaux, matériel pour manifestations | D19: =ISBLANK(B19) -> FALSE | E19: =if(D20=TRUE, CONCATENATE(A19," ",A20),A19) -> ACADEMIE DES SCIENCES, BELLES LETTRES ET ARTS DE BORDEAUX
A20: BORDEAUX | D20: =ISBLANK(B20) -> TRUE | E20: =if(D21=TRUE, CONCATENATE(A20," ",A21),A20) -> BORDEAUX
A21: ACADEMIE PROSPECTIVE NOUVELLES TECHNOLOGIES | B21: 0 | C21: Locaux | D21: =ISBLANK(B21) -> FALSE | E21: =if(D22=TRUE, CONCATENATE(A21," ",A22),A21) -> ACADEMIE PROSPECTIVE NOUVELLES TECHNOLOGIES
A22: ACADEMIE YOUNUS | B22: 22000 | C22: Locaux, équipements sportifs, matériel pour | D22: =ISBLANK(B22) -> FALSE | E22: =if(D23=TRUE, CONCATENATE(A22," ",A23),A22) -> ACADEMIE YOUNUS
C23: manifestations | D23: =ISBLANK(B23) -> TRUE | E23: =if(D24=TRUE, CONCATENATE(A23," ",A24),A23)
A24: ACCOMPAGNEMENT ET RECHERCHE PSYCHO-SOCIO EDUCATIFS | B24: 0 | C24: Locaux | D24: =ISBLANK(B24) -> FALSE | E24: =if(D25=TRUE, CONCATENATE(A24," ",A25),A24) -> ACCOMPAGNEMENT ET RECHERCHE PSYCHO-SOCIO EDUCATIFS POUR LES JEUNES (ARPEJE)
A25: POUR LES JEUNES (ARPEJE) | D25: =ISBLANK(B25) -> TRUE | E25: =if(D26=TRUE, CONCATENATE(A25," ",A26),A25) -> POUR LES JEUNES (ARPEJE)
A26: ACCOMPAGNEMENT PSYCHOLOGIQUE ET MEDIATION | B26: 5000 | D26: =ISBLANK(B26) -> FALSE | E26: =if(D27=TRUE, CONCATENATE(A26," ",A27),A26) -> ACCOMPAGNEMENT PSYCHOLOGIQUE ET MEDIATION INTERCULTURELLE - AMI
A27: INTERCULTURELLE - AMI | D27: =ISBLANK(B27) -> TRUE | E27: =if(D28=TRUE, CONCATENATE(A27," ",A28),A27) -> INTERCULTURELLE - AMI
A28: ACCOMPAGNER CONDUIRE TRANSMETTRE - ACT | B28: 300 | C28: Locaux | D28: =ISBLANK(B28) -> FALSE | E28: =if(D29=TRUE, CONCATENATE(A28," ",A29),A28) -> ACCOMPAGNER CONDUIRE TRANSMETTRE - ACT
A29: ACCORDERIE BORDEAUX SUD | B29: 4500 | C29: Locaux | D29: =ISBLANK(B29) -> FALSE | E29: =if(D30=TRUE, CONCATENATE(A29," ",A30),A29) -> ACCORDERIE BORDEAUX SUD
A30: ACHATS GROUPES ASSOCIATIF POUR L'ECONOMIE SOLIDAIRE DE | B30: 0 | C30: Locaux | D30: =ISBLANK(B30) -> FALSE | E30: =if(D31=TRUE, CONCATENATE(A30," ",A31),A30) -> ACHATS GROUPES ASSOCIATIF POUR L'ECONOMIE SOLIDAIRE DE BORDEAUX - AGAPES
A31: BORDEAUX - AGAPES | D31: =ISBLANK(B31) -> TRUE | E31: =if(D32=TRUE, CONCATENATE(A31," ",A32),A31) -> BORDEAUX - AGAPES
A32: ACIDD, ASSOCIATION COMMUNICATION ET INFORMATION POUR LE | B32: 10000 | C32: Locaux | D32: =ISBLANK(B32) -> FALSE | E32: =if(D33=TRUE, CONCATENATE(A32," ",A33),A32) -> ACIDD, ASSOCIATION COMMUNICATION ET INFORMATION POUR LE DEVELOPPEMENT DURABLE
A33: DEVELOPPEMENT DURABLE | D33: =ISBLANK(B33) -> TRUE | E33: =if(D34=TRUE, CONCATENATE(A33," ",A34),A33) -> DEVELOPPEMENT DURABLE
A34: ACINQBYS_ESPACE 29 A5BIS | B34: 22000 | D34: =ISBLANK(B34) -> FALSE | E34: =if(D35=TRUE, CONCATENATE(A34," ",A35),A34) -> ACINQBYS_ESPACE 29 A5BIS
A35: ACTA GIRONDE - AGIR CONTRE LA TORTURE DES ANIMAUX | B35: 0 | C35: Locaux | D35: =ISBLANK(B35) -> FALSE | E35: =if(D36=TRUE, CONCATENATE(A35," ",A36),A35) -> ACTA GIRONDE - AGIR CONTRE LA TORTURE DES ANIMAUX
A36: ACTIFS 33 | B36: 2400 | D36: =ISBLANK(B36) -> FALSE | E36: =if(D37=TRUE, CONCATENATE(A36," ",A37),A36) -> ACTIFS 33
A37: ACTIMAGE | B37: 6500 | D37: =ISBLANK(B37) -> FALSE | E37: =if(D38=TRUE, CONCATENATE(A37," ",A38),A37) -> ACTIMAGE
A38: ACTION CONTRE LA FAIM | B38: 0 | C38: Locaux | D38: =ISBLANK(B38) -> FALSE | E38: =if(D39=TRUE, CONCATENATE(A38," ",A39),A38) -> ACTION CONTRE LA FAIM
A39: ACTION INTERNATIONALE POUR LA PAIX ET LE DEVELOPPEMENT | B39: 0 | C39: Locaux | D39: =ISBLANK(B39) -> FALSE | E39: =if(D40=TRUE, CONCATENATE(A39," ",A40),A39) -> ACTION INTERNATIONALE POUR LA PAIX ET LE DEVELOPPEMENT
A40: AD LUCEM THEATRE | B40: 0 | C40: Locaux | D40: =ISBLANK(B40) -> FALSE | E40: =if(D41=TRUE, CONCATENATE(A40," ",A41),A40) -> AD LUCEM THEATRE
...

Sheet etape3
A1: on rajoute les en-têtes et on se prépare à supprimer les lignes qui ont un "TRUE". Elle correspondant à des morceaux de données inutiles, qu'on a déjà recollés par ailleurs. Mais comme ma formule de colonne E s'appuie sur le TRUE, il faut que je copie toute la colonne E et que je fasse edition --> collage spécial --> coller uniquement les valeurs dans la colonne E. Là c'est juste les résultats qui restent, la formule derrière a disparu. Je peux supprimer mes TRUE sans souci
B2: Montant du fonds de concours ou de la subvention (numéraire) | C2: Prestations en nature | D2: isblank | E2: nom des bénéficiaires
A3: "BAMBINO BERTHELOT" ASSOCIATION DE PARENTS D'ELEVES DE | B3: 0 | C3: Locaux | D3: =ISBLANK(B3) -> FALSE | E3: "BAMBINO BERTHELOT" ASSOCIATION DE PARENTS D'ELEVES DE L'ECOLE MATERNELLE BERTHELOT A BORDEAUX
A4: L'ECOLE MATERNELLE BERTHELOT A BORDEAUX | D4: =ISBLANK(B4) -> TRUE | E4: L'ECOLE MATERNELLE BERTHELOT A BORDEAUX
A5: 1001 JEUNES BORDELAIS | B5: 0 | C5: Matériel pour manifestations | D5: =ISBLANK(B5) -> FALSE | E5: 1001 JEUNES BORDELAIS
A6: 2AA | B6: 0 | C6: Locaux | D6: =ISBLANK(B6) -> FALSE | E6: 2AA
A7: 2SI2LA | B7: 0 | C7: Locaux | D7: =ISBLANK(B7) -> FALSE | E7: 2SI2LA
A8: 4 CATS | B8: 0 | C8: Locaux | D8: =ISBLANK(B8) -> FALSE | E8: 4 CATS
A9: 5UN7 | B9: 1000 | D9: =ISBLANK(B9) -> FALSE | E9: 5UN7
A10: 60 000 REBONDS | B10: 1800 | D10: =ISBLANK(B10) -> FALSE | E10: 60 000 REBONDS
A11: 9-33 | B11: 19000 | C11: Communication, locaux | D11: =ISBLANK(B11) -> FALSE | E11: 9-33
A12: A L EAU MUSIC | B12: 500 | D12: =ISBLANK(B12) -> FALSE | E12: A L EAU MUSIC
A13: A PART ENTIERE | B13: 2000 | D13: =ISBLANK(B13) -> FALSE | E13: A PART ENTIERE
A14: A PETIT PAS | B14: 3000 | D14: =ISBLANK(B14) -> FALSE | E14: A PETIT PAS
A15: A TRAVERS CHANT | B15: 0 | C15: Locaux | D15: =ISBLANK(B15) -> FALSE | E15: A TRAVERS CHANT
A16: A2RUNNING | B16: 0 | C16: Locaux | D16: =ISBLANK(B16) -> FALSE | E16: A2RUNNING
A17: ABALONE CHASSE BORDEAUX | B17: 0 | C17: Locaux, équipements sportifs | D17: =ISBLANK(B17) -> FALSE | E17: ABALONE CHASSE BORDEAUX
A18: ABEILLES BORDELAISES | B18: 0 | C18: Locaux | D18: =ISBLANK(B18) -> FALSE | E18: ABEILLES BORDELAISES
A19: ACADEMIE BUSHIKAI KARATE DO | B19: 0 | C19: Equipements sportifs | D19: =ISBLANK(B19) -> FALSE | E19: ACADEMIE BUSHIKAI KARATE DO
A20: ACADEMIE DES SCIENCES, BELLES LETTRES ET ARTS DE | B20: 7600 | C20: Locaux, matériel pour manifestations | D20: =ISBLANK(B20) -> FALSE | E20: ACADEMIE DES SCIENCES, BELLES LETTRES ET ARTS DE BORDEAUX
A21: BORDEAUX | D21: =ISBLANK(B21) -> TRUE | E21: BORDEAUX
A22: ACADEMIE PROSPECTIVE NOUVELLES TECHNOLOGIES | B22: 0 | C22: Locaux | D22: =ISBLANK(B22) -> FALSE | E22: ACADEMIE PROSPECTIVE NOUVELLES TECHNOLOGIES
A23: ACADEMIE YOUNUS | B23: 22000 | C23: Locaux, équipements sportifs, matériel pour | D23: =ISBLANK(B23) -> FALSE | E23: ACADEMIE YOUNUS
C24: manifestations | D24: =ISBLANK(B24) -> TRUE
A25: ACCOMPAGNEMENT ET RECHERCHE PSYCHO-SOCIO EDUCATIFS | B25: 0 | C25: Locaux | D25: =ISBLANK(B25) -> FALSE | E25: ACCOMPAGNEMENT ET RECHERCHE PSYCHO-SOCIO EDUCATIFS POUR LES JEUNES (ARPEJE)
A26: POUR LES JEUNES (ARPEJE) | D26: =ISBLANK(B26) -> TRUE | E26: POUR LES JEUNES (ARPEJE)
A27: ACCOMPAGNEMENT PSYCHOLOGIQUE ET MEDIATION | B27: 5000 | D27: =ISBLANK(B27) -> FALSE | E27: ACCOMPAGNEMENT PSYCHOLOGIQUE ET MEDIATION INTERCULTURELLE - AMI
A28: INTERCULTURELLE - AMI | D28: =ISBLANK(B28) -> TRUE | E28: INTERCULTURELLE - AMI
A29: ACCOMPAGNER CONDUIRE TRANSMETTRE - ACT | B29: 300 | C29: Locaux | D29: =ISBLANK(B29) -> FALSE | E29: ACCOMPAGNER CONDUIRE TRANSMETTRE - ACT
A30: ACCORDERIE BORDEAUX SUD | B30: 4500 | C30: Locaux | D30: =ISBLANK(B30) -> FALSE | E30: ACCORDERIE BORDEAUX SUD
A31: ACHATS GROUPES ASSOCIATIF POUR L'ECONOMIE SOLIDAIRE DE | B31: 0 | C31: Locaux | D31: =ISBLANK(B31) -> FALSE | E31: ACHATS GROUPES ASSOCIATIF POUR L'ECONOMIE SOLIDAIRE DE BORDEAUX - AGAPES
A32: BORDEAUX - AGAPES | D32: =ISBLANK(B32) -> TRUE | E32: BORDEAUX - AGAPES
A33: ACIDD, ASSOCIATION COMMUNICATION ET INFORMATION POUR LE | B33: 10000 | C33: Locaux | D33: =ISBLANK(B33) -> FALSE | E33: ACIDD, ASSOCIATION COMMUNICATION ET INFORMATION POUR LE DEVELOPPEMENT DURABLE
A34: DEVELOPPEMENT DURABLE | D34: =ISBLANK(B34) -> TRUE | E34: DEVELOPPEMENT DURABLE
A35: ACINQBYS_ESPACE 29 A5BIS | B35: 22000 | D35: =ISBLANK(B35) -> FALSE | E35: ACINQBYS_ESPACE 29 A5BIS
A36: ACTA GIRONDE - AGIR CONTRE LA TORTURE DES ANIMAUX | B36: 0 | C36: Locaux | D36: =ISBLANK(B36) -> FALSE | E36: ACTA GIRONDE - AGIR CONTRE LA TORTURE DES ANIMAUX
A37: ACTIFS 33 | B37: 2400 | D37: =ISBLANK(B37) -> FALSE | E37: ACTIFS 33
A38: ACTIMAGE | B38: 6500 | D38: =ISBLANK(B38) -> FALSE | E38: ACTIMAGE
A39: ACTION CONTRE LA FAIM | B39: 0 | C39: Locaux | D39: =ISBLANK(B39) -> FALSE | E39: ACTION CONTRE LA FAIM
A40: ACTION INTERNATIONALE POUR LA PAIX ET LE DEVELOPPEMENT | B40: 0 | C40: Locaux | D40: =ISBLANK(B40) -> FALSE | E40: ACTION INTERNATIONALE POUR LA PAIX ET LE DEVELOPPEMENT
...

Sheet etape4
A1: Je crée un filtre sur la colonne "isblank" et je filtre seulement les TRUE, afin de les supprimer: magique, il ne reste plus que les FALSE!
B2: Montant du fonds de concours ou de la subvention (numéraire) | C2: Prestations en nature | D2: isblank | E2: nom des bénéficiaires
A3: "BAMBINO BERTHELOT" ASSOCIATION DE PARENTS D'ELEVES DE | B3: 0 | C3: Locaux | D3: =ISBLANK(B3) -> FALSE | E3: "BAMBINO BERTHELOT" ASSOCIATION DE PARENTS D'ELEVES DE L'ECOLE MATERNELLE BERTHELOT A BORDEAUX
A4: 1001 JEUNES BORDELAIS | B4: 0 | C4: Matériel pour manifestations | D4: =ISBLANK(B4) -> FALSE | E4: 1001 JEUNES BORDELAIS
A5: 2AA | B5: 0 | C5: Locaux | D5: =ISBLANK(B5) -> FALSE | E5: 2AA
A6: 2SI2LA | B6: 0 | C6: Locaux | D6: =ISBLANK(B6) -> FALSE | E6: 2SI2LA
A7: 4 CATS | B7: 0 | C7: Locaux | D7: =ISBLANK(B7) -> FALSE | E7: 4 CATS
A8: 5UN7 | B8: 1000 | D8: =ISBLANK(B8) -> FALSE | E8: 5UN7
A9: 60 000 REBONDS | B9: 1800 | D9: =ISBLANK(B9) -> FALSE | E9: 60 000 REBONDS
A10: 9-33 | B10: 19000 | C10: Communication, locaux | D10: =ISBLANK(B10) -> FALSE | E10: 9-33
A11: A L EAU MUSIC | B11: 500 | D11: =ISBLANK(B11) -> FALSE | E11: A L EAU MUSIC
A12: A PART ENTIERE | B12: 2000 | D12: =ISBLANK(B12) -> FALSE | E12: A PART ENTIERE
A13: A PETIT PAS | B13: 3000 | D13: =ISBLANK(B13) -> FALSE | E13: A PETIT PAS
A14: A TRAVERS CHANT | B14: 0 | C14: Locaux | D14: =ISBLANK(B14) -> FALSE | E14: A TRAVERS CHANT
A15: A2RUNNING | B15: 0 | C15: Locaux | D15: =ISBLANK(B15) -> FALSE | E15: A2RUNNING
A16: ABALONE CHASSE BORDEAUX | B16: 0 | C16: Locaux, équipements sportifs | D16: =ISBLANK(B16) -> FALSE | E16: ABALONE CHASSE BORDEAUX
A17: ABEILLES BORDELAISES | B17: 0 | C17: Locaux | D17: =ISBLANK(B17) -> FALSE | E17: ABEILLES BORDELAISES
A18: ACADEMIE BUSHIKAI KARATE DO | B18: 0 | C18: Equipements sportifs | D18: =ISBLANK(B18) -> FALSE | E18: ACADEMIE BUSHIKAI KARATE DO
A19: ACADEMIE DES SCIENCES, BELLES LETTRES ET ARTS DE | B19: 7600 | C19: Locaux, matériel pour manifestations | D19: =ISBLANK(B19) -> FALSE | E19: ACADEMIE DES SCIENCES, BELLES LETTRES ET ARTS DE BORDEAUX
A20: ACADEMIE PROSPECTIVE NOUVELLES TECHNOLOGIES | B20: 0 | C20: Locaux | D20: =ISBLANK(B20) -> FALSE | E20: ACADEMIE PROSPECTIVE NOUVELLES TECHNOLOGIES
A21: ACADEMIE YOUNUS | B21: 22000 | C21: Locaux, équipements sportifs, matériel pour | D21: =ISBLANK(B21) -> FALSE | E21: ACADEMIE YOUNUS
A22: ACCOMPAGNEMENT ET RECHERCHE PSYCHO-SOCIO EDUCATIFS | B22: 0 | C22: Locaux | D22: =ISBLANK(B22) -> FALSE | E22: ACCOMPAGNEMENT ET RECHERCHE PSYCHO-SOCIO EDUCATIFS POUR LES JEUNES (ARPEJE)
A23: ACCOMPAGNEMENT PSYCHOLOGIQUE ET MEDIATION | B23: 5000 | D23: =ISBLANK(B23) -> FALSE | E23: ACCOMPAGNEMENT PSYCHOLOGIQUE ET MEDIATION INTERCULTURELLE - AMI
A24: ACCOMPAGNER CONDUIRE TRANSMETTRE - ACT | B24: 300 | C24: Locaux | D24: =ISBLANK(B24) -> FALSE | E24: ACCOMPAGNER CONDUIRE TRANSMETTRE - ACT
A25: ACCORDERIE BORDEAUX SUD | B25: 4500 | C25: Locaux | D25: =ISBLANK(B25) -> FALSE | E25: ACCORDERIE BORDEAUX SUD
A26: ACHATS GROUPES ASSOCIATIF POUR L'ECONOMIE SOLIDAIRE DE | B26: 0 | C26: Locaux | D26: =ISBLANK(B26) -> FALSE | E26: ACHATS GROUPES ASSOCIATIF POUR L'ECONOMIE SOLIDAIRE DE BORDEAUX - AGAPES
A27: ACIDD, ASSOCIATION COMMUNICATION ET INFORMATION POUR LE | B27: 10000 | C27: Locaux | D27: =ISBLANK(B27) -> FALSE | E27: ACIDD, ASSOCIATION COMMUNICATION ET INFORMATION POUR LE DEVELOPPEMENT DURABLE
A28: ACINQBYS_ESPACE 29 A5BIS | B28: 22000 | D28: =ISBLANK(B28) -> FALSE | E28: ACINQBYS_ESPACE 29 A5BIS
A29: ACTA GIRONDE - AGIR CONTRE LA TORTURE DES ANIMAUX | B29: 0 | C29: Locaux | D29: =ISBLANK(B29) -> FALSE | E29: ACTA GIRONDE - AGIR CONTRE LA TORTURE DES ANIMAUX
A30: ACTIFS 33 | B30: 2400 | D30: =ISBLANK(B30) -> FALSE | E30: ACTIFS 33
A31: ACTIMAGE | B31: 6500 | D31: =ISBLANK(B31) -> FALSE | E31: ACTIMAGE
A32: ACTION CONTRE LA FAIM | B32: 0 | C32: Locaux | D32: =ISBLANK(B32) -> FALSE | E32: ACTION CONTRE LA FAIM
A33: ACTION INTERNATIONALE POUR LA PAIX ET LE DEVELOPPEMENT | B33: 0 | C33: Locaux | D33: =ISBLANK(B33) -> FALSE | E33: ACTION INTERNATIONALE POUR LA PAIX ET LE DEVELOPPEMENT
A34: AD LUCEM THEATRE | B34: 0 | C34: Locaux | D34: =ISBLANK(B34) -> FALSE | E34: AD LUCEM THEATRE
A35: ADDAH 33 | B35: 500 | D35: =ISBLANK(B35) -> FALSE | E35: ADDAH 33
A36: ADORA | B36: 5000 | C36: Locaux | D36: =ISBLANK(B36) -> FALSE | E36: ADORA
A37: ADRIA | B37: 1500 | D37: =ISBLANK(B37) -> FALSE | E37: ADRIA
A38: AEP SAINT PROJET | B38: 0 | C38: Matériel pour manifestations | D38: =ISBLANK(B38) -> FALSE | E38: AEP SAINT PROJET
A39: AFRICAFRANCE | B39: 1500 | D39: =ISBLANK(B39) -> FALSE | E39: AFRICAFRANCE
A40: AGENCE D'URBANISME BORDEAUX METROPOLE AQUITAINE | B40: 60000 | D40: =ISBLANK(B40) -> FALSE | E40: AGENCE D'URBANISME BORDEAUX METROPOLE AQUITAINE (A'URBA)
...

Sheet etape5
A1: Je peux désormais reconstituter mon jeu de données original, en suppriman la colonne A et en bougeant la colonne E pour qu'elle devienne la nouvelle colonne A. Je supprime aussi la colonne isblank, qui nous aura bien aidé
A2: nom des bénéficiaires | B2: Montant du fonds de concours ou de la subvention (numéraire) | C2: Prestations en nature
A3: "BAMBINO BERTHELOT" ASSOCIATION DE PARENTS D'ELEVES DE L'ECOLE MATERNELLE BERTHELOT A BORDEAUX | B3: 0 | C3: Locaux
A4: 1001 JEUNES BORDELAIS | B4: 0 | C4: Matériel pour manifestations
A5: 2AA | B5: 0 | C5: Locaux
A6: 2SI2LA | B6: 0 | C6: Locaux
A7: 4 CATS | B7: 0 | C7: Locaux
A8: 5UN7 | B8: 1000
A9: 60 000 REBONDS | B9: 1800
A10: 9-33 | B10: 19000 | C10: Communication, locaux
A11: A L EAU MUSIC | B11: 500
A12: A PART ENTIERE | B12: 2000
A13: A PETIT PAS | B13: 3000
A14: A TRAVERS CHANT | B14: 0 | C14: Locaux
A15: A2RUNNING | B15: 0 | C15: Locaux
A16: ABALONE CHASSE BORDEAUX | B16: 0 | C16: Locaux, équipements sportifs
A17: ABEILLES BORDELAISES | B17: 0 | C17: Locaux
A18: ACADEMIE BUSHIKAI KARATE DO | B18: 0 | C18: Equipements sportifs
A19: ACADEMIE DES SCIENCES, BELLES LETTRES ET ARTS DE BORDEAUX | B19: 7600 | C19: Locaux, matériel pour manifestations
A20: ACADEMIE PROSPECTIVE NOUVELLES TECHNOLOGIES | B20: 0 | C20: Locaux
A21: ACADEMIE YOUNUS | B21: 22000 | C21: Locaux, équipements sportifs, matériel pour
A22: ACCOMPAGNEMENT ET RECHERCHE PSYCHO-SOCIO EDUCATIFS POUR LES JEUNES (ARPEJE) | B22: 0 | C22: Locaux
A23: ACCOMPAGNEMENT PSYCHOLOGIQUE ET MEDIATION INTERCULTURELLE - AMI | B23: 5000
A24: ACCOMPAGNER CONDUIRE TRANSMETTRE - ACT | B24: 300 | C24: Locaux
A25: ACCORDERIE BORDEAUX SUD | B25: 4500 | C25: Locaux
A26: ACHATS GROUPES ASSOCIATIF POUR L'ECONOMIE SOLIDAIRE DE BORDEAUX - AGAPES | B26: 0 | C26: Locaux
A27: ACIDD, ASSOCIATION COMMUNICATION ET INFORMATION POUR LE DEVELOPPEMENT DURABLE | B27: 10000 | C27: Locaux
A28: ACINQBYS_ESPACE 29 A5BIS | B28: 22000
A29: ACTA GIRONDE - AGIR CONTRE LA TORTURE DES ANIMAUX | B29: 0 | C29: Locaux
A30: ACTIFS 33 | B30: 2400
A31: ACTIMAGE | B31: 6500
A32: ACTION CONTRE LA FAIM | B32: 0 | C32: Locaux
A33: ACTION INTERNATIONALE POUR LA PAIX ET LE DEVELOPPEMENT | B33: 0 | C33: Locaux
A34: AD LUCEM THEATRE | B34: 0 | C34: Locaux
A35: ADDAH 33 | B35: 500
A36: ADORA | B36: 5000 | C36: Locaux
A37: ADRIA | B37: 1500
A38: AEP SAINT PROJET | B38: 0 | C38: Matériel pour manifestations
A39: AFRICAFRANCE | B39: 1500
A40: AGENCE D'URBANISME BORDEAUX METROPOLE AQUITAINE (A'URBA) | B40: 60000
...

Sheet clean
A1: nom des bénéficiaires | B1: Montant du fonds de concours ou de la subvention (numéraire) | C1: Prestations en nature
A2: OPERA NATIONAL DE BORDEAUX | B2: 16167670
A3: ASSOCIATION DES CENTRES D'ANIMATION DE QUARTIERS DE BORDEAUX - ACAQB | B3: 8060927.5 | C3: Communication, locaux, équipements sportifs,
A4: CCAS DE BORDEAUX | B4: 7912204
A5: ECOLE D'ENSEIGNEMENT SUPÉRIEUR D'ART DE BORDEAUX - ESAB | B5: 3120000
A6: ASSOCIATION PITCHOUN | B6: 1735000 | C6: Locaux
A7: THEATRE NATIONAL DE BORDEAUX EN AQUITAINE - TNBA | B7: 1646816 | C7: Communication, locaux
A8: ASSOCIATION PETITE ENFANCE ENFANCE ET FAMILLE - APEEF | B8: 1578403 | C8: Locaux, matériel pour manifestations
A9: UNION SAINT-BRUNO | B9: 1537650 | C9: Locaux, équipements sportifs, matériel pour
A10: SPORTING CHANTECLER BORDEAUX NORD LE LAC | B10: 1128560 | C10: Locaux, équipements sportifs, matériel pour
A11: AVANT GARDE ET JEANNE D'ARC DE BORDEAUX CAUDERAN - AGJA BORDEAUX CAUDERAN | B11: 1089439 | C11: Locaux, équipements sportifs, matériel pour
A12: UNION SPORTIVE LES CHARTRONS | B12: 896350 | C12: Locaux, équipements sportifs, matériel pour
A13: LES JEUNES DE SAINT AUGUSTIN - JSA | B13: 892663 | C13: Locaux, équipements sportifs, matériel pour
A14: UNION SAINT JEAN - MAISON DE QUARTIER | B14: 879983 | C14: Locaux, équipements sportifs, matériel pour
A15: STADE BORDELAIS ASPTT | B15: 819458 | C15: Locaux, équipements sportifs, matériel pour
A16: ARC EN REVE | B16: 752250 | C16: Communication, matériel pour manifestations, locaux
A17: MAISON DE L'EMPLOI, DE L'INSERTION ECONOMIQUE ET DE L'ENTREPRISE DE BORDEAUX | B17: 678000
A18: CLUB PYRENEES AQUITAINE, ASSOCIATION SPORTIVE, EDUCATIVE ET CULTURELLE | B18: 634600 | C18: Locaux, équipements sportifs, matériel pour
A19: P'TIT BOUT'CHOU | B19: 567000 | C19: Matériel pour manifestations
A20: ASSOCIATION BRINS D'EVEIL | B20: 532800
A21: ASSOCIATION DE GESTION ET D'ANIMATION DES CRECHES C.S.F. (AGEAC/CSF) | B21: 512833.33
A22: MISSION LOCALE BORDEAUX AVENIR JEUNES | B22: 494000 | C22: Locaux, matériel pour manifestations
A23: GP INTENCITE CENTRE SOCIAL ET CULTUREL DU GRAND PARC | B23: 492222 | C23: Locaux, matériel pour manifestations
A24: INTERLUDE | B24: 478850 | C24: Locaux, matériel pour manifestations
A25: CENTRE SOCIAL ET FAMILIAL BORDEAUX NORD | B25: 461165 | C25: Locaux, équipements sportifs, matériel pour
A26: AMICALE LAIQUE DAVID JOHNSTON LAGRANGE ALBERT BARRAUD NAUJAC | B26: 450195 | C26: Equipements sportifs
A27: SASP UNION BORDEAUX BEGLES | B27: 450000 | C27: Matériel pour manifestations
A28: FOYER FRATERNEL | B28: 426565 | C28: Locaux, matériel pour manifestations
A29: FESTIVAL DES ARTS DE BORDEAUX | B29: 402000 | C29: Communication, locaux
A30: ASSOCIATION DU COMITE DES OEUVRES SOCIALES DES MUNICIPAUX DE BORDEAUX - ACOSMB | B30: 380000 | C30: Matériel pour manifestations
A31: POLE D'ENSEIGNEMENT SUPERIEUR DE LA MUSIQUE ET DE LA DANSE DE BORDEAUX AQUITAINE - PESMD | B31: 357672 | C31: Locaux
A32: AUTEUIL PETITE ENFANCE | B32: 347000
A33: LES COQS ROUGES | B33: 343924 | C33: Equipements sportifs, matériel pour manifestations
A34: BORDEAUX GRANDS EVENEMENTS (BGE) | B34: 339500 | C34: Communication, locaux
A35: GESTION DU CENTRE DE LOISIRS DE LA POSTE ALEMA | B35: 334000
A36: ASSOCIATION PETITS BOUCHONS | B36: 311500
A37: ASSOCIATION POUR L'INNOVATION EN MATIERE D'INTEGRATION | B37: 300000
A38: BOXERS DE BORDEAUX | B38: 283000
A39: SASP JSA BORDEAUX METROPOLE | B39: 280000 | C39: Matériel pour manifestations
A40: CLUB ATHLETIQUE MUNICIPAL DE BORDEAUX - CAM | B40: 243834 | C40: Locaux, équipements sportifs, matériel pour
...

Sheet verif1
A1: Maintenant que j'ai une jeu de données propre, je peux passer à l'étape de vérification statistique: je vais regarder des indicateurs statistiques classiques qui me donneront une idée de si il y a des choses étranges qui se passent dans mon jeu de données. Ici par exemple, le fait que la médiane et la moyenne soient à 0 signifie que la majorité des associations ne reçoivent aucun appui financier. Est-ce que cela fait sens ? C'est là où votre bon sens et votre connaissance du contexte doit vous guider : impossible d'analyser des données sans comprendre leur contexte ! Ici vous pouvez aussi comparer le total obtenu avec le total affiché dans le PDF. Si le chiffre n'est pas le même, préparez-vous à vérifier 2, 3 fois toutes vos étapes d'extraction et de nettoyage de données. Si le décalage reste toujours, l'erreur est peut-être dans le fichier d'origine !
A2: COUNT | B2: =COUNT(B9:B1541) -> 1533
A3: MAXIMUM | B3: =MAX(B9:B1541) -> 16167670
A4: MINIMUM | B4: =MIN(B9:B1541) -> 0
A5: MEDIANE | B5: =MEDIAN(B9:B1541) -> 0
A6: MOYENNE | B6: =AVERAGE(B9:B1541) -> 44559.533
A7: TOTAL | B7: =SUM(B9:B1541) -> 68309764
A8: nom des bénéficiaires | B8: Montant du fonds de concours ou de la subvention (numéraire) | C8: Prestations en nature
A9: "BAMBINO BERTHELOT" ASSOCIATION DE PARENTS D'ELEVES DE L'ECOLE MATERNELLE BERTHELOT A BORDEAUX | B9: 0 | C9: Locaux
A10: 1001 JEUNES BORDELAIS | B10: 0 | C10: Matériel pour manifestations
A11: 2AA | B11: 0 | C11: Locaux
A12: 2SI2LA | B12: 0 | C12: Locaux
A13: 4 CATS | B13: 0 | C13: Locaux
A14: 5UN7 | B14: 1000
A15: 60 000 REBONDS | B15: 1800
A16: 9-33 | B16: 19000 | C16: Communication, locaux
A17: A L EAU MUSIC | B17: 500
A18: A PART ENTIERE | B18: 2000
A19: A PETIT PAS | B19: 3000
A20: A TRAVERS CHANT | B20: 0 | C20: Locaux
A21: A2RUNNING | B21: 0 | C21: Locaux
A22: ABALONE CHASSE BORDEAUX | B22: 0 | C22: Locaux, équipements sportifs
A23: ABEILLES BORDELAISES | B23: 0 | C23: Locaux
A24: ACADEMIE BUSHIKAI KARATE DO | B24: 0 | C24: Equipements sportifs
A25: ACADEMIE DES SCIENCES, BELLES LETTRES ET ARTS DE BORDEAUX | B25: 7600 | C25: Locaux, matériel pour manifestations
A26: ACADEMIE PROSPECTIVE NOUVELLES TECHNOLOGIES | B26: 0 | C26: Locaux
A27: ACADEMIE YOUNUS | B27: 22000 | C27: Locaux, équipements sportifs, matériel pour
A28: ACCOMPAGNEMENT ET RECHERCHE PSYCHO-SOCIO EDUCATIFS POUR LES JEUNES (ARPEJE) | B28: 0 | C28: Locaux
A29: ACCOMPAGNEMENT PSYCHOLOGIQUE ET MEDIATION INTERCULTURELLE - AMI | B29: 5000
A30: ACCOMPAGNER CONDUIRE TRANSMETTRE - ACT | B30: 300 | C30: Locaux
A31: ACCORDERIE BORDEAUX SUD | B31: 4500 | C31: Locaux
A32: ACHATS GROUPES ASSOCIATIF POUR L'ECONOMIE SOLIDAIRE DE BORDEAUX - AGAPES | B32: 0 | C32: Locaux
A33: ACIDD, ASSOCIATION COMMUNICATION ET INFORMATION POUR LE DEVELOPPEMENT DURABLE | B33: 10000 | C33: Locaux
A34: ACINQBYS_ESPACE 29 A5BIS | B34: 22000
A35: ACTA GIRONDE - AGIR CONTRE LA TORTURE DES ANIMAUX | B35: 0 | C35: Locaux
A36: ACTIFS 33 | B36: 2400
A37: ACTIMAGE | B37: 6500
A38: ACTION CONTRE LA FAIM | B38: 0 | C38: Locaux
A39: ACTION INTERNATIONALE POUR LA PAIX ET LE DEVELOPPEMENT | B39: 0 | C39: Locaux
A40: AD LUCEM THEATRE | B40: 0 | C40: Locaux
...

Sheet analyse1
A1: nom des bénéficiaires | B1: Montant du fonds de concours ou de la subvention (numéraire) | C1: Prestations en nature | D1: avec/sans
A2: OPERA NATIONAL DE BORDEAUX | B2: 16167670 | D2: =IF(B2=0,"SANS","AVEC") -> AVEC
A3: ASSOCIATION DES CENTRES D'ANIMATION DE QUARTIERS DE BORDEAUX - ACAQB | B3: 8060927.5 | C3: Communication, locaux, équipements sportifs, | D3: =IF(B3=0,"SANS","AVEC") -> AVEC
A4: CCAS DE BORDEAUX | B4: 7912204 | D4: =IF(B4=0,"SANS","AVEC") -> AVEC
A5: ECOLE D'ENSEIGNEMENT SUPÉRIEUR D'ART DE BORDEAUX - ESAB | B5: 3120000 | D5: =IF(B5=0,"SANS","AVEC") -> AVEC
A6: ASSOCIATION PITCHOUN | B6: 1735000 | C6: Locaux | D6: =IF(B6=0,"SANS","AVEC") -> AVEC
A7: THEATRE NATIONAL DE BORDEAUX EN AQUITAINE - TNBA | B7: 1646816 | C7: Communication, locaux | D7: =IF(B7=0,"SANS","AVEC") -> AVEC
A8: ASSOCIATION PETITE ENFANCE ENFANCE ET FAMILLE - APEEF | B8: 1578403 | C8: Locaux, matériel pour manifestations | D8: =IF(B8=0,"SANS","AVEC") -> AVEC
A9: UNION SAINT-BRUNO | B9: 1537650 | C9: Locaux, équipements sportifs, matériel pour | D9: =IF(B9=0,"SANS","AVEC") -> AVEC
A10: SPORTING CHANTECLER BORDEAUX NORD LE LAC | B10: 1128560 | C10: Locaux, équipements sportifs, matériel pour | D10: =IF(B10=0,"SANS","AVEC") -> AVEC
A11: AVANT GARDE ET JEANNE D'ARC DE BORDEAUX CAUDERAN - AGJA BORDEAUX CAUDERAN | B11: 1089439 | C11: Locaux, équipements sportifs, matériel pour | D11: =IF(B11=0,"SANS","AVEC") -> AVEC
A12: UNION SPORTIVE LES CHARTRONS | B12: 896350 | C12: Locaux, équipements sportifs, matériel pour | D12: =IF(B12=0,"SANS","AVEC") -> AVEC
A13: LES JEUNES DE SAINT AUGUSTIN - JSA | B13: 892663 | C13: Locaux, équipements sportifs, matériel pour | D13: =IF(B13=0,"SANS","AVEC") -> AVEC
A14: UNION SAINT JEAN - MAISON DE QUARTIER | B14: 879983 | C14: Locaux, équipements sportifs, matériel pour | D14: =IF(B14=0,"SANS","AVEC") -> AVEC
A15: STADE BORDELAIS ASPTT | B15: 819458 | C15: Locaux, équipements sportifs, matériel pour | D15: =IF(B15=0,"SANS","AVEC") -> AVEC
A16: ARC EN REVE | B16: 752250 | C16: Communication, matériel pour manifestations, locaux | D16: =IF(B16=0,"SANS","AVEC") -> AVEC
A17: MAISON DE L'EMPLOI, DE L'INSERTION ECONOMIQUE ET DE L'ENTREPRISE DE BORDEAUX | B17: 678000 | D17: =IF(B17=0,"SANS","AVEC") -> AVEC
A18: CLUB PYRENEES AQUITAINE, ASSOCIATION SPORTIVE, EDUCATIVE ET CULTURELLE | B18: 634600 | C18: Locaux, équipements sportifs, matériel pour | D18: =IF(B18=0,"SANS","AVEC") -> AVEC
A19: P'TIT BOUT'CHOU | B19: 567000 | C19: Matériel pour manifestations | D19: =IF(B19=0,"SANS","AVEC") -> AVEC
A20: ASSOCIATION BRINS D'EVEIL | B20: 532800 | D20: =IF(B20=0,"SANS","AVEC") -> AVEC
A21: ASSOCIATION DE GESTION ET D'ANIMATION DES CRECHES C.S.F. (AGEAC/CSF) | B21: 512833.33 | D21: =IF(B21=0,"SANS","AVEC") -> AVEC
A22: MISSION LOCALE BORDEAUX AVENIR JEUNES | B22: 494000 | C22: Locaux, matériel pour manifestations | D22: =IF(B22=0,"SANS","AVEC") -> AVEC
A23: GP INTENCITE CENTRE SOCIAL ET CULTUREL DU GRAND PARC | B23: 492222 | C23: Locaux, matériel pour manifestations | D23: =IF(B23=0,"SANS","AVEC") -> AVEC
A24: INTERLUDE | B24: 478850 | C24: Locaux, matériel pour manifestations | D24: =IF(B24=0,"SANS","AVEC") -> AVEC
A25: CENTRE SOCIAL ET FAMILIAL BORDEAUX NORD | B25: 461165 | C25: Locaux, équipements sportifs, matériel pour | D25: =IF(B25=0,"SANS","AVEC") -> AVEC
A26: AMICALE LAIQUE DAVID JOHNSTON LAGRANGE ALBERT BARRAUD NAUJAC | B26: 450195 | C26: Equipements sportifs | D26: =IF(B26=0,"SANS","AVEC") -> AVEC
A27: SASP UNION BORDEAUX BEGLES | B27: 450000 | C27: Matériel pour manifestations | D27: =IF(B27=0,"SANS","AVEC") -> AVEC
A28: FOYER FRATERNEL | B28: 426565 | C28: Locaux, matériel pour manifestations | D28: =IF(B28=0,"SANS","AVEC") -> AVEC
A29: FESTIVAL DES ARTS DE BORDEAUX | B29: 402000 | C29: Communication, locaux | D29: =IF(B29=0,"SANS","AVEC") -> AVEC
A30: ASSOCIATION DU COMITE DES OEUVRES SOCIALES DES MUNICIPAUX DE BORDEAUX - ACOSMB | B30: 380000 | C30: Matériel pour manifestations | D30: =IF(B30=0,"SANS","AVEC") -> AVEC
A31: POLE D'ENSEIGNEMENT SUPERIEUR DE LA MUSIQUE ET DE LA DANSE DE BORDEAUX AQUITAINE - PESMD | B31: 357672 | C31: Locaux | D31: =IF(B31=0,"SANS","AVEC") -> AVEC
A32: AUTEUIL PETITE ENFANCE | B32: 347000 | D32: =IF(B32=0,"SANS","AVEC") -> AVEC
A33: LES COQS ROUGES | B33: 343924 | C33: Equipements sportifs, matériel pour manifestations | D33: =IF(B33=0,"SANS","AVEC") -> AVEC
A34: BORDEAUX GRANDS EVENEMENTS (BGE) | B34: 339500 | C34: Communication, locaux | D34: =IF(B34=0,"SANS","AVEC") -> AVEC
A35: GESTION DU CENTRE DE LOISIRS DE LA POSTE ALEMA | B35: 334000 | D35: =IF(B35=0,"SANS","AVEC") -> AVEC
A36: ASSOCIATION PETITS BOUCHONS | B36: 311500 | D36: =IF(B36=0,"SANS","AVEC") -> AVEC
A37: ASSOCIATION POUR L'INNOVATION EN MATIERE D'INTEGRATION | B37: 300000 | D37: =IF(B37=0,"SANS","AVEC") -> AVEC
A38: BOXERS DE BORDEAUX | B38: 283000 | D38: =IF(B38=0,"SANS","AVEC") -> AVEC
A39: SASP JSA BORDEAUX METROPOLE | B39: 280000 | C39: Matériel pour manifestations | D39: =IF(B39=0,"SANS","AVEC") -> AVEC
A40: CLUB ATHLETIQUE MUNICIPAL DE BORDEAUX - CAM | B40: 243834 | C40: Locaux, équipements sportifs, matériel pour | D40: =IF(B40=0,"SANS","AVEC") -> AVEC
...

Sheet analyse2
E2: %AVEC | F2: %SANS
E3: =B3/$B$23 -> 0.51486486 | F3: =C3/$C$23 -> 0
E4: =B4/$B$23 -> 0.0027027027 | F4: =C4/$C$23 -> 0.0050441362
E5: =B5/$B$23 -> 0.0013513514 | F5: =C5/$C$23 -> 0
E6: =B6/$B$23 -> 0.010810811 | F6: =C6/$C$23 -> 0.001261034
E7: =B7/$B$23 -> 0.0013513514 | F7: =C7/$C$23 -> 0
E8: =B8/$B$23 -> 0.0027027027 | F8: =C8/$C$23 -> 0
E9: =B9/$B$23 -> 0.012162162 | F9: =C9/$C$23 -> 0
E10: =B10/$B$23 -> 0.0013513514 | F10: =C10/$C$23 -> 0
E11: =B11/$B$23 -> 0.0040540541 | F11: =C11/$C$23 -> 0.001261034
E12: =B12/$B$23 -> 0.0027027027 | F12: =C12/$C$23 -> 0
E13: =B13/$B$23 -> 0.028378378 | F13: =C13/$C$23 -> 0.095838588
E14: =B14/$B$23 -> 0.013513514 | F14: =C14/$C$23 -> 0.011349306
... E22: =B22/$B$23 -> 0.097297297 | F22: =C22/$C$23 -> 0.16519546
E23: =SUM(E3:E22) -> 1 | F23: =SUM(F3:F22) -> 1

Sheet consolidvert1
A1: nom des bénéficiaires | B1: Montant du fonds de concours ou de la subvention (numéraire) | C1: Prestations en nature
A2: 100 PROPOS SANS REPONSE | B2: 760
A3: 1001 JEUNES BORDELAIS | B3: 0 | C3: Matériel pour manifestations
A4: 2A - ATELIERS ARTISTIQUES | B4: 0 | C4: Locaux
A5: 2MOIZAILES | B5: 500
A6: 5UN7 | B6: 2000
A7: 60 000 REBONDS | B7: 1800
A8: 9EME TEMPS | B8: 1600
A9: A FOND TU PEUX ! | B9: 0 | C9: Matériel pour manifestations
A10: A PART CA TOUT VA BIEN | B10: 0 | C10: Locaux
A11: A PART ENTIERE | B11: 700 | C11: Matériel pour manifestations
A12: A TRAVERS CHANT | B12: 0 | C12: Locaux
A13: A.A.O (AM ANGEGEBENEM ORT) | B13: 2000
A14: A2RUNNING | B14: 0 | C14: Locaux
A15: ABALONE CHASSE BORDEAUX - ACB | B15: 0 | C15: Equipements sportifs, locaux
A16: ABEILLES BORDELAISES | B16: 0 | C16: Locaux
A17: ABICE | B17: 0 | C17: Matériel pour manifestations
A18: ACADEMIE BUSHIKAI KARATE DO | B18: 0 | C18: Equipements sportifs
A19: ACADEMIE DES SCIENCES, BELLES LETTRES ET ARTS DE BORDEAUX | B19: 7600 | C19: Locaux
A20: ACADEMIE YOUNUS | B20: 22016 | C20: Matériel pour manifestations, équipements sportifs,
A21: ACARBO | B21: 0 | C21: Equipements sportifs
A22: ACCOMPAGNEMENT ET RECHERCHE PSYCHO-SOCIO EDUCATIFS POUR LES JEUNES (ARPEJE) | B22: 0 | C22: Locaux
A23: ACCOMPAGNEMENT PSYCHOLOGIQUE ET MEDIATION INTERCULTURELLE - AMI | B23: 7000 | C23: Locaux
A24: ACCOMPAGNEMENT RECHERCHE PSYCHO EDUCATIFS POUR LES JEUNES | B24: 1500
A25: ACCOMPAGNER CONDUIRE TRANSMETTRE - ACT | B25: 300 | C25: Locaux
A26: ACCORDERIE BORDEAUX | B26: 6180 | C26: Locaux
A27: ACEPP 33/47 - ASSOCIATION DES COLLECTIFS ENFANTS PARENTS PROFESSIONNELS 33/47 | B27: 0 | C27: Matériel pour manifestations
A28: ACIDD, ASSOCIATION COMMUNICATION ET INFORMATION POUR LE DEVELOPPEMENT DURABLE | B28: 10000 | C28: Locaux
A29: ACINQBYS_ESPACE 29 A5BIS | B29: 20000
A30: ACTA GIRONDE - AGIR CONTRE LA TORTURE DES ANIMAUX | B30: 0 | C30: Locaux
A31: ACTIFS 33 | B31: 2400
A32: ACTIMAGE | B32: 29000 | C32: Locaux
A33: ACTION INTERNATIONALE POUR LA PAIX ET LE DEVELOPPEMENT (AIPD) | B33: 0 | C33: Locaux
A34: ACTION JAZZ | B34: 10738 | C34: Matériel pour manifestations, locaux
A35: ACTIV'ACTION | B35: 0 | C35: Locaux
A36: AD HOC : ASSOCIATION DES DOCTORANTS EN DROIT DE L'UNIVERSITE DE BORDEAUX | B36: 0 | C36: Locaux
A37: ADDAH 33 | B37: 500
A38: ADORA - ASS. DEVELOPPEMENT ET ACCOMPAGNEMENT AQUITAINE ORIENTATION PERS. ET PROF. TOUT AU LONG VIE | B38: 8000 | C38: Locaux
A39: AEP SAINT GABRIEL | B39: 800
A40: AES | B40: 0 | C40: Locaux
...

Sheet consolidvert2
A1: Année | B1: nom des bénéficiaires | C1: Montant du fonds de concours ou de la subvention (numéraire) | D1: Prestations en nature
A2: 2016 | B2: OPERA NATIONAL DE BORDEAUX | C2: 16167670
A3: 2016 | B3: ASSOCIATION DES CENTRES D'ANIMATION DE QUARTIERS DE BORDEAUX - ACAQB | C3: 8060927.5 | D3: Communication, locaux, équipements sportifs,
A4: 2016 | B4: CCAS DE BORDEAUX | C4: 7912204
A5: 2016 | B5: ECOLE D'ENSEIGNEMENT SUPÉRIEUR D'ART DE BORDEAUX - ESAB | C5: 3120000
A6: 2016 | B6: ASSOCIATION PITCHOUN | C6: 1735000 | D6: Locaux
A7: 2016 | B7: THEATRE NATIONAL DE BORDEAUX EN AQUITAINE - TNBA | C7: 1646816 | D7: Communication, locaux
A8: 2016 | B8: ASSOCIATION PETITE ENFANCE ENFANCE ET FAMILLE - APEEF | C8: 1578403 | D8: Locaux, matériel pour manifestations
A9: 2016 | B9: UNION SAINT-BRUNO | C9: 1537650 | D9: Locaux, équipements sportifs, matériel pour
A10: 2016 | B10: SPORTING CHANTECLER BORDEAUX NORD LE LAC | C10: 1128560 | D10: Locaux, équipements sportifs, matériel pour
A11: 2016 | B11: AVANT GARDE ET JEANNE D'ARC DE BORDEAUX CAUDERAN - AGJA BORDEAUX CAUDERAN | C11: 1089439 | D11: Locaux, équipements sportifs, matériel pour
A12: 2016 | B12: UNION SPORTIVE LES CHARTRONS | C12: 896350 | D12: Locaux, équipements sportifs, matériel pour
A13: 2016 | B13: LES JEUNES DE SAINT AUGUSTIN - JSA | C13: 892663 | D13: Locaux, équipements sportifs, matériel pour
A14: 2016 | B14: UNION SAINT JEAN - MAISON DE QUARTIER | C14: 879983 | D14: Locaux, équipements sportifs, matériel pour
A15: 2016 | B15: STADE BORDELAIS ASPTT | C15: 819458 | D15: Locaux, équipements sportifs, matériel pour
A16: 2016 | B16: ARC EN REVE | C16: 752250 | D16: Communication, matériel pour manifestations, locaux
A17: 2016 | B17: MAISON DE L'EMPLOI, DE L'INSERTION ECONOMIQUE ET DE L'ENTREPRISE DE BORDEAUX | C17: 678000
A18: 2016 | B18: CLUB PYRENEES AQUITAINE, ASSOCIATION SPORTIVE, EDUCATIVE ET CULTURELLE | C18: 634600 | D18: Locaux, équipements sportifs, matériel pour
A19: 2016 | B19: P'TIT BOUT'CHOU | C19: 567000 | D19: Matériel pour manifestations
A20: 2016 | B20: ASSOCIATION BRINS D'EVEIL | C20: 532800
A21: 2016 | B21: ASSOCIATION DE GESTION ET D'ANIMATION DES CRECHES C.S.F. (AGEAC/CSF) | C21: 512833.33
A22: 2016 | B22: MISSION LOCALE BORDEAUX AVENIR JEUNES | C22: 494000 | D22: Locaux, matériel pour manifestations
A23: 2016 | B23: GP INTENCITE CENTRE SOCIAL ET CULTUREL DU GRAND PARC | C23: 492222 | D23: Locaux, matériel pour manifestations
A24: 2016 | B24: INTERLUDE | C24: 478850 | D24: Locaux, matériel pour manifestations
A25: 2016 | B25: CENTRE SOCIAL ET FAMILIAL BORDEAUX NORD | C25: 461165 | D25: Locaux, équipements sportifs, matériel pour
A26: 2016 | B26: AMICALE LAIQUE DAVID JOHNSTON LAGRANGE ALBERT BARRAUD NAUJAC | C26: 450195 | D26: Equipements sportifs
A27: 2016 | B27: SASP UNION BORDEAUX BEGLES | C27: 450000 | D27: Matériel pour manifestations
A28: 2016 | B28: FOYER FRATERNEL | C28: 426565 | D28: Locaux, matériel pour manifestations
A29: 2016 | B29: FESTIVAL DES ARTS DE BORDEAUX | C29: 402000 | D29: Communication, locaux
A30: 2016 | B30: ASSOCIATION DU COMITE DES OEUVRES SOCIALES DES MUNICIPAUX DE BORDEAUX - ACOSMB | C30: 380000 | D30: Matériel pour manifestations
A31: 2016 | B31: POLE D'ENSEIGNEMENT SUPERIEUR DE LA MUSIQUE ET DE LA DANSE DE BORDEAUX AQUITAINE - PESMD | C31: 357672 | D31: Locaux
A32: 2016 | B32: AUTEUIL PETITE ENFANCE | C32: 347000
A33: 2016 | B33: LES COQS ROUGES | C33: 343924 | D33: Equipements sportifs, matériel pour manifestations
A34: 2016 | B34: BORDEAUX GRANDS EVENEMENTS (BGE) | C34: 339500 | D34: Communication, locaux
A35: 2016 | B35: GESTION DU CENTRE DE LOISIRS DE LA POSTE ALEMA | C35: 334000
A36: 2016 | B36: ASSOCIATION PETITS BOUCHONS | C36: 311500
A37: 2016 | B37: ASSOCIATION POUR L'INNOVATION EN MATIERE D'INTEGRATION | C37: 300000
A38: 2016 | B38: BOXERS DE BORDEAUX | C38: 283000
A39: 2016 | B39: SASP JSA BORDEAUX METROPOLE | C39: 280000 | D39: Matériel pour manifestations
A40: 2016 | B40: CLUB ATHLETIQUE MUNICIPAL DE BORDEAUX - CAM | C40: 243834 | D40: Locaux, équipements sportifs, matériel pour
...

Sheet clean2
A1: Année | B1: nom des bénéficiaires | C1: Montant du fonds de concours ou de la subvention (numéraire) | D1: Prestations en nature
A2: 2016 | B2: OPERA NATIONAL DE BORDEAUX | C2: 16167670
A3: 2016 | B3: ASSOCIATION DES CENTRES D'ANIMATION DE QUARTIERS DE BORDEAUX - ACAQB | C3: 8060927.5 | D3: Communication, locaux, équipements sportifs,
A4: 2016 | B4: CCAS DE BORDEAUX | C4: 7912204
A5: 2016 | B5: ECOLE D'ENSEIGNEMENT SUPERIEUR D'ART DE BORDEAUX - ESAB | C5: 3120000
A6: 2016 | B6: ASSOCIATION PITCHOUN | C6: 1735000 | D6: Locaux
A7: 2016 | B7: THEATRE NATIONAL DE BORDEAUX EN AQUITAINE - TNBA | C7: 1646816 | D7: Communication, locaux
A8: 2016 | B8: ASSOCIATION PETITE ENFANCE ENFANCE ET FAMILLE - APEEF | C8: 1578403 | D8: Locaux, matériel pour manifestations
A9: 2016 | B9: UNION SAINT-BRUNO | C9: 1537650 | D9: Locaux, équipements sportifs, matériel pour
A10: 2016 | B10: SPORTING CHANTECLER BORDEAUX NORD LE LAC | C10: 1128560 | D10: Locaux, équipements sportifs, matériel pour
A11: 2016 | B11: AVANT GARDE ET JEANNE D'ARC DE BORDEAUX CAUDERAN - AGJA BORDEAUX CAUDERAN | C11: 1089439 | D11: Locaux, équipements sportifs, matériel pour
A12: 2016 | B12: UNION SPORTIVE LES CHARTRONS | C12: 896350 | D12: Locaux, équipements sportifs, matériel pour
A13: 2016 | B13: LES JEUNES DE SAINT AUGUSTIN - JSA | C13: 892663 | D13: Locaux, équipements sportifs, matériel pour
A14: 2016 | B14: UNION SAINT JEAN - MAISON DE QUARTIER | C14: 879983 | D14: Locaux, équipements sportifs, matériel pour
A15: 2016 | B15: STADE BORDELAIS ASPTT | C15: 819458 | D15: Locaux, équipements sportifs, matériel pour
A16: 2016 | B16: ARC EN REVE | C16: 752250 | D16: Communication, matériel pour manifestations, locaux
A17: 2016 | B17: MAISON DE L'EMPLOI, DE L'INSERTION ECONOMIQUE ET DE L'ENTREPRISE DE BORDEAUX | C17: 678000
A18: 2016 | B18: CLUB PYRENEES AQUITAINE, ASSOCIATION SPORTIVE, EDUCATIVE ET CULTURELLE | C18: 634600 | D18: Locaux, équipements sportifs, matériel pour
A19: 2016 | B19: P'TIT BOUT'CHOU | C19: 567000 | D19: Matériel pour manifestations
A20: 2016 | B20: ASSOCIATION BRINS D'EVEIL | C20: 532800
A21: 2016 | B21: ASSOCIATION DE GESTION ET D'ANIMATION DES CRECHES C.S.F. (AGEAC/CSF) | C21: 512833.33
A22: 2016 | B22: MISSION LOCALE BORDEAUX AVENIR JEUNES | C22: 494000 | D22: Locaux, matériel pour manifestations
A23: 2016 | B23: GP INTENCITE CENTRE SOCIAL ET CULTUREL DU GRAND PARC | C23: 492222 | D23: Locaux, matériel pour manifestations
A24: 2016 | B24: INTERLUDE | C24: 478850 | D24: Locaux, matériel pour manifestations
A25: 2016 | B25: CENTRE SOCIAL ET FAMILIAL BORDEAUX NORD | C25: 461165 | D25: Locaux, équipements sportifs, matériel pour
A26: 2016 | B26: AMICALE LAIQUE DAVID JOHNSTON LAGRANGE ALBERT BARRAUD NAUJAC | C26: 450195 | D26: Equipements sportifs
A27: 2016 | B27: SASP UNION BORDEAUX BEGLES | C27: 450000 | D27: Matériel pour manifestations
A28: 2016 | B28: FOYER FRATERNEL | C28: 426565 | D28: Locaux, matériel pour manifestations
A29: 2016 | B29: FESTIVAL DES ARTS DE BORDEAUX | C29: 402000 | D29: Communication, locaux
A30: 2016 | B30: ASSOCIATION DU COMITE DES OEUVRES SOCIALES DES MUNICIPAUX DE BORDEAUX - ACOSMB | C30: 380000 | D30: Matériel pour manifestations
A31: 2016 | B31: POLE D'ENSEIGNEMENT SUPERIEUR DE LA MUSIQUE ET DE LA DANSE DE BORDEAUX AQUITAINE - PESMD | C31: 357672 | D31: Locaux
A32: 2016 | B32: AUTEUIL PETITE ENFANCE | C32: 347000
A33: 2016 | B33: LES COQS ROUGES | C33: 343924 | D33: Equipements sportifs, matériel pour manifestations
A34: 2016 | B34: BORDEAUX GRANDS EVENEMENTS (BGE) | C34: 339500 | D34: Communication, locaux
A35: 2016 | B35: GESTION DU CENTRE DE LOISIRS DE LA POSTE ALEMA | C35: 334000
A36: 2016 | B36: ASSOCIATION PETITS BOUCHONS | C36: 311500
A37: 2016 | B37: ASSOCIATION POUR L'INNOVATION EN MATIERE D'INTEGRATION | C37: 300000
A38: 2016 | B38: BOXERS DE BORDEAUX | C38: 283000
A39: 2016 | B39: SASP JSA BORDEAUX METROPOLE | C39: 280000 | D39: Matériel pour manifestations
A40: 2016 | B40: CLUB ATHLETIQUE MUNICIPAL DE BORDEAUX - CAM | C40: 243834 | D40: Locaux, équipements sportifs, matériel pour
...

Sheet verif2
D2: 2016 + 2017 | E2: =countif(B2:B2203,">1") -> 936
D3: 2016 ou 2017 | E3: =countif(B3:B2204,"=1") -> 1266

Sheet analyse3.
G2: 2016 + 2017 | H2: =countif(B2:B2203,">1") -> 981
G3: 2016 ou 2017 | H3: =countif(B3:B2204,"=1") -> 0

Sheet consolid1
A1: web-scraper-start-url | B1: nom | C1: description | D1: adresse | E1: code postal | F1: telephone | G1: president | H1: site web | I1: categorie
A2: https://assos.bordeaux.fr/association/detail/1857 | B2: PERCAL TANGO | C2: Promouvoir la culture argentine à travers la musique, la danse, le théâtre. Création et vente des spectacles vivants. | D2: 86 Cours Victor Hugo | E2: 33000 | F2: 05 40 05 22 45 | G2: null | H2: null | I2: null
A3: https://assos.bordeaux.fr/association/detail/634 | B3: ARTISANS DU MONDE BORDEAUX - ADM | C3: Promouvoir le commerce équitable afin de permettre aux producteurs de pays ou régions défavorisés de vivre dignement de leur travail et être acteur de leur développement. Permettre aux consommateurs d'être informés sur les dysfonctionnements du commerce international. Contribuer à changer les mécanismes du commerce international | D3: 30 rue du Parlement Saint Pierre | E3: 33000 | F3: 05 56 44 23 33 | G3: null | H3: admbordeaux.org | I3: Entraide, solidarité, humanitaire
A4: https://assos.bordeaux.fr/association/detail/955 | B4: CERCLE PHILATÉLIQUE BORDEAUX AQUITAINE - CPBA | C4: Association philatélique (collection de timbres) et marcophile (marques postales) atteignant une dizaine d'années d'existence forte de 160 membres actifs. Cette association est ouverte à tous les philatélistes débutants ou confirmés, de tous les âges. Ses adhérents ont la possibilité de se réunir pour échanger et chercher des pièces manquantes à leurs collections, 4 samedis par mois. | D4: 8 Rue de Blois Chez M. Langella | E4: 33600 | F4: 05 56 07 24 64 | G4: Gérard Langella | H4: null | I4: Loisirs
A5: https://assos.bordeaux.fr/association/detail/588 | B5: ALLO AMIANTE | C5: Défense des victimes de l'amiante et des victimes de maladies professionnelles faisant suite à une exposition aux autres agents cancérigènes ; prévention chez les particuliers et éradication de l'amiante | D5: 5 place, Amédée St Germain | E5: 33800 | F5: 05 56 91 60 69 | G5: Georges ARNAUDEAU | H5: null | I5: Santé, bien-être
A6: https://assos.bordeaux.fr/association/detail/680 | B6: CENTRE ACCUEIL CONSULTATION INFORMATION SEXUALITÉ - CACIS | C6: Dans une démarche d’éducation populaire, le CACIS se donne pour finalité de permettre à toute personne, jeune ou adulte, de trouver les moyens de vivre sa sexualité dans notre société et d’agir contre toute forme d’exclusion liée à la santé, à la sexualité et au genre. | D6: Place de l'Europe BP 44 | E6: 33030 | F6: 05 56 39 11 69 | G6: Brigitte Tandonnet | H6: cacis-pro.fr | I6: Santé, bien-être
A7: https://assos.bordeaux.fr/association/detail/1132 | B7: HANDI CAP NOUVELLE AQUITAINE - HCNA | C7: Handi CAP Nouvelle Aquitaine est une association loi 1901 qui a pour objet d'informer les personnes touchées et concernées par le handicap ou la perte d'autonomie sur les loisirs accessibles des secteurs du tourisme, de la culture, du sport présents en Nouvelle Aquitaine. Elle fait coopérer les partenaires de ces secteurs pour collecter et organiser la diffusion de ces informations. | D7: 436 av de Verdun | E7: 33700 | F7: 05 56 12 39 39 | G7: Patrick TREINS | H7: null | I7: null
A8: https://assos.bordeaux.fr/association/detail/1394 | B8: ASSOCIATION DES SAHRAOUIS À BORDEAUX - ASB | C8: Notre association a pour but de faire connaitre et reconnaître le peuple du Sahara Occidental, son histoire, sa culture, sa vie, son territoire et ses ressources auprès de l'opinion française et internationale. Mais aussi de soutenir les sahraouis dans les difficultés matérielles quotidiennes et dans la lutte pacifique vers la résolution du problème de décolonisation de leur pays. | D8: 9 bis cours Edouard Vaillant | E8: 33300 | F8: 06 05 90 55 41 | G8: Mohamed Salem Mohamed Brahim | H8: null | I8: Culture
A9: https://assos.bordeaux.fr/association/detail/1820 | B9: LES CRAYONNEUSES | C9: Action de médiation artistique, culturelle, bien-être. Création d'ouvrages et objets papiers. | D9: 3 chemin du Grand Port | E9: 33880 | F9: 06 87 19 99 02 | G9: null | H9: lescrayonneuses.com | I9: Santé, bien-être
A10: https://assos.bordeaux.fr/association/detail/515 | B10: OPÉRA BASTIDE - OB | C10: la compagnie Opéra Bastide représentait initialement un espace de création où l'apprentissage du métier se fait immédiatement par la scène, au contact du public, en dehors du cadre institutionnel. | D10: BP 24 BP 24 | E10: 33034 | F10: 06 58 52 19 58 | G10: null | H10: null | I10: Culture
A11: https://assos.bordeaux.fr/association/detail/713 | B11: ASSOCIATION DES AMIS D’ELIANE LAVAIL - AMIDEL | D11: pas d'adresse | G11: null | H11: null | I11: null
A12: https://assos.bordeaux.fr/association/detail/615 | B12: MAM'AN LES TI'BATEAUX | C12: L’objet de l’association de maison d’assistant(e)s maternel(le)s est le suivant : Création, ouverture et gestion d'une maison d'assistant(e)s maternel(le)s (M.A.M.) avec un projet de mixité dans l'accueil d'enfants non porteurs de handicaps âgés de deux mois et demi à quatre ans et d'enfants porteurs de handicaps ou atteints d'une maladie chronique âgés de deux mois et demi à six ans. | D12: 06 Place Philippe Lebon | E12: 33300 | F12: 06 79 08 95 93 | G12: Christine MOUNIER | I12: Education - Enfance - Jeunesse - Vie étudiante
A13: https://assos.bordeaux.fr/association/detail/1405 | B13: WINE WILD WEST | C13: L'association Wine Wild West a pour objet : l’organisation et la promotion d’un rassemblement annuel de danseurs de west coast swing en région bordelaise dénommé Wine Wild West. Ce rassemblement est un festival qui comprend des cours de danse et soirées de west coast swing. De plus le festival propose des découvertes œnologiques et de spécialités Bordelaises. | D13: 10 impasse Manes Chez Mme Dubernet | E13: 33110 | F13: 06 52 06 18 13 | G13: null | H13: www.winewildwest-bordeaux.fr | I13: Culture
A14: https://assos.bordeaux.fr/association/detail/1194 | B14: UNION SAINT-BRUNO - USB | C14: Favoriser la pratique du sport sous toutes ses formes au titre du loisir et/ou de la compétition. | D14: 49 rue Brizard | E14: 33000 | F14: 05 56 96 33 53 | G14: null | H14: www.saint-bruno.org | I14: Sport
A15: https://assos.bordeaux.fr/association/detail/1053 | B15: BXA - ESPRIT VOILE - BXA EV | C15: Proposer la découverte et le perfectionnement à la voile au départ de Bordeaux sur l'estuaire de la Gironde avec le voilier habitable de l’association (7,5 m ESTE 24). Développer, promouvoir et favoriser des activités à caractère culturel et sportif dans le domaine du nautisme avec comme champ d’action les bassins à flot de Bordeaux, la ville de Bordeaux et au delà. | D15: Bld Alfred DANEY Quai ouest Bassin à flot n° 2 | E15: 33300 | F15: 07 69 17 50 70 | G15: null | H15: www.bxaespritvoile.fr | I15: Sport
A16: https://assos.bordeaux.fr/association/detail/567 | B16: ASSOCIATION PARLECOUTER | C16: Enseigner l'apprentissage d'outils de communication bienveillante et respectueuse, basés sur l'écoute active, profonde et sans jugement, sur le développement de l'empathie, pour une meilleure compréhension de l'autre et de soi. L'association vise à créer des conditions favorables à l'éducation et l'accompagnement des enfants / adolescents, à instaurer des relations plus sereines en famille et en société. | D16: 11 rue du Palais Gallien, Appt A314 | E16: 33000 | F16: 06 78 66 97 33 | G16: null | H16: parlecouter.wixsite.com/bordeaux | I16: Education - Enfance - Jeunesse - Vie étudiante
A17: https://assos.bordeaux.fr/association/detail/1441 | B17: AIDOMI | C17: AIDOMI est une association d'aide et de soins à domicile organisée en Service Polyvalent d'Aide et de Soins à Domicile (SPASAD). Nos services accompagnent 24h /24h les personnes vulnérables et les proches aidants dans le maintien à domicile à travers des missions d'aide à domicile (entretien du domicile, préparation des repas, accompagnement à la vie sociale) et des soins infirmiers et d'hygiène. | D17: 22 rue professeur lannelongue | E17: 33300 | F17: 05 56 01 91 91 | G17: null | H17: aidomi.fr | I17: Santé, bien-être
