Workbook

Sheet nosdeputes.fr_deputes2018-05-31
A1: id | B1: nom | C1: nom_de_famille | D1: prenom | E1: sexe | F1: date_naissance | G1: lieu_naissance | H1: num_deptmt | I1: nom_circo | J1: num_circo | K1: mandat_debut | L1: mandat_fin | M1: ancien_depute | N1: groupe_sigle | O1: parti_ratt_financier | P1: sites_web | Q1: anciens_mandats | R1: profession | S1: place_en_hemicycle | T1: url_an | U1: id_an | V1: slug | W1: url_nosdeputes | X1: url_nosdeputes_api | Y1: nb_mandats | Z1: twitter
A2: 1 | B2: Alain Ballay | C2: Lamour | D2: Jean-François | E2: H | F2: 20487 | G2: Paris (Paris) | H2: 75 | I2: Paris | J2: 13 | K2: 41080 | L2: 42906 | M2: 1 | N2: LR | O2: Les Républicains | P2: http://www.jflamour.fr|https://twitter.com/JF_Lamour| | Q2: 20/06/2007 / 19/06/2012 / fin de législature|20/06/2012 / / | | R2: Kinésithérapeute | S2: 80 | T2: http://www2.assemblee-nationale.fr/deputes/fiche/OMC_PA230329 | U2: 230329 | V2: jean-francois-lamour | W2: https://2012-2017.nosdeputes.fr/jean-francois-lamour | X2: https://2012-2017.nosdeputes.fr/jean-francois-lamour/csv | Y2: 2 | Z2: JF_Lamour
A3: 2 | B3: Alain Bocquet | C3: Clément | D3: Jean-Michel | E3: H | F3: 20028 | G3: Mauprevoir (Vienne) | H3: 86 | I3: Vienne | J3: 3 | K3: 41080 | L3: 42906 | M3: 1 | N3: SER | O3: Parti socialiste | P3: https://twitter.com/jmclement86|http://www.jeanmichelclement.com| | Q3: 20/06/2007 / 19/06/2012 / fin de législature|20/06/2012 / / | | R3: Avocat | S3: 263 | T3: http://www2.assemblee-nationale.fr/deputes/fiche/OMC_PA336439 | U3: 336439 | V3: jean-michel-clement | W3: https://2012-2017.nosdeputes.fr/jean-michel-clement | X3: https://2012-2017.nosdeputes.fr/jean-michel-clement/csv | Y3: 2 | Z3: jmclement86
A4: 3 | B4: Alain Calmette | C4: Reynès | D4: Bernard | E4: H | F4: 19650 | G4: Meknès (Maroc) | H4: 13 | I4: Bouches-du-Rhône | J4: 15 | K4: 41080 | L4: 42906 | M4: 1 | N4: LR | O4: Les Républicains | P4: http://www.bernard-reynes.com|https://twitter.com/bernardreynes| | Q4: 20/06/2007 / 19/06/2012 / fin de législature|20/06/2012 / / | | R4: Chirurgien-Dentiste | S4: 190 | T4: http://www2.assemblee-nationale.fr/deputes/fiche/OMC_PA330788 | U4: 330788 | V4: bernard-reynes | W4: https://2012-2017.nosdeputes.fr/bernard-reynes | X4: https://2012-2017.nosdeputes.fr/bernard-reynes/csv | Y4: 2 | Z4: bernardreynes
A5: 4 | B5: Alain Chrétien | C5: Hurel | D5: Sandrine | E5: F | F5: 25057 | G5: Lisieux (Calvados) | H5: 76 | I5: Seine-Maritime | J5: 6 | K5: 41080 | L5: 42243 | M5: 1 | O5: Parti socialiste | P5: http://www.sandrine-hurel.info|https://twitter.com/sandrinehurel|http://www.sandrine-hurel.info/index.php| | Q5: 20/06/2007 / 19/06/2012 / fin de législature|20/06/2012 / 27/08/2015 / prolongation de mission temporaire| | R5: Secrétaire de direction | S5: 460 | T5: http://www2.assemblee-nationale.fr/deputes/fiche/OMC_PA304016 | U5: 304016 | V5: sandrine-hurel | W5: https://2012-2017.nosdeputes.fr/sandrine-hurel | X5: https://2012-2017.nosdeputes.fr/sandrine-hurel/csv | Y5: 2 | Z5: sandrinehurel
A6: 5 | B6: Alain Claeys | C6: Laffineur | D6: Marc | E6: H | F6: 16659 | G6: Maubeuge (Nord) | H6: 49 | I6: Maine-et-Loire | J6: 7 | K6: 41080 | L6: 42906 | M6: 1 | N6: LR | O6: Les Républicains | P6: http://www.marclaffineur.fr|https://twitter.com/Marclaffineur| | Q6: 20/06/2012 / / |01/06/1997 / 18/06/2002 / fin de législature|02/04/1993 / 21/04/1997 / fin de législature|19/06/2002 / 19/06/2007 / fin de législature|17/06/2012 / 19/06/2012 / fin de législature|20/06/2007 / 29/07/2011 / nomination comme membre du gouvernement|13/06/1988 / 01/04/1993 / fin de législature| | R6: Médecin anesthésiste-réanimateur | S6: 183 | T6: http://www2.assemblee-nationale.fr/deputes/fiche/OMC_PA1790 | U6: 1790 | V6: marc-laffineur | W6: https://2012-2017.nosdeputes.fr/marc-laffineur | X6: https://2012-2017.nosdeputes.fr/marc-laffineur/csv | Y6: 2 | Z6: Marclaffineur
A7: 6 | B7: Alain Fauré | C7: Courson (de) | D7: Charles | E7: H | F7: 19086 | G7: Paris (Paris) | H7: 51 | I7: Marne | J7: 5 | K7: 41080 | L7: 42906 | M7: 1 | N7: UDI | O7: Association PSLE - Nouveau centre | P7: https://twitter.com/C_deCourson| | Q7: 20/06/2007 / 19/06/2012 / fin de législature|20/06/2012 / / |01/06/1997 / 18/06/2002 / fin de législature|02/04/1993 / 21/04/1997 / fin de législature|19/06/2002 / 19/06/2007 / fin de législature| | R7: Magistrat à la Cour des comptes (conseiller référendaire de première classe) | S7: 295 | T7: http://www2.assemblee-nationale.fr/deputes/fiche/OMC_PA942 | U7: 942 | V7: charles-de-courson | W7: https://2012-2017.nosdeputes.fr/charles-de-courson | X7: https://2012-2017.nosdeputes.fr/charles-de-courson/csv | Y7: 3 | Z7: C_deCourson
A8: 7 | B8: Alain Gest | C8: Paul | D8: Christian | E8: H | F8: 21998 | G8: Clermont-Ferrand (Puy-de-Dôme) | H8: 58 | I8: Nièvre | J8: 2 | K8: 41080 | L8: 42906 | M8: 1 | N8: SER | O8: Parti socialiste | P8: http://www.christianpaul.fr|https://twitter.com/christianpaul58| | Q8: 20/06/2007 / 19/06/2012 / fin de législature|20/06/2012 / / |19/06/2002 / 19/06/2007 / fin de législature|01/06/1997 / 30/09/2000 / nomination comme membre du gouvernement| | R8: Administrateur civil | S8: 336 | T8: http://www2.assemblee-nationale.fr/deputes/fiche/OMC_PA2338 | U8: 2338 | V8: christian-paul | W8: https://2012-2017.nosdeputes.fr/christian-paul | X8: https://2012-2017.nosdeputes.fr/christian-paul/csv | Y8: 2 | Z8: christianpaul58
A9: 8 | B9: Alain Leboeuf | C9: Dufau | D9: Jean-Pierre | E9: H | F9: 15892 | G9: Capbreton (Landes) | H9: 40 | I9: Landes | J9: 2 | K9: 41080 | L9: 42906 | M9: 1 | N9: SER | O9: Parti socialiste | P9: http://www.jeanpierredufau.org| | Q9: 20/06/2007 / 19/06/2012 / fin de législature|20/06/2012 / / |01/06/1997 / 18/06/2002 / fin de législature|19/06/2002 / 19/06/2007 / fin de législature| | R9: Enseignant retraité | S9: 500 | T9: http://www2.assemblee-nationale.fr/deputes/fiche/OMC_PA1182 | U9: 1182 | V9: jean-pierre-dufau | W9: https://2012-2017.nosdeputes.fr/jean-pierre-dufau | X9: https://2012-2017.nosdeputes.fr/jean-pierre-dufau/csv | Y9: 2
A10: 9 | B10: Alain Marc | C10: Féron | D10: Hervé | E10: H | F10: 20670 | G10: Luxeuil-les-Bains (Haute-Saône) | H10: 54 | I10: Meurthe-et-Moselle | J10: 2 | K10: 41080 | L10: 42906 | M10: 1 | N10: SER | O10: Parti socialiste | P10: http://herveferon.fr| | Q10: 20/06/2007 / 19/06/2012 / fin de législature|20/06/2012 / / | | R10: Homme de lettres et artiste | S10: 524 | T10: http://www2.assemblee-nationale.fr/deputes/fiche/OMC_PA333335 | U10: 333335 | V10: herve-feron | W10: https://2012-2017.nosdeputes.fr/herve-feron | X10: https://2012-2017.nosdeputes.fr/herve-feron/csv | Y10: 2
A11: 10 | B11: Alain Marleix | C11: Touraine | D11: Jean-Louis | E11: H | F11: 16718 | G11: Lyon (3ème arrondissement) (Rhône) | H11: 69 | I11: Rhône | J11: 3 | K11: 41080 | L11: 42906 | M11: 1 | N11: SER | O11: Parti socialiste | P11: http://www.jeanlouistouraine.fr| | Q11: 20/06/2007 / 19/06/2012 / fin de législature|20/06/2012 / / | | R11: Professeur de médecine | S11: 518 | T11: http://www2.assemblee-nationale.fr/deputes/fiche/OMC_PA334768 | U11: 334768 | V11: jean-louis-touraine | W11: https://2012-2017.nosdeputes.fr/jean-louis-touraine | X11: https://2012-2017.nosdeputes.fr/jean-louis-touraine/csv | Y11: 3
A12: 11 | B12: Alain Marsaud | C12: Giacobbi | D12: Paul | E12: H | F12: 20975 | G12: Courbevoie (Hauts-de-Seine) | H12: 2B | I12: Haute-Corse | J12: 2 | K12: 41080 | L12: 42906 | M12: 1 | N12: RRDP | O12: Parti radical de gauche | P12: https://twitter.com/pgiacobbi|http://blog.paul-giacobbi.org| | Q12: 20/06/2007 / 19/06/2012 / fin de législature|20/06/2012 / / |19/06/2002 / 19/06/2007 / fin de législature| | R12: Administrateur civil au ministère de l'équipement | S12: 269 | T12: http://www2.assemblee-nationale.fr/deputes/fiche/OMC_PA267407 | U12: 267407 | V12: paul-giacobbi | W12: https://2012-2017.nosdeputes.fr/paul-giacobbi | X12: https://2012-2017.nosdeputes.fr/paul-giacobbi/csv | Y12: 3 | Z12: pgiacobbi
A13: 12 | B13: Alain Marty | C13: Le Fur | D13: Marc | E13: H | F13: 20787 | G13: Dakar (Sénégal) | H13: 22 | I13: Côtes-d'Armor | J13: 3 | K13: 41080 | L13: 42906 | M13: 1 | N13: LR | O13: Les Républicains | P13: http://www.marclefur.bzh|http://www.marclefur.com|https://twitter.com/marclefur| | Q13: 20/06/2007 / 19/06/2012 / fin de législature|20/06/2012 / / |02/04/1993 / 21/04/1997 / fin de législature|19/06/2002 / 19/06/2007 / fin de législature| | R13: Sous-préfet | S13: 96 | T13: http://www2.assemblee-nationale.fr/deputes/fiche/OMC_PA1874 | U13: 1874 | V13: marc-le-fur | W13: https://2012-2017.nosdeputes.fr/marc-le-fur | X13: https://2012-2017.nosdeputes.fr/marc-le-fur/csv | Y13: 2 | Z13: marclefur
A14: 13 | B14: Alain Moyne-Bressand | C14: Marsac | D14: Jean-René | E14: H | F14: 19835 | G14: Béganne (Morbihan) | H14: 35 | I14: Ille-et-Vilaine | J14: 4 | K14: 41080 | L14: 42906 | M14: 1 | N14: SER | O14: Parti socialiste | P14: http://www.jrmarsac-leblog.typepad.fr| | Q14: 20/06/2007 / 19/06/2012 / fin de législature|20/06/2012 / / | | R14: Cadre | S14: 527 | T14: http://www2.assemblee-nationale.fr/deputes/fiche/OMC_PA332206 | U14: 332206 | V14: jean-rene-marsac | W14: https://2012-2017.nosdeputes.fr/jean-rene-marsac | X14: https://2012-2017.nosdeputes.fr/jean-rene-marsac/csv | Y14: 1
A15: 14 | B15: Alain Rodet | C15: Leonetti | D15: Jean | E15: H | F15: 17723 | G15: Marseille (Bouches-du-Rhône) | H15: 6 | I15: Alpes-Maritimes | J15: 7 | K15: 41080 | L15: 42906 | M15: 1 | N15: LR | O15: Les Républicains | P15: http://jeanleonetti.com|http://www.jeanleonetti.fr|https://twitter.com/JeanLeonetti| | Q15: 20/06/2012 / / |01/06/1997 / 18/06/2002 / fin de législature|19/06/2002 / 19/06/2007 / fin de législature|17/06/2012 / 19/06/2012 / fin de législature|20/06/2007 / 29/07/2011 / nomination comme membre du gouvernement| | R15: Praticien hospitalier | S15: 81 | T15: http://www2.assemblee-nationale.fr/deputes/fiche/OMC_PA1946 | U15: 1946 | V15: jean-leonetti | W15: https://2012-2017.nosdeputes.fr/jean-leonetti | X15: https://2012-2017.nosdeputes.fr/jean-leonetti/csv | Y15: 2 | Z15: JeanLeonetti
A16: 15 | B16: Alain Rousset | C16: Fourneyron | D16: Valérie | E16: F | F16: 21827 | G16: Petit Quevilly (Seine-Maritime) | H16: 76 | I16: Seine-Maritime | J16: 1 | K16: 41824 | L16: 42906 | M16: 1 | N16: SER | O16: Parti socialiste | P16: http://www.valerie-fourneyron.fr| | Q16: 20/06/2012 / 21/07/2012 / nomination comme membre du gouvernement|04/07/2014 / / |20/06/2007 / 16/06/2012 / nomination comme membre du gouvernement| | R16: Médecin | S16: 335 | T16: http://www2.assemblee-nationale.fr/deputes/fiche/OMC_PA335543 | U16: 335543 | V16: valerie-fourneyron | W16: https://2012-2017.nosdeputes.fr/valerie-fourneyron | X16: https://2012-2017.nosdeputes.fr/valerie-fourneyron/csv | Y16: 2
A17: 16 | B17: Alain Suguenot | C17: Rugy (de) | D17: François | E17: H | F17: 27004 | G17: Nantes (Loire-Atlantique) | H17: 44 | I17: Loire-Atlantique | J17: 1 | K17: 41080 | L17: 42906 | M17: 1 | N17: SER | O17: Parti socialiste | P17: http://www.francoisderugy.fr|http://www.derugy2017.fr|https://twitter.com/FdeRugy| | Q17: 20/06/2007 / 19/06/2012 / fin de législature|20/06/2012 / / | | R17: Assistant parlementaire | S17: 274 | T17: http://www2.assemblee-nationale.fr/deputes/fiche/OMC_PA332747 | U17: 332747 | V17: francois-de-rugy | W17: https://2012-2017.nosdeputes.fr/francois-de-rugy | X17: https://2012-2017.nosdeputes.fr/francois-de-rugy/csv | Y17: 3 | Z17: FdeRugy
A18: 17 | B18: Alain Tourret | C18: Chartier | D18: Jérôme | E18: H | F18: 24425 | G18: Paris (Paris) | H18: 95 | I18: Val-d'Oise | J18: 7 | K18: 41080 | L18: 42906 | M18: 1 | N18: LR | O18: Les Républicains | P18: http://www.jeromechartier.fr|https://twitter.com/jechartier| | Q18: 20/06/2007 / 19/06/2012 / fin de législature|20/06/2012 / / |19/06/2002 / 19/06/2007 / fin de législature| | R18: Ancien associé gérant | S18: 85 | T18: http://www2.assemblee-nationale.fr/deputes/fiche/OMC_PA267895 | U18: 267895 | V18: jerome-chartier | W18: https://2012-2017.nosdeputes.fr/jerome-chartier | X18: https://2012-2017.nosdeputes.fr/jerome-chartier/csv | Y18: 3 | Z18: jechartier
A19: 18 | B19: Alain Vidalies | C19: Jung | D19: Armand | E19: H | F19: 18610 | G19: Theding (Moselle) | H19: 67 | I19: Bas-Rhin | J19: 1 | K19: 41080 | L19: 42432 | M19: 1 | O19: Parti socialiste | P19: http://www.armandjung-depute.fr| | Q19: 20/06/2007 / 19/06/2012 / fin de législature|20/06/2012 / 03/03/2016 / démission|19/06/2002 / 19/06/2007 / fin de législature|05/07/1997 / 18/06/2002 / fin de législature| | R19: Fonctionnaire territorial | S19: 383 | T19: http://www2.assemblee-nationale.fr/deputes/fiche/OMC_PA1748 | U19: 1748 | V19: armand-jung | W19: https://2012-2017.nosdeputes.fr/armand-jung | X19: https://2012-2017.nosdeputes.fr/armand-jung/csv | Y19: 1
A20: 633 | B20: Alexis Bachelay | C20: Gauquelin | D20: Renaud | E20: H | F20: 20035 | G20: Paris (Paris) | H20: 69 | I20: Rhône | J20: 7 | K20: 42441 | L20: 42906 | M20: 1 | N20: SER | O20: Parti socialiste | Q20: 12/03/2016 / / | | R20: Médecin généraliste | S20: 541 | T20: http://www2.assemblee-nationale.fr/deputes/fiche/OMC_PA643165 | U20: 643165 | V20: renaud-gauquelin | W20: https://2012-2017.nosdeputes.fr/renaud-gauquelin | X20: https://2012-2017.nosdeputes.fr/renaud-gauquelin/csv | Y20: 2
A21: 19 | B21: Alfred Marie-Jeanne | C21: Hillmeyer | D21: Francis | E21: H | F21: 17054 | G21: Mulhouse (Haut-Rhin) | H21: 68 | I21: Haut-Rhin | J21: 6 | K21: 41080 | L21: 42906 | M21: 1 | N21: UDI | O21: Association PSLE - Nouveau centre | Q21: 20/06/2007 / 19/06/2012 / fin de législature|20/06/2012 / / |26/06/2000 / 18/06/2002 / fin de législature|19/06/2002 / 19/06/2007 / fin de législature| | R21: Journaliste reporter-photographe | S21: 234 | T21: http://www2.assemblee-nationale.fr/deputes/fiche/OMC_PA216574 | U21: 216574 | V21: francis-hillmeyer | W21: https://2012-2017.nosdeputes.fr/francis-hillmeyer | X21: https://2012-2017.nosdeputes.fr/francis-hillmeyer/csv | Y21: 2
A22: 20 | B22: André Chassaigne | C22: Lemasle | D22: Patrick | E22: H | F22: 19132 | G22: Saint-Hilaire-du-Harcouët (Manche) | H22: 31 | I22: Haute-Garonne | J22: 7 | K22: 41080 | L22: 42906 | M22: 1 | N22: SER | O22: Parti socialiste | Q22: 20/06/2007 / 19/06/2012 / fin de législature|20/06/2012 / / |19/06/2002 / 19/06/2007 / fin de législature|03/07/1997 / 18/06/2002 / fin de législature| | R22: Exploitant agricole | S22: 540 | T22: http://www2.assemblee-nationale.fr/deputes/fiche/OMC_PA1936 | U22: 1936 | V22: patrick-lemasle | W22: https://2012-2017.nosdeputes.fr/patrick-lemasle | X22: https://2012-2017.nosdeputes.fr/patrick-lemasle/csv | Y22: 2
A23: 21 | B23: André Santini | C23: Lambert | D23: Jérôme | E23: H | F23: 20978 | G23: Vincennes (Val-de-Marne) | H23: 16 | I23: Charente | J23: 3 | K23: 41080 | L23: 42906 | M23: 1 | N23: RRDP | O23: Parti socialiste | Q23: 20/06/2007 / 19/06/2012 / fin de législature|20/06/2012 / / |01/06/1997 / 18/06/2002 / fin de législature|19/06/2002 / 19/06/2007 / fin de législature|02/04/1986 / 14/05/1988 / fin de législature|13/06/1988 / 01/04/1993 / fin de législature| | R23: Cadre de l'industrie | S23: 300 | T23: http://www2.assemblee-nationale.fr/deputes/fiche/OMC_PA1809 | U23: 1809 | V23: jerome-lambert | W23: https://2012-2017.nosdeputes.fr/jerome-lambert | X23: https://2012-2017.nosdeputes.fr/jerome-lambert/csv | Y23: 1
A24: 22 | B24: André Schneider | C24: Verchère | D24: Patrice | E24: H | F24: 27027 | G24: Coteau (Loire) | H24: 69 | I24: Rhône | J24: 8 | K24: 41080 | L24: 42906 | M24: 1 | N24: LR | O24: Les Républicains | P24: http://www.patriceverchere.fr| | Q24: 20/06/2007 / 19/06/2012 / fin de législature|20/06/2012 / / | | R24: Assistant parlementaire | S24: 143 | T24: http://www2.assemblee-nationale.fr/deputes/fiche/OMC_PA334843 | U24: 334843 | V24: patrice-verchere | W24: https://2012-2017.nosdeputes.fr/patrice-verchere | X24: https://2012-2017.nosdeputes.fr/patrice-verchere/csv | Y24: 2
A25: 23 | B25: Anne Grommerch | C25: Gaymard | D25: Hervé | E25: H | F25: 22067 | G25: Bourg-Saint-Maurice (Savoie) | H25: 73 | I25: Savoie | J25: 2 | K25: 41080 | L25: 42906 | M25: 1 | N25: LR | O25: Les Républicains | P25: http://www.herve-gaymard.fr|https://twitter.com/HGaymard|http://www.herve-gaymard.com| | Q25: 20/06/2007 / 19/06/2012 / fin de législature|20/06/2012 / / |01/06/1997 / 07/06/2002 / nomination comme membre du gouvernement|17/07/1995 / 16/08/1995 / nomination comme membre du gouvernement|02/05/1993 / 06/06/1995 / démission|19/06/2002 / 18/07/2002 / nomination comme membre du gouvernement| | R25: Administrateur civil | S25: 170 | T25: http://www2.assemblee-nationale.fr/deputes/fiche/OMC_PA1445 | U25: 1445 | V25: herve-gaymard | W25: https://2012-2017.nosdeputes.fr/herve-gaymard | X25: https://2012-2017.nosdeputes.fr/herve-gaymard/csv | Y25: 2 | Z25: HGaymard
A26: 24 | B26: Anne-Christine Lang | C26: Salen | D26: Paul | E26: H | F26: 18066 | G26: Veauche (Loire) | H26: 42 | I26: Loire | J26: 6 | K26: 41080 | L26: 42906 | M26: 1 | N26: LR | O26: Les Républicains | P26: http://www.paulsalendepute.fr| | Q26: 20/06/2012 / / |06/05/2011 / 19/06/2012 / fin de législature| | R26: Retraité | S26: 241 | T26: http://www2.assemblee-nationale.fr/deputes/fiche/OMC_PA2664 | U26: 2664 | V26: paul-salen | W26: https://2012-2017.nosdeputes.fr/paul-salen | X26: https://2012-2017.nosdeputes.fr/paul-salen/csv | Y26: 1
A27: 25 | B27: Anne-Lise Dufour-Tonini | C27: Lazaro | D27: Thierry | E27: H | F27: 22186 | G27: Lille (Nord) | H27: 59 | I27: Nord | J27: 6 | K27: 41080 | L27: 42906 | M27: 1 | N27: LR | O27: Les Républicains | P27: http://thierrylazaro.fr| | Q27: 20/06/2007 / 19/06/2012 / fin de législature|20/06/2012 / / |01/06/1997 / 18/06/2002 / fin de législature|02/04/1993 / 21/04/1997 / fin de législature|19/06/2002 / 19/06/2007 / fin de législature| | R27: Chargé de communication | S27: 89 | T27: http://www2.assemblee-nationale.fr/deputes/fiche/OMC_PA1857 | U27: 1857 | V27: thierry-lazaro | W27: https://2012-2017.nosdeputes.fr/thierry-lazaro | X27: https://2012-2017.nosdeputes.fr/thierry-lazaro/csv | Y27: 2
A28: 26 | B28: Anne-Yvonne Le Dain | C28: Got | D28: Pascale | E28: F | F28: 22372 | G28: Royan (Charente-Maritime) | H28: 33 | I28: Gironde | J28: 5 | K28: 41080 | L28: 42906 | M28: 1 | N28: SER | O28: Parti socialiste | Q28: 20/06/2007 / 19/06/2012 / fin de législature|20/06/2012 / / | | R28: Journaliste | S28: 523 | T28: http://www2.assemblee-nationale.fr/deputes/fiche/OMC_PA331973 | U28: 331973 | V28: pascale-got | W28: https://2012-2017.nosdeputes.fr/pascale-got | X28: https://2012-2017.nosdeputes.fr/pascale-got/csv | Y28: 2
A29: 27 | B29: Annick Girardin | C29: Guégot | D29: Françoise | E29: F | F29: 22869 | G29: Oullins (Rhône) | H29: 76 | I29: Seine-Maritime | J29: 2 | K29: 41080 | L29: 42906 | M29: 1 | N29: LR | O29: Les Républicains | P29: https://twitter.com/fguegot|http://www.francoiseguegot.fr| | Q29: 20/06/2007 / 19/06/2012 / fin de législature|20/06/2012 / / | | R29: Maître de conférences associée | S29: 91 | T29: http://www2.assemblee-nationale.fr/deputes/fiche/OMC_PA335567 | U29: 335567 | V29: francoise-guegot | W29: https://2012-2017.nosdeputes.fr/francoise-guegot | X29: https://2012-2017.nosdeputes.fr/francoise-guegot/csv | Y29: 2 | Z29: fguegot
A30: 28 | B30: Annick Le Loch | C30: Perez | D30: Jean-Claude | E30: H | F30: 23467 | G30: Carcassonne (Aude) | H30: 11 | I30: Aude | J30: 1 | K30: 41080 | L30: 42906 | M30: 1 | N30: SER | O30: Parti socialiste | P30: http://www.jeanclaudeperez.net| | Q30: 20/06/2007 / 19/06/2012 / fin de législature|20/06/2012 / / |01/06/1997 / 18/06/2002 / fin de législature|19/06/2002 / 19/06/2007 / fin de législature| | R30: Secrétaire de mairie | S30: 412 | T30: http://www2.assemblee-nationale.fr/deputes/fiche/OMC_PA2365 | U30: 2365 | V30: jean-claude-perez | W30: https://2012-2017.nosdeputes.fr/jean-claude-perez | X30: https://2012-2017.nosdeputes.fr/jean-claude-perez/csv | Y30: 2
A31: 29 | B31: Annick Lepetit | C31: Mariani | D31: Thierry | E31: H | F31: 21405 | G31: Orange (Vaucluse) | H31: 999 | I31: Français établis hors de France | J31: 11 | K31: 41080 | L31: 42906 | M31: 1 | N31: LR | O31: Les Républicains | P31: http://www.thierrymariani.com|https://twitter.com/ThierryMARIANI| | Q31: 20/06/2012 / / |20/06/2007 / 15/12/2010 / nomination comme membre du gouvernement|01/06/1997 / 18/06/2002 / fin de législature|02/04/1993 / 21/04/1997 / fin de législature|19/06/2002 / 19/06/2007 / fin de législature|17/06/2012 / 19/06/2012 / fin de législature| | R31: Cadre | S31: 7 | T31: http://www2.assemblee-nationale.fr/deputes/fiche/OMC_PA2073 | U31: 2073 | V31: thierry-mariani | W31: https://2012-2017.nosdeputes.fr/thierry-mariani | X31: https://2012-2017.nosdeputes.fr/thierry-mariani/csv | Y31: 2 | Z31: ThierryMARIANI
A32: 30 | B32: Annie Genevard | C32: Reynier | D32: Franck | E32: H | F32: 24035 | G32: Montélimar (Drôme) | H32: 26 | I32: Drôme | J32: 2 | K32: 41080 | L32: 42906 | M32: 1 | N32: UDI | O32: Union des Radicaux, Centristes, Indépendants et Démocrates | P32: http://www.franckreynier.fr|http://www.franck-reynier.fr|https://twitter.com/FranckReynier| | Q32: 20/06/2007 / 19/06/2012 / fin de législature|20/06/2012 / / | | R32: Informaticien | S32: 211 | T32: http://www2.assemblee-nationale.fr/deputes/fiche/OMC_PA331442 | U32: 331442 | V32: franck-reynier | W32: https://2012-2017.nosdeputes.fr/franck-reynier | X32: https://2012-2017.nosdeputes.fr/franck-reynier/csv | Y32: 2 | Z32: FranckReynier
A33: 31 | B33: Annie Le Houerou | C33: Lepetit | D33: Annick | E33: F | F33: 21275 | G33: Boulogne-Billancourt (Hauts-de-Seine) | H33: 75 | I33: Paris | J33: 3 | K33: 41080 | L33: 42906 | M33: 1 | N33: SER | O33: Parti socialiste | P33: http://www.annicklepetit.fr|https://twitter.com/annick_lepetit| | Q33: 20/06/2007 / 19/06/2012 / fin de législature|20/06/2012 / / |19/06/2002 / 21/11/2002 / annulation de l'élection sur décision du conseil constitutionnel|03/02/2003 / 19/06/2007 / fin de législature| | R33: Cadre | S33: 372 | T33: http://www2.assemblee-nationale.fr/deputes/fiche/OMC_PA267965 | U33: 267965 | V33: annick-lepetit | W33: https://2012-2017.nosdeputes.fr/annick-lepetit | X33: https://2012-2017.nosdeputes.fr/annick-lepetit/csv | Y33: 2 | Z33: annick_lepetit
A34: 32 | B34: Antoine Herth | C34: Mamère | D34: Noël | E34: H | F34: 17892 | G34: Libourne (Gironde) | H34: 33 | I34: Gironde | J34: 3 | K34: 41080 | L34: 42906 | M34: 1 | N34: NI | O34: Europe Écologie Les Verts | P34: https://twitter.com/noelmamere| | Q34: 20/06/2007 / 19/06/2012 / fin de législature|20/06/2012 / / |01/06/1997 / 18/06/2002 / fin de législature|19/06/2002 / 19/06/2007 / fin de législature| | R34: Journaliste | S34: 303 | T34: http://www2.assemblee-nationale.fr/deputes/fiche/OMC_PA2045 | U34: 2045 | V34: noel-mamere | W34: https://2012-2017.nosdeputes.fr/noel-mamere | X34: https://2012-2017.nosdeputes.fr/noel-mamere/csv | Y34: 2 | Z34: noelmamere
A35: 33 | B35: Arlette Grosskost | C35: Scellier | D35: François | E35: H | F35: 13277 | G35: Amiens (Somme) | H35: 95 | I35: Val-d'Oise | J35: 6 | K35: 41080 | L35: 42906 | M35: 1 | N35: LR | O35: Union des Radicaux, Centristes, Indépendants et Démocrates | P35: http://www.scellier.net| | Q35: 20/06/2007 / 19/06/2012 / fin de législature|20/06/2012 / / |19/06/2002 / 19/06/2007 / fin de législature| | R35: Directeur divisionnaire des impôts honoraire | S35: 6 | T35: http://www2.assemblee-nationale.fr/deputes/fiche/OMC_PA2700 | U35: 2700 | V35: francois-scellier | W35: https://2012-2017.nosdeputes.fr/francois-scellier | X35: https://2012-2017.nosdeputes.fr/francois-scellier/csv | Y35: 2
A36: 34 | B36: Armand Jung | C36: Cherpion | D36: Gérard | E36: H | F36: 17607 | G36: Dombasle-sur-Meurthe (Meurthe-et-Moselle) | H36: 88 | I36: Vosges | J36: 2 | K36: 41080 | L36: 42906 | M36: 1 | N36: LR | O36: Les Républicains | P36: http://www.gerard-cherpion.fr|https://twitter.com/GerardCherpion| | Q36: 20/06/2007 / 19/06/2012 / fin de législature|20/06/2012 / / |02/04/1993 / 21/04/1997 / fin de législature|19/06/2002 / 19/06/2007 / fin de législature| | R36: Pharmacien | S36: 114 | T36: http://www2.assemblee-nationale.fr/deputes/fiche/OMC_PA856 | U36: 856 | V36: gerard-cherpion | W36: https://2012-2017.nosdeputes.fr/gerard-cherpion | X36: https://2012-2017.nosdeputes.fr/gerard-cherpion/csv | Y36: 2 | Z36: GerardCherpion
A37: 35 | B37: Arnaud Leroy | C37: Fraysse | D37: Jacqueline | E37: F | F37: 17223 | G37: Paris (Paris) | H37: 92 | I37: Hauts-de-Seine | J37: 4 | K37: 41080 | L37: 42906 | M37: 1 | N37: GDR | O37: Forces de gauche | Q37: 20/06/2007 / 19/06/2012 / fin de législature|20/06/2012 / / |02/07/1981 / 01/04/1986 / fin de législature|03/04/1978 / 22/05/1981 / fin de législature|01/06/1997 / 18/06/2002 / fin de législature|19/06/2002 / 19/06/2007 / fin de législature| | R37: Médecin cardiologue | S37: 590 | T37: http://www2.assemblee-nationale.fr/deputes/fiche/OMC_PA1364 | U37: 1364 | V37: jacqueline-fraysse | W37: https://2012-2017.nosdeputes.fr/jacqueline-fraysse | X37: https://2012-2017.nosdeputes.fr/jacqueline-fraysse/csv | Y37: 2
A38: 36 | B38: Arnaud Richard | C38: Leroy | D38: Maurice | E38: H | F38: 21583 | G38: Paris (Paris) | H38: 41 | I38: Loir-et-Cher | J38: 3 | K38: 41080 | L38: 42906 | M38: 1 | N38: UDI | O38: Association PSLE - Nouveau centre | P38: https://twitter.com/MauriceLeroy|http://www.mauriceleroymedia.com|http://www.facebook.com/maurice.leroy.politique| | Q38: 20/06/2012 / / |20/06/2007 / 15/12/2010 / nomination comme membre du gouvernement|01/06/1997 / 18/06/2002 / fin de législature|19/06/2002 / 19/06/2007 / fin de législature|17/06/2012 / 19/06/2012 / fin de législature| | R38: Économiste | S38: 200 | T38: http://www2.assemblee-nationale.fr/deputes/fiche/OMC_PA1960 | U38: 1960 | V38: maurice-leroy | W38: https://2012-2017.nosdeputes.fr/maurice-leroy | X38: https://2012-2017.nosdeputes.fr/maurice-leroy/csv | Y38: 2 | Z38: MauriceLeroy
A39: 37 | B39: Arnaud Robinet | C39: Vercamer | D39: Francis | E39: H | F39: 21315 | G39: Lille (Nord) | H39: 59 | I39: Nord | J39: 7 | K39: 41080 | L39: 42906 | M39: 1 | N39: UDI | O39: Association PSLE - Nouveau centre | P39: http://www.vercamer.fr| | Q39: 20/06/2007 / 19/06/2012 / fin de législature|20/06/2012 / / |19/06/2002 / 19/06/2007 / fin de législature| | R39: Ingénieur | S39: 191 | T39: http://www2.assemblee-nationale.fr/deputes/fiche/OMC_PA267585 | U39: 267585 | V39: francis-vercamer | W39: https://2012-2017.nosdeputes.fr/francis-vercamer | X39: https://2012-2017.nosdeputes.fr/francis-vercamer/csv | Y39: 2
A40: 38 | B40: Arnaud Viala | C40: Cornut-Gentille | D40: François | E40: H | F40: 21327 | G40: Saint-Mandé (Val-de-Marne) | H40: 52 | I40: Haute-Marne | J40: 2 | K40: 41080 | L40: 42906 | M40: 1 | N40: LR | O40: Les Républicains | P40: http://www.francois.cornut-gentille.fr| | Q40: 20/06/2007 / 19/06/2012 / fin de législature|20/06/2012 / / |01/06/1997 / 18/06/2002 / fin de législature|02/04/1993 / 21/04/1997 / fin de législature|19/06/2002 / 19/06/2007 / fin de législature| | R40: Cadre d'entreprise | S40: 94 | T40: http://www2.assemblee-nationale.fr/deputes/fiche/OMC_PA923 | U40: 923 | V40: francois-cornut-gentille | W40: https://2012-2017.nosdeputes.fr/francois-cornut-gentille | X40: https://2012-2017.nosdeputes.fr/francois-cornut-gentille/csv | Y40: 2
...

Sheet donnees_L14_PS_1an_amendements_
A1: legislature | B1: id_loi | C1: etape_discussion | D1: id_amendement | E1: date_amendement | H1: tri_date | I1: etape_texte | J1: action_amendement | K1: resume_amendement | L1: url_pdf | M1: statut_amendement | N1: auteur | O1: groupe_politique | P1: statut_auteur | Q1: co-signataires
A2: 14 | B2: PRJLANR5L14B0071 | C2: 1ère lecture (1ère assemblée saisie) | D2: AMANR5L14SEA644420B0071P0D1N407 | E2: 2012-07-12T00:00:00Z | F2: =LEFT(E2,4) -> 2012 | G2: =RIGHT(LEFT(E2,7),2) -> 07 | H2: =F2&G2 -> 201207 | I2: Article 27 | J2: Après le mot : « est », la fin de la première phrase du neuvième alinéa du V de l'article 43 de la loi n° 99‑1172 du 30 décembre 1999 de finances pour 2000 est ainsi rédigée : « , pour le laboratoire de Bure en Meuse, réparti en deux parts entre les départements de la Meuse et de la Haute‑Marne, à raison de 60 % pour la Meuse et 40 % pour la Haute‑Marne, et ce, à compter du 1er janvier 2013 ». | K2: L’objectif du présent amendement est de proposer une nouvelle répartition entre les départements de la Meuse et de la Haute-Marne. Le laboratoire de Bure est situé sur le département de la Meuse et une infime partie dans un rayon de 10 km déborde en Haute-Marne. Aussi, la Meuse accueille l’ensemble des installations dédiées au laboratoire et devra recevoir le site de stockage réversible en couches géologiques profondes des déchets nucléaires (Centre industriel de stockage géologique pour les déchets Haute Activité et Moyenne Activité à Vie Longue- CIGEO). Si le projet d’une zone interdépartementale d’activité économique est prévue, mais toujours pas réalisée, par les deux Conseils généraux, il est donc indispensable d’appliquer dès maintenant la répartition des ressources fiscales liées au laboratoire et au futur centre de stockage à partir de l’accord acté par le Comité de Haut Niveau, soit 60 % pour la Meuse et 40 % pour la Haute-Marne, et ce, en tenant compte du calendrier CIGEO. Aujourd’hui les deux départements reçoivent chacun 30 millions d’euros, sur les 60 millions annuels versés pour les années 2010, 2011 et 2012. | L2: /14/amendements/0071/AN/407.pdf | M2: Discuté | N2: Jean-Louis Dumont | O2: SER | P2: Depute | Q2: Jean-Louis Dumont
A3: 14 | B3: PRJLANR5L14B0071 | C3: 1ère lecture (1ère assemblée saisie) | D3: AMANR5L14SEA644420B0071P0D1N405 | E3: 2012-07-12T00:00:00Z | F3: =LEFT(E3,4) -> 2012 | G3: =RIGHT(LEFT(E3,7),2) -> 07 | H3: =F3&G3 -> 201207 | I3: Article 27 | J3: Le V de l’article 43 de la loi n° 99‑1172 du 30 décembre 1999 de finances pour 2000 est ainsi modifié : 1° Le début du cinquième alinéa est ainsi rédigé : « À compter du 1er janvier 2014 et pour la durée d’exploitation de l’installation, les valeurs...(le reste sans changement) » ; 2° Le tableau du sixième alinéa est ainsi modifié : a) À la troisième ligne de la deuxième colonne, le nombre : « 5,27 » est remplacé par le nombre : « 6,5 » ; b) À la troisième ligne de la troisième colonne, le nombre : « 1,73 » est remplacé par le nombre : « 2 » ; c) À la troisième ligne de la quatrième colonne, le nombre : « 0,87 » est remplacé par le nombre : « 1 » ; d) À la quatrième ligne de la deuxième colonne, le nombre : « 6,08 » est remplacé par le nombre : « 6,5 » ; e) À la cinquième ligne de la deuxième colonne, le nombre : « 6,08 » est remplacé par le nombre : « 6,5 » ; f) À la sixième ligne de la deuxième colonne, le nombre : « 5,32 » est remplacé par le nombre : « 6,5 » ; g) À la sixième ligne de la troisième colonne, le nombre : « 1,75 » est remplacé par le nombre : « 2 » ; h) À la sixième ligne de la quatrième colonne, le nombre : « 0,88 » est remplacé par le nombre : « 1 ». | K3: L’objectif du présent amendement est d’augmenter le montant des taxes additionnelles alimentant la redevance liée au laboratoire de Bure en Meuse et d’augmenter à due concurrence le versement, actuellement de 30 millions d’euros. | L3: /14/amendements/0071/AN/405.pdf | M3: Discuté | N3: Jean-Louis Dumont | O3: SER | P3: Depute | Q3: Jean-Louis Dumont
A4: 14 | B4: PRJLANR5L14B0071 | C4: 1ère lecture (1ère assemblée saisie) | D4: AMANR5L14SEA644420B0071P0D1N413 | E4: 2012-07-12T00:00:00Z | F4: =LEFT(E4,4) -> 2012 | G4: =RIGHT(LEFT(E4,7),2) -> 07 | H4: =F4&G4 -> 201207 | I4: Article 27 | J4: Le début du cinquième alinéa du V de l'article 43 de la loi n° 99–1172 du 30 décembre 1999 de finances pour 2000 est ainsi rédigé : « À compter du 1er janvier 2013, les valeurs...(le reste sans changement) ». | K4: L’objectif du présent amendement est de prolonger la redevance ANDRA liée au versement des taxes additionnelles dues par l’exploitant des installations du laboratoire de Bure en Meuse pour l’année 2013 et suivantes, autant d’années que le laboratoire sera en exploitation. | L4: /14/amendements/0071/AN/413.pdf | M4: Discuté | N4: Jean-Louis Dumont | O4: SER | P4: Depute | Q4: Jean-Louis Dumont
A5: 14 | B5: PRJLANR5L14B0071 | C5: 1ère lecture (1ère assemblée saisie) | D5: AMANR5L14SEA644420B0071P0D1N179 | E5: 2012-07-12T00:00:00Z | F5: =LEFT(E5,4) -> 2012 | G5: =RIGHT(LEFT(E5,7),2) -> 07 | H5: =F5&G5 -> 201207 | I5: Article 4 | J5: Après la référence : « 784, », rédiger ainsi la fin de l'alinéa 7 « les mots : « de celles passées depuis plus de dix ans » sont remplacés par les mots : « d’une seule donation antérieure et, le cas échéant, d’une donation de l’immeuble constituant au jour de la donation la résidence principale du donateur ». ». | K5: Les ménages ayant la possibilité de léguer à leurs enfants plus d'une fois dans la vie 100 000 euros sont extrêmement peu nombreux. En effet le patrimoine médian en France se situe à 150 200 euros. Les 10 % les mieux dotés ont au moins 552 300 euros de patrimoine brut et détiennent près de la moitié de la masse totale de celui-ci. Enfin, les 1 % des ménages les plus riches en termes de patrimoine détiennent chacun plus de 1,9 million d'euros d'avoirs. Cet abattement fiscal concerne donc une infime minorité de ménages déjà privilégiés. Les dispositions actuellement contenues dans le code général des impôts et modifiées par la loi de finances rectificative permettront de verser, tous les 15 ans, 100 000 euros par personne et par enfant exonéré d'impôts, ce qui permet par exemple à des parents avec deux enfants de verser 400 000 euros tous les 15 ans. Cette somme est particulièrement importante au regard de l'imposition à laquelle sont soumis les revenus. Cet amendement vise à rompre avec la République des héritiers, en privilégiant les revenus dégagés par les innovateurs et les créateurs d'emploi par rapport au patrimoine qui aboutit a une reproduction et un renforcement des inégalités entre les citoyens, encore plus rapide ces dernières années. Les inégalités de patrimoine ont en effet augmenté de 30 % entre 2004 et 2010 et sont 50 fois plus fortes que les inégalités de revenu. La fonction redistributive de l'impôt doit donc pleinement jouer son rôle qui a été négligé ces 20 dernières années. | L5: /14/amendements/0071/AN/179.pdf | M5: Irrecevable | N5: Razzy Hammadi | O5: SER | P5: Depute | Q5: Razzy Hammadi
A6: 14 | B6: PRJLANR5L14B0071 | C6: 1ère lecture (1ère assemblée saisie) | D6: AMANR5L14SEA644420B0071P0D1N395 | E6: 2012-07-12T00:00:00Z | F6: =LEFT(E6,4) -> 2012 | G6: =RIGHT(LEFT(E6,7),2) -> 07 | H6: =F6&G6 -> 201207 | I6: Article 6 | J6: Après l'alinéa 1, insérer l'alinéa suivant : « 1° A À la première phrase du premier alinéa du I, les mots : « un milliard » sont remplacés par les mots : « cent-cinquante millions ». | K6: Amendement d'élargissement du seuil de capitalisation boursière à partir duquel les entreprises sont soumises à la taxe sur les transactions financières. | L6: /14/amendements/0071/AN/395.pdf | M6: Discuté | N6: Laurent Grandguillaume | O6: SER | P6: Depute | Q6: Laurent Grandguillaume
A7: 14 | B7: PRJLANR5L14B0071 | C7: 1ère lecture (1ère assemblée saisie) | D7: AMANR5L14SEA644420B0071P0D1N410 | E7: 2012-07-12T00:00:00Z | F7: =LEFT(E7,4) -> 2012 | G7: =RIGHT(LEFT(E7,7),2) -> 07 | H7: =F7&G7 -> 201207 | I7: de finances rectificative pour 2012 | J7: I-Après l’article 43, alinéa 4 du V, LoiLoi n°99-1172 du 30 décembre 1999, modifié par la Loi n° 2011-1977 du 28 décembre 2011-art.46 (V), est ainsi rédigé « A compter du 1er janvier 2014 et pour la durée d’exploitation de l’installation, les valeurs des coefficients s’appliquant aux catégories d’installations visées dans le tableau précédent sont fixées comme suit : » II- A la 3ème ligne de la 2ème colonne du tableau du paragraphe 4, substituer au nombre : « 5,27 » le nombre : « 6,5 ». A la 3ème ligne de la 3ème colonne du tableau du paragraphe 4, substituer au nombre : « 1,73 » le nombre : « 2 ». A la 3ème ligne de la 4ème colonne du tableau du paragraphe 4, substituer au nombre : « 0,87 » le nombre : « 1 ». A la 4ème ligne de la 2ème colonne du tableau du paragraphe 4, substituer au nombre : « 6,08 » le nombre : « 6,5 ». A la 5ème ligne de la 2ème colonne du tableau du paragraphe 4, substituer au nombre : « 6,08 » le nombre : « 6,5 ». A la 6ème ligne de la 2ème colonne du tableau du paragraphe 4, substituer au nombre : « 5,32 » le nombre : « 6,5 ». A la 6ème ligne de la 3ème colonne du tableau du paragraphe 4, substituer au nombre : « 1,75 » le nombre : « 2 ». A la 6ème ligne de la 4ème colonne du tableau du paragraphe 4, substituer au nombre : « 0,88 » le nombre : « 1 ». | K7: L’objectif du présent amendement est d’augmenter le montant des taxes additionnelles alimentant la redevance liée au laboratoire de Bure en Meuse et d’augmenter à due concurrence le versement, actuellement de 30 millions d’euros. | L7: /14/amendements/0071/AN/410.pdf | M7: Retiré | N7: Jean-Louis Dumont | O7: SER | P7: Depute | Q7: Jean-Louis Dumont
A8: 14 | B8: PRJLANR5L14B0235 | C8: 1ère lecture (1ère assemblée saisie) | D8: AMANR5L14SEA644420B0235P2D1N521 | E8: 2012-11-09T00:00:00Z | F8: =LEFT(E8,4) -> 2012 | G8: =RIGHT(LEFT(E8,7),2) -> 11 | H8: =F8&G8 -> 201211 | I8: Article 68 | J8: Après l’alinéa 2, insérer l’alinéa suivant : « 1° bis Au 5° et à la première phrase de l'avant‑dernier alinéa du I, après la référence : « 3° », est insérée la référence : « du I » ; ». | K8: Amendement de coordination. | L8: /14/amendements/0235C/AN/521.pdf | M8: Discuté | N8: Pascal Terrasse | O8: SER | P8: Depute | Q8: Pascal Terrasse
A9: 14 | B9: PRJLANR5L14B0235 | C9: 1ère lecture (1ère assemblée saisie) | D9: AMANR5L14SEA644420B0235P2D1N519 | E9: 2012-11-09T00:00:00Z | F9: =LEFT(E9,4) -> 2012 | G9: =RIGHT(LEFT(E9,7),2) -> 11 | H9: =F9&G9 -> 201211 | I9: Article 67 | J9: Après l’alinéa 80, insérer les trois alinéas suivants : « 20° Aux a) et b) du 2° du I. de l’article L. 5217‑13, après la référence : « 3° », est insérée, par deux fois, la référence : « du I ». « I bis. – 1° À l’article L. 133‑11 du code du tourisme, la référence : « huitième alinéa du 4° » est remplacée par la référence : « deuxième alinéa du II » ; « 2° Le II de l’article 20 de la loi n° 2006‑436 du 14 avril 2006 relative aux parcs nationaux, aux parcs naturels marins et aux parcs naturels régionaux est abrogé ; ». | K9: Amendement de coordination. | L9: /14/amendements/0235C/AN/519.pdf | M9: Discuté | N9: Pascal Terrasse | O9: SER | P9: Depute | Q9: Pascal Terrasse
A10: 14 | B10: PRJLANR5L14B0235 | C10: 1ère lecture (1ère assemblée saisie) | D10: AMANR5L14SEA644420B0235P2D1N705 | E10: 2012-11-12T00:00:00Z | F10: =LEFT(E10,4) -> 2012 | G10: =RIGHT(LEFT(E10,7),2) -> 11 | H10: =F10&G10 -> 201211 | I10: Article 59 | J10: Le a bis de l’article L. 135 B du livre des procédures fiscales, est complété par une phrase ainsi rédigée : « Pour un produit local intégrant le risque de caisse, ces montants sont ventilés par date et type d’encaissement ; » | K10: L’article 100 de la loi de finances pour 2012 a sécurisé l’accès des collectivités locales au détail des données sur la CVAE, basées sur les déclarations des contribuables. Contrairement aux produits CVAE versés en 2011 aux collectivités locales qui correspondaient aux montants déclarés pour un millésime de valeur ajoutée, les produits 2012 correspondent aux montants versés l’année précédente. Les collectivités locales sont ainsi exposées aux risques de caisse. Cet amendement vise ainsi à compléter les informations restituées sur la CVAE pour permettre d’identifier cet écart avec les montants déclarés. Il importe en effet de pouvoir distinguer dans cet écart ce qui relève des ajustements effectués par l’entreprise elle-même (ajustement légal lors du versement des acomptes, en fonction de ses anticipations de réalisation de chiffre d’affaires et valeur ajoutée à clôture de l’exercice, rattrapage sur millésime antérieur et pénalités), de ce qui relève des activités de redressements. | L10: /14/amendements/0235C/AN/705.pdf | M10: Discuté | N10: Alain Rousset | O10: SER | P10: Depute | Q10: Alain Rousset
A11: 14 | B11: PRJLANR5L14B0235 | C11: 1ère lecture (1ère assemblée saisie) | D11: AMANR5L14SEA644420B0235P2D1N411 | E11: 2012-11-08T00:00:00Z | F11: =LEFT(E11,4) -> 2012 | G11: =RIGHT(LEFT(E11,7),2) -> 11 | H11: =F11&G11 -> 201211 | I11: Article 66 | J11: À l’alinéa 4, substituer aux mots : « 3 CIF », les mots : « la Caisse Centrale du Crédit Immobilier de France ». | K11: Amendement de précision. | L11: /14/amendements/0235C/AN/411.pdf | M11: Discuté | N11: Dominique Lefebvre | O11: SER | P11: Depute | Q11: Dominique Lefebvre
A12: 14 | B12: PRJLANR5L14B0235 | C12: 1ère lecture (1ère assemblée saisie) | D12: AMANR5L14SEA644420B0235P2D1N687 | E12: 2012-11-12T00:00:00Z | F12: =LEFT(E12,4) -> 2012 | G12: =RIGHT(LEFT(E12,7),2) -> 11 | H12: =F12&G12 -> 201211 | I12: Article 59 | J12: Les articles L. 2332‑2, L. 3332‑1‑1 et L. 4331‑2‑1 du code général des collectivités territoriales sont ainsi modifiés : 1° Au début du premier alinéa, est insérée la référence : « I » ; 2° Après l’avant-dernier alinéa, il est inséré un alinéa ainsi rédigé : « II. – Pour les impôts non recouvrés par voie de rôle et encaissés par l’État l’année précédente, l’attribution s’effectue en début d’année, avant le 31 janvier suivant le produit notifié provisoire et avant le 31 mars pour l’ajustement correspondant au produit notifié définitif. » ; 3° Au début du dernier alinéa, est insérée la référence : « III ». | K12: Le présent amendement vise à ajuster le versement du produit de CVAE aux collectivités locales, en tenant compte de la réalité d’encaissement par l’État auprès des entreprises. Le versement aux collectivités locales a été calé sur le système des douzièmes qui prévaut en fiscalité directe locale. Or, taxe d’habitation et taxes foncières sont des impôts sur rôle recouvrés en fin d’année par l’État, le versement par douzièmes aux collectivités correspond donc pour partie à des avances. La CVAE est un impôt auto-liquidé, le produit versé aux collectivités locales correspond aux encaissements perçus par l’État l’année précédente (début mai, 15 juin et 15 septembre). Par conséquent, le produit CVAE doit être versé sans délai, en début d’année ; sur la part du produit payé par les entreprises (3/4 du produit CVAE local), l’État bénéficie en effet de la trésorerie l’année précédente, lui permettant de verser la part du produit correspondant aux dégrèvements (1/4 du produit CVAE local) également dès le début d’année suivante. | L12: /14/amendements/0235C/AN/687.pdf | M12: Discuté | N12: Alain Rousset | O12: SER | P12: Depute | Q12: Alain Rousset
A13: 14 | B13: PRJLANR5L14B0235 | C13: 1ère lecture (1ère assemblée saisie) | D13: AMANR5L14SEA644420B0235P2D1N673 | E13: 2012-11-12T00:00:00Z | F13: =LEFT(E13,4) -> 2012 | G13: =RIGHT(LEFT(E13,7),2) -> 11 | H13: =F13&G13 -> 201211 | I13: Article 64 | J13: Après le mot : « communes », rédiger ainsi la fin de l'alinéa 7 : « faisant l’objet d’un arrêté de carence mentionné au L. 302-9-1 du code de la construction et de l’habitation, la taxe est instaurée de plein droit, ce pour la durée de l’arrêté de carence. » | K13: Afin de diminuer la tension locative sur le parc de logements privés, l’objet de cet amendement est de permettre une meilleure mobilisation des logements vacants, en renforçant le dispositif de majoration de la taxe d’habitation qui leur est applicable : les logements visés sont les logements vacants depuis deux ans au moins, soit une diminution de 3 ans de la durée de latence. Cette taxe est constituée comme une taxe d’habitation sur les logements vacants et donc avec les taux de la taxe d’habitation, limitant les questions d’optimisation fiscale, il est préférable que le taux reste celui de la taxe d’habitation. | L13: /14/amendements/0235C/AN/673.pdf | M13: Discuté | N13: Daniel Goldberg | O13: SER | P13: Depute | Q13: Daniel Goldberg
... A21: 14 | B21: PRJLANR5L14B0235 | C21: 1ère lecture (1ère assemblée saisie) | D21: AMANR5L14SEA644420B0235P2D1N177 | E21: 2012-10-31T00:00:00Z | F21: =LEFT(E21,4) -> 2012 | G21: =RIGHT(LEFT(E21,7),2) -> 10 | H21: =F21&G21 -> 201210 | I21: Article 62 | J21: Le Gouvernement remet au Parlement, au plus tard le 1er juin 2013, un rapport sur la situation des conjoints survivants des plus grands invalides de guerre, dont l’indice de pension était supérieur ou égal à 2 000 points. Le rapport précise les pistes envisagées pour augmenter le niveau des pensions des conjoints survivants en proportion des pensions versées aux plus grands invalides de guerre, y compris au moyen d’un prélèvement sur ces pensions. | K21: Les conjoints survivants de très grands invalides se trouvent fréquemment démunis lors du décès de l’ouvrant-droit, alors que le conjoint doit faire face seul aux frais du ménage et aux difficultés causées par le décès de l’invalide. Il existe en effet une disproportion considérable entre la pension que percevait l’invalide et celle qui est versée au conjoint survivant, 500 points au taux normal pour un soldat en application de l’article L. 50 du code des pensions militaires d’invalidité et des victimes de la guerre, majorée forfaitairement de 15 points depuis 2004. Cette disproportion est d’autant plus choquante que, dans presque tous les cas, le conjoint survivant a apporté ses soins à l’invalide, permettant souvent d’éviter une hospitalisation qui aurait été onéreuse pour la collectivité. Les lois de finances pour 2011 et 2011 avaient corrigé à la marge ce système en octroyant un complément de pension de 360 points aux veuves d’invalides bénéficiant de pensions de plus de 11 000 points. Il est temps d’aller plus loin et de mettre en place un dispositif complet, qui prenne en considération le montant des pensions versées aux plus grands invalides pour la fixation du montant des pensions des veuves et éviter ainsi une trop grande disproportion entre les deux. Le rapport du Gouvernement devra permettre d’informer pleinement le Parlement sur ce sujet pour lui permettre d’effectuer des choix en recensant précisément le nombre de veuves, en France et à l’étranger, leur âge et le montant de leurs pensions. Le rapport étudiera aussi la faisabilité de la mise en place d’une taxation des pensions des plus grands invalides pour financer un dispositif qui assure aux veuves une pension décente. | L21: /14/amendements/0235C/AN/177.pdf | M21: Discuté | N21: Daniel Boisserie | O21: SER | P21: Depute | Q21: Daniel Boisserie
A22: 14 | B22: PRJLANR5L14B0235 | C22: 1ère lecture (1ère assemblée saisie) | D22: AMANR5L14SEA644420B0235P2D1N629 | E22: 2012-11-09T00:00:00Z | F22: =LEFT(E22,4) -> 2012 | G22: =RIGHT(LEFT(E22,7),2) -> 11 | H22: =F22&G22 -> 201211 | I22: ÉTAT B | K22: Un amendement n° 446 du Gouvernement a été déposé et adopté le 9 novembre dernier afin de transférer les crédits de la DGME (qui vient d’être rebaptisée Direction interministérielle de modernisation de l’action publique, ou DIMAP), relevant de l’action 4 du programme Stratégie des finances publiques de la présente mission, au programme Coordination du travail gouvernemental de la mission Direction de l’action du Gouvernement, à laquelle la DGME serait désormais rattachée. Parallèlement, l’amendement n° 447 du Gouvernement, déposé sur cette mission, supprime les crédits de l’action 4 du programme Stratégie des finances publiques. La Rapporteure spéciale se félicite que le Gouvernement appuie ainsi les propositions qu’elle a formulées dans son rapport spécial en faveur d’un renforcement du pilotage interministériel de la réforme de l’État, par le rattachement de la DGME aux services du Premier ministre. Par le présent amendement, elle propose d’aller au bout de cette logique, en rattachant à la mission Direction de l’action du Gouvernement, outre la DGME, les programmes informatiques Chorus et ONP, qui relèvent respectivement des actions 05 Information financière de l’État et 06 Systèmes d’information et production de la paye. De tels projets informatiques transversaux sont de réels leviers de modernisation de l’action publique. Or, à l’issue de ses travaux, la Rapporteure spéciale a constaté que leur mise en œuvre pâtissait d’un manque de gouvernance interministérielle, et elle juge que leur rattachement à Bercy n’est pas optimal. Dans cette perspective, le présent amendement supprime le programme Stratégie des finances publiques et modernisation de l’État et reventile ses six actions, ce qui conduit à modifier l’architecture budgétaire de la mission. La DGME ou DIMAP peut donc être rattachée à la mission Direction de l’action du Gouvernement, du fait de l’adoption de l’amendement n° 446 précité, et la Rapporteure spéciale propose en conséquence de supprimer ses crédits (47,64 millions d’euros) au sein du programme Stratégie des finances publiques. Parallèlement, la Rapporteure spéciale propose de réunir les crédits des actions Information financière de l’État (85,3 et 81,6 millions d’euros en AE et CP) et Systèmes d’information et production de la paye (63,1 et 68,3 millions d’euros en AE et CP) du programme Stratégie des finances publiques, au sein d’un nouveau programme intitulé Systèmes d’information transversaux, et de rattacher ce dernier à la mission Direction de l’action du Gouvernement. Néanmoins, le droit existant ne lui permet pas, contrairement au Gouvernement, de créer un programme dans une autre mission ; de ce fait, dans un premier temps, le programme qu’elle crée est maintenu dans la mission Gestion des finances publiques et des ressources humaines. Les trois actions restantes du programme supprimé sont reventilées entre les différents autres programmes de la mission, à dotation constante : – l’action Politique des finances publiques et analyse de la performance des politiques publiques, qui correspond aux moyens de la direction du budget, soit 36,95 millions d’euros, est rattachée au programme Conduite et pilotage des politiques économique et financière ; – l’action Politique de la fonction publique et modernisation de la gestion des ressources humaines, qui regroupe la masse salariale des agents de la Direction générale de l’administration et de la fonction publique (DGAFP) pour 12,9 millions d’euros, est logiquement rattachée au programme Fonction publique, alors que ce programme porte d’ores et déjà les moyens dont dispose la DGAFP pour la formation des fonctionnaires. Ce changement de nomenclature permet de donner davantage de cohérence au programme Fonction publique, en remédiant à l’éclatement des crédits de la DGAFP ; – l’action Régulation des jeux correspond aux crédits de l’Autorité de régulation des jeux en ligne (ARJEL) pour respectivement 9,8 et 10,5 millions d’euros en AE et en CP en 2013 ; son rattachement au programme Stratégie des finances publiques apparaissait dès l’origine quelque peu incongru, comme l’avait souligné le précédent rapporteur spécial. Il semblerait plus pertinent de la placer au sein du programme Développement des entreprises et du tourisme, qui relève de la mission Économie, et qui porte notamment les moyens de la direction générale de la concurrence, de la consommation et de la répression des fraudes (DGCCRF). Néanmoins, encore une fois, le droit en vigueur ne permet pas de procéder par voie d’amendement parlementaire à des transferts de moyens entre deux missions différentes. À défaut, l’action Régulation des jeux est rattachée au programme Facilitation et sécurisation des échanges, pour rejoindre les activités de la direction générale des douanes et des droits indirects, laquelle participe, d’une certaine façon, à la protection des citoyens et des consommateurs, de même que l’ARJEL. | L22: /14/amendements/0235C/AN/629.pdf | M22: Discuté | N22: Karine Berger | O22: SER | P22: Depute | Q22: Karine Berger
A23: 14 | B23: PRJLANR5L14B0235 | C23: 1ère lecture (1ère assemblée saisie) | D23: AMANR5L14SEA644420B0235P2D1N689 | E23: 2012-11-12T00:00:00Z | F23: =LEFT(E23,4) -> 2012 | G23: =RIGHT(LEFT(E23,7),2) -> 11 | H23: =F23&G23 -> 201211 | I23: Article 59 | J23: L’article 1599 quater B du code général des impôts est ainsi modifié : 1° Au a) du I et à la première phrase du a) du III, après le mot : « cuivre », sont insérés les mots : « ou fibre optique » ; 2° Le IV devient le V ; 3° Après le tableau du b) du III, il est inséré un IV ainsi rédigé: « IV. – Les lignes fibre optique, activées pour la première fois au 1er janvier de l’année d’imposition donnent lieu à abattement sur les autres éléments d’assiette de l’opérateur, à due concurrence. Cet abattement ne vaut qu’une fois par ligne fibre optique, tout opérateur confondu. » | K23: Cet amendement a pour but de refonder, pour partie, l’imposition forfaitaire sur les entreprises de réseau (IFER) concernant les opérateurs de téléphonie. Instaurée par la loi de finances initiale 2010 et modifiée par celle de 2011, cette taxe revenant aux Régions est assise sur des éléments de la boucle locale cuivre. Du fait de la mutation technologique en cours vers la fibre optique, ces éléments sont appelés à être progressivement remplacés (effet substitutif total à terme). Afin de pérenniser l’assiette, l’amendement intègre les éléments du réseau fibre optique. Afin d’encourager la substitution de la fibre au cuivre, il prévoit une mesure d’abattement, lors de la 1ère activation de ligne abonné en fibre (IV). | L23: /14/amendements/0235C/AN/689.pdf | M23: Discuté | N23: Alain Rousset | O23: SER | P23: Depute | Q23: Alain Rousset
A24: 14 | B24: PRJLANR5L14B0235 | C24: 1ère lecture (1ère assemblée saisie) | D24: AMANR5L14SEA644420B0235P2D1N518 | E24: 2012-11-09T00:00:00Z | F24: =LEFT(E24,4) -> 2012 | G24: =RIGHT(LEFT(E24,7),2) -> 11 | H24: =F24&G24 -> 201211 | I24: Article 67 | J24: Après l’alinéa 67, insérer les quatre alinéas suivants : « 15° bis L’article L. 5211-28-1 est ainsi modifié : « a) Au premier alinéa, après la référence : « 3° », est insérée la référence : « du I » ; « b) À la deuxième phrase du troisième alinéa, après la référence : « 3° », est insérée la référence : « du I » , et à la dernière phrase du même alinéa, après le mot : « alinéa », est insérée la référence : « du II » ; « c) Au dernier alinéa, après le mot : « alinéa », est insérée la référence : « du II » ; » | K24: Amendement de coordination. | L24: /14/amendements/0235C/AN/518.pdf | M24: Discuté | N24: Pascal Terrasse | O24: SER | P24: Depute | Q24: Pascal Terrasse
A25: 14 | B25: PRJLANR5L14B0235 | C25: 1ère lecture (1ère assemblée saisie) | D25: AMANR5L14SEA644420B0235P2D1N509 | E25: 2012-11-09T00:00:00Z | F25: =LEFT(E25,4) -> 2012 | G25: =RIGHT(LEFT(E25,7),2) -> 11 | H25: =F25&G25 -> 201211 | I25: Article 67 | J25: Après l’alinéa 41, insérer l’alinéa suivant : « a bis) Au troisième alinéa du b du 1°, la première occurrence du mot : « moyen » est supprimée. ». | K25: Amendement rédactionnel. | L25: /14/amendements/0235C/AN/509.pdf | M25: Discuté | N25: Pascal Terrasse | O25: SER | P25: Depute | Q25: Pascal Terrasse
A26: 14 | B26: PRJLANR5L14B0235 | C26: 1ère lecture (1ère assemblée saisie) | D26: AMANR5L14SEA644420B0235P2D1N682 | E26: 2012-11-12T00:00:00Z | F26: =LEFT(E26,4) -> 2012 | G26: =RIGHT(LEFT(E26,7),2) -> 11 | H26: =F26&G26 -> 201211 | I26: Article 59 | J26: I.– Le I de l’article 1384 C du code général des impôts est complété par un alinéa ainsi rédigé : «Toutefois, la durée d’exonération est ramenée à quinze ans pour les logements acquis auprès des organismes visés à l’article L.411-5 du code de la construction et de l'habitation et au moyen de prêts visés à la sous-section 3 de la section 1 du chapitre unique du titre III du livre III du même code.» II.– Le I du présent article s'applique aux décisions d'octroi de subvention ou de prêt intervenues à compter du 1er janvier 2009. | K26: En novembre 2009, environ 35 000 logements locatifs étaient cédés par la société Icade, filiale cotée de la Caisse des dépôts et consignations, à un consortium de 26 bailleurs sociaux mené par la Société Nationale Immobilière. Peu avant, à la suite notamment d'une mobilisation sans précédent de 36 maires d'Ile-de-France, le gouvernement d’alors s'engageait à compenser les exonérations de taxe foncière sur les propriétés bâties accordées à ces bailleurs lors d'acquisition en PLS, en déposant un amendement, adopté à l'unanimité à l'Assemblée nationale dans le cadre de la discussion du projet de loi de finances pour 2010. Mais du fait que les différentes compensations d'exonérations sont devenues, depuis l'entrée en application de la loi de finances pour 2009, des variables d'ajustement au sein de l'enveloppe normée des concours de l'Etat, le montant de cette compensation se trouve chaque année réduit par l'application d'un coefficient déflateur cumulé. En 2012, les exonérations de taxe foncière sur les propriétés bâties liées au patrimoine Icade n’ont été compensées qu'à 62%. Cet amendement vise donc à limiter la pénalisation financière des collectivités locales qui, accueillant l’ancien patrimoine immobilier d’Icade, contribuent activement au maintien d’une offre de logements accessibles aux ménages les plus fragiles, en réduisant la durée d'exonération à 15 ans. | L26: /14/amendements/0235C/AN/682.pdf | M26: Discuté | N26: François Pupponi | O26: SER | P26: Depute | Q26: François Pupponi
A27: 14 | B27: PRJLANR5L14B0235 | C27: 1ère lecture (1ère assemblée saisie) | D27: AMANR5L14SEA644420B0235P2D1N529 | E27: 2012-11-09T00:00:00Z | F27: =LEFT(E27,4) -> 2012 | G27: =RIGHT(LEFT(E27,7),2) -> 11 | H27: =F27&G27 -> 201211 | I27: Article 67 | J27: Substituer à l’alinéa 20 les deux alinéas suivants : « d) Le sixième alinéa du 4° est ainsi rédigé : « II. – Le taux de croissance de la dotation forfaitaire est égal au taux d’évolution de la somme des composantes de cette dotation par rapport à la somme des montants versés l’année précédente en application du I, hors les montants prévus à son 3°. À compter de 2011, pour le calcul de ce taux de référence, il n’est pas tenu compte de l’évolution de la dotation forfaitaire liée aux variations de la population telle que définie par l’article L. 2334‑2, ni des évolutions liées aux éventuelles minorations des composantes de la dotation forfaitaire prévues aux 3° et 4° du I. ». | K27: Amendement rédactionnel. | L27: /14/amendements/0235C/AN/529.pdf | M27: Retiré | N27: Pascal Terrasse | O27: SER | P27: Depute | Q27: Pascal Terrasse
A28: 14 | B28: PRJLANR5L14B0235 | C28: 1ère lecture (1ère assemblée saisie) | D28: AMANR5L14SEA644420B0235P2D1N508 | E28: 2012-11-09T00:00:00Z | F28: =LEFT(E28,4) -> 2012 | G28: =RIGHT(LEFT(E28,7),2) -> 11 | H28: =F28&G28 -> 201211 | I28: Article 67 | J28: Au début de l’alinéa 36, substituer aux mots : « L’indice » les mots : « Cet indice ». | K28: Amendement rédactionnel. | L28: /14/amendements/0235C/AN/508.pdf | M28: Discuté | N28: Pascal Terrasse | O28: SER | P28: Depute | Q28: Pascal Terrasse
A29: 14 | B29: PRJLANR5L14B0235 | C29: 1ère lecture (1ère assemblée saisie) | D29: AMANR5L14SEA644420B0235P2D1N395 | E29: 2012-11-08T00:00:00Z | F29: =LEFT(E29,4) -> 2012 | G29: =RIGHT(LEFT(E29,7),2) -> 11 | H29: =F29&G29 -> 201211 | I29: Article 66 | J29: À l’alinéa 2, substituer au mot : « intérêt », le mot : « intérêts ». | K29: Amendement rédactionnel. | L29: /14/amendements/0235C/AN/395.pdf | M29: Discuté | N29: Dominique Lefebvre | O29: SER | P29: Depute | Q29: Dominique Lefebvre
