Workbook

Sheet Nuance
B2: Libellé | C2: Signification | D2: G
B3: LEXG | C3: Liste Extrême gauche | D3: G
B4: LFG | C4: Liste du Front de Gauche | D4: G
B5: LPG | C5: Liste du Parti de Gauche | D5: G
B6: LCOM | C6: Liste du Parti communiste français | D6: G
B7: LVEG | C7: Liste Europe Ecologie-Les Verts et gauche | D7: G
B8: LSOC | C8: Liste du Parti Socialiste | D8: G
B9: LUG | C9: Liste Union de la Gauche | D9: G
B10: LRDG | C10: Liste du Parti radical de gauche | D10: G
B11: LDVG | C11: Liste Divers gauche | D11: G
B12: LVEC | C12: Liste d’Europe-Ecologie-Les Verts | D12: G
B13: LECO | C13: Liste Ecologiste | D13: G
... B23: LEXD | C23: Liste Extrême droite | D23: D

Sheet hypothèses
A1: hypothèse exo 3 | B1: étape d'analyse
A2: dans les régions du Nord ce sont majoritairement les listes de droite qui ont remporté les élections | B2: catégoriser libellé régions par NORD SUD EST OUEST catégoriser nuance par GAUCHE CENTRE DROITE somme(voix) de couleur droite dans geographie NORD est supérieure à la somme(voix) de couleur gauche ou du centre
A3: la droite a gagné le plus de régions
A4: la droite est plus puissante dans le Sud-est
A5: la gauche l'a remporté dans les régions frontalières

Sheet candidats
A1: Date de l'export | B1: Code de la région | C1: Libellé de la région | D1: Code section électorale | E1: Libellé section électorale | F1: N° Panneau Liste | G1: Code Dépôt Liste | H1: Libellé abrégé liste | I1: Libellé Etendu Liste | J1: Nuance Liste | K1: Tête de Liste | L1: n° candidat | M1: Sexe candidat | N1: Nom candidat | O1: Prénom candidat | Q1: Date naissance candidat | R1: Profession candidat | S1: Personnalité candidat | T1: Le candidat est sortant
A2: 42318.715 | B2: 44 | C2: Alsace - Champagne-Ardenne - Lorraine | D2: 67 | E2: Bas-Rhin | F2: 1 | G2: 9 | H2: EUROPE ECOLOGIE LES VERTS | I2: ÉCOLOGISTES, SOLIDAIRES ET CITOYENS | J2: LVEG | K2: OUI | L2: 1 | M2: F | N2: BÉLIER | O2: Sandrine | P2: =IFERROR(__xludf.DUMMYFUNCTION("JOIN("" "",N2:O2)"),"BÉLIER Sandrine") -> BÉLIER Sandrine | Q2: 26909 | R2: Industriel-Chef entreprise | T2: Non
A3: 42318.715 | B3: 44 | C3: Alsace - Champagne-Ardenne - Lorraine | D3: 57 | E3: Moselle | F3: 2 | G3: 4 | H3: LFG | I3: Nos vies d'abord ! | J3: LFG | K3: OUI | L3: 1 | M3: M | N3: PERON | O3: Patrick | P3: =IFERROR(__xludf.DUMMYFUNCTION("JOIN("" "",N3:O3)"),"PERON Patrick") -> PERON Patrick | Q3: 19946 | R3: Retraité salarié privé | T3: Non
A4: 42318.715 | B4: 44 | C4: Alsace - Champagne-Ardenne - Lorraine | D4: 88 | E4: Vosges | F4: 3 | G4: 2 | H4: DEBOUT LA FRANCE | I4: DEBOUT LA FRANCE AVEC NICOLAS DUPONT-AIGNAN | J4: LDLF | K4: OUI | L4: 1 | M4: M | N4: JACOBELLI | O4: Laurent | P4: =IFERROR(__xludf.DUMMYFUNCTION("JOIN("" "",N4:O4)"),"JACOBELLI Laurent") -> JACOBELLI Laurent | Q4: 25489 | R4: Industriel-Chef entreprise | T4: Non
A5: 42318.715 | B5: 44 | C5: Alsace - Champagne-Ardenne - Lorraine | D5: 57 | E5: Moselle | F5: 4 | G5: 7 | H5: PARTI SOCIALISTE | I5: + FORTE, + PROCHE, NOTRE REGION AVEC JEAN-PIERRE MASSERET | J5: LUG | K5: OUI | L5: 2 | M5: M | N5: MASSERET | O5: Jean-Pierre | P5: =IFERROR(__xludf.DUMMYFUNCTION("JOIN("" "",N5:O5)"),"MASSERET Jean-Pierre") -> MASSERET Jean-Pierre | Q5: 16307 | R5: Retraité fonct.publique (sf enseig.) | S5: SEN,PCR | T5: Oui
A6: 42318.715 | B6: 44 | C6: Alsace - Champagne-Ardenne - Lorraine | D6: 57 | E6: Moselle | F6: 5 | G6: 6 | H6: FRONT NATIONAL | I6: LISTE FRONT NATIONAL PRESENTEE PAR MARINE LE PEN | J6: LFN | K6: OUI | L6: 1 | M6: M | N6: PHILIPPOT | O6: Florian | P6: =IFERROR(__xludf.DUMMYFUNCTION("JOIN("" "",N6:O6)"),"PHILIPPOT Florian") -> PHILIPPOT Florian | Q6: 29883 | R6: Grands corps de l'état | S6: RPE | T6: Non
A7: 42318.715 | B7: 44 | C7: Alsace - Champagne-Ardenne - Lorraine | D7: 88 | E7: Vosges | F7: 6 | G7: 5 | H7: UPR | I7: L'UPR, avec FRANÇOIS ASSELINEAU - LE PARTI QUI MONTE malgré le silence des médias | J7: LDIV | K7: OUI | L7: 1 | M7: M | N7: WENTZEL | O7: David | P7: =IFERROR(__xludf.DUMMYFUNCTION("JOIN("" "",N7:O7)"),"WENTZEL David") -> WENTZEL David | Q7: 31128 | R7: Agent subalterne (entr.publiques) | T7: Non
A8: 42318.715 | B8: 44 | C8: Alsace - Champagne-Ardenne - Lorraine | D8: 68 | E8: Haut-Rhin | F8: 7 | G8: 3 | H8: LUTTE OUVRIERE | I8: Lutte ouvrière - Faire entendre le camp des travailleurs | J8: LEXG | K8: OUI | L8: 2 | M8: M | N8: WOSTYN | O8: Julien | P8: =IFERROR(__xludf.DUMMYFUNCTION("JOIN("" "",N8:O8)"),"WOSTYN Julien") -> WOSTYN Julien | Q8: 28847 | R8: Ouvrier (secteur privé) | T8: Non
A9: 42318.715 | B9: 44 | C9: Alsace - Champagne-Ardenne - Lorraine | D9: 68 | E9: Haut-Rhin | F9: 8 | G9: 10 | H9: LISTE RÉGIONALISTE | I9: Non à l'ACAL, Oui à nos régions ! | J9: LREG | K9: OUI | L9: 2 | M9: M | N9: TROUILLET | O9: Jean-Georges | P9: =IFERROR(__xludf.DUMMYFUNCTION("JOIN("" "",N9:O9)"),"TROUILLET Jean-Georges") -> TROUILLET Jean-Georges | Q9: 28456 | R9: Ingénieur | T9: Non
A10: 42318.715 | B10: 44 | C10: Alsace - Champagne-Ardenne - Lorraine | D10: 67 | E10: Bas-Rhin | F10: 9 | G10: 8 | H10: LLR | I10: Unissons nos énergies avec Philippe RICHERT | J10: LUD | K10: OUI | L10: 1 | M10: M | N10: RICHERT | O10: Philippe | P10: =IFERROR(__xludf.DUMMYFUNCTION("JOIN("" "",N10:O10)"),"RICHERT Philippe") -> RICHERT Philippe | Q10: 19501 | R10: Permanent politique | S10: PCR | T10: Oui
A11: 42318.715 | B11: 75 | C11: Aquitaine - Limousin - Poitou-Charentes | D11: 33 | E11: Gironde | F11: 1 | G11: 10 | H11: NOUVELLE DONNE | I11: NOUVELLE DONNE : REPRENEZ LA MAIN ! | J11: LDVG | K11: OUI | L11: 11 | M11: M | N11: PEREIRA | O11: Nicolas | P11: =IFERROR(__xludf.DUMMYFUNCTION("JOIN("" "",N11:O11)"),"PEREIRA Nicolas") -> PEREIRA Nicolas | Q11: 33409 | R11: Autre cadre (secteur privé) | T11: Non
A12: 42318.715 | B12: 75 | C12: Aquitaine - Limousin - Poitou-Charentes | D12: 33 | E12: Gironde | F12: 2 | G12: 5 | H12: PLUS FORTS, PLUS SOLIDAIR | I12: PLUS FORTS, PLUS SOLIDAIRES, ENSEMBLE | J12: LUG | K12: OUI | L12: 1 | M12: M | N12: ROUSSET | O12: Alain | P12: =IFERROR(__xludf.DUMMYFUNCTION("JOIN("" "",N12:O12)"),"ROUSSET Alain") -> ROUSSET Alain | Q12: 18675 | R12: Autre profession | S12: DEP,PCR | T12: Oui
A13: 42318.715 | B13: 75 | C13: Aquitaine - Limousin - Poitou-Charentes | D13: 33 | E13: Gironde | F13: 3 | G13: 7 | H13: GENERATION NOUVELLE REGIO | I13: GENERATION NOUVELLE REGION | J13: LUD | K13: OUI | L13: 1 | M13: F | N13: CALMELS | O13: Virginie | P13: =IFERROR(__xludf.DUMMYFUNCTION("JOIN("" "",N13:O13)"),"CALMELS Virginie") -> CALMELS Virginie | Q13: 25975 | R13: Administrateur de sociétés | T13: Non
A14: 42318.715 | B14: 75 | C14: Aquitaine - Limousin - Poitou-Charentes | D14: 64 | E14: Pyrénées-Atlantiques | F14: 4 | G14: 9 | H14: L'HUMAIN D'ABORD ! | I14: L'HUMAIN D'ABORD ! | J14: LFG | K14: OUI | L14: 2 | M14: M | N14: DARTIGOLLES | O14: Olivier | P14: =IFERROR(__xludf.DUMMYFUNCTION("JOIN("" "",N14:O14)"),"DARTIGOLLES Olivier") -> DARTIGOLLES Olivier | Q14: 25807 | R14: Permanent politique | T14: Non
A15: 42318.715 | B15: 75 | C15: Aquitaine - Limousin - Poitou-Charentes | D15: 33 | E15: Gironde | F15: 5 | G15: 6 | H15: L'UPR | I15: L'UPR AVEC FRANCOIS ASSELINEAU - LE PARTI QUI MONTE MALGRE LE SILENCE DES MEDIAS | J15: LDIV | K15: OUI | L15: 19 | M15: M | N15: DOUET | O15: William | P15: =IFERROR(__xludf.DUMMYFUNCTION("JOIN("" "",N15:O15)"),"DOUET William") -> DOUET William | Q15: 33754 | R15: Etudiant | T15: Non
A16: 42318.715 | B16: 75 | C16: Aquitaine - Limousin - Poitou-Charentes | D16: 64 | E16: Pyrénées-Atlantiques | F16: 6 | G16: 11 | H16: FAISONS ENSEMBLE | I16: FAISONS ENSEMBLE | J16: LDVG | K16: OUI | L16: 3 | M16: M | N16: BOUSSION | O16: Joseph | P16: =IFERROR(__xludf.DUMMYFUNCTION("JOIN("" "",N16:O16)"),"BOUSSION Joseph") -> BOUSSION Joseph | Q16: 31058 | R16: Sans profession déclarée | T16: Non
A17: 42318.715 | B17: 75 | C17: Aquitaine - Limousin - Poitou-Charentes | D17: 16 | E17: Charente | F17: 7 | G17: 8 | H17: OSONS MIEUX | I17: OSONS MIEUX AVEC FRANÇOISE COUTANT - LISTE ECOLOGISTE ET CITOYENNE | J17: LVEC | K17: OUI | L17: 1 | M17: F | N17: COUTANT | O17: Françoise | P17: =IFERROR(__xludf.DUMMYFUNCTION("JOIN("" "",N17:O17)"),"COUTANT Françoise") -> COUTANT Françoise | Q17: 24262 | R17: Professeur du secondaire et techn. | T17: Oui
A18: 42318.715 | B18: 75 | C18: Aquitaine - Limousin - Poitou-Charentes | D18: 33 | E18: Gironde | F18: 8 | G18: 3 | H18: LISTE FRONT NATIONAL | I18: LISTE FRONT NATIONAL PRESENTEE PAR MARINE LE PEN | J18: LFN | K18: OUI | L18: 1 | M18: M | N18: COLOMBIER | O18: Jacques | P18: =IFERROR(__xludf.DUMMYFUNCTION("JOIN("" "",N18:O18)"),"COLOMBIER Jacques") -> COLOMBIER Jacques | Q18: 19041 | R18: Retraité des professions libérales | T18: Non
A19: 42318.715 | B19: 75 | C19: Aquitaine - Limousin - Poitou-Charentes | D19: 47 | E19: Lot-et-Garonne | F19: 9 | G19: 4 | H19: DEBOUT LA FRANCE | I19: DEBOUT LA FRANCE AVEC NICOLAS DUPONT AIGNAN | J19: LDLF | K19: OUI | L19: 1 | M19: M | N19: SETZE | O19: Yvon | P19: =IFERROR(__xludf.DUMMYFUNCTION("JOIN("" "",N19:O19)"),"SETZE Yvon") -> SETZE Yvon | Q19: 19116 | R19: Retr.artis.commerc.chef d entrep. | T19: Non
A20: 42318.715 | B20: 75 | C20: Aquitaine - Limousin - Poitou-Charentes | D20: 33 | E20: Gironde | F20: 10 | G20: 2 | H20: LUTTE OUVRIERE | I20: LUTTE OUVRIERE - FAIRE ENTENDRE LE CAMP DES TRAVAILLEURS | J20: LEXG | K20: OUI | L20: 2 | M20: M | N20: PERCHET | O20: Guillaume | P20: =IFERROR(__xludf.DUMMYFUNCTION("JOIN("" "",N20:O20)"),"PERCHET Guillaume") -> PERCHET Guillaume | Q20: 25877 | R20: Autre cadre (secteur privé) | T20: Non
A21: 42318.715 | B21: 84 | C21: Auvergne - Rhône-Alpes | D21: 26 | E21: Drôme | F21: 1 | G21: 3 | H21: L'UPR, AVEC FRANÇOIS ASSE | I21: L'UPR, avec François ASSELINEAU - LE PARTI QUI MONTE malgré le silence des médias | J21: LDIV | K21: OUI | L21: 1 | M21: M | N21: FÉDÈLE | O21: Alain | P21: =IFERROR(__xludf.DUMMYFUNCTION("JOIN("" "",N21:O21)"),"FÉDÈLE Alain") -> FÉDÈLE Alain | Q21: 23420 | R21: Homme de lettres et Artiste | T21: Non
A22: 42318.715 | B22: 84 | C22: Auvergne - Rhône-Alpes | D22: 69M | E22: Métropole de Lyon | F22: 2 | G22: 10 | H22: 100% CITOYEN | I22: 100% CITOYEN | J22: LDVD | K22: OUI | L22: 1 | M22: M | N22: LAFOND | O22: Eric | P22: =IFERROR(__xludf.DUMMYFUNCTION("JOIN("" "",N22:O22)"),"LAFOND Eric") -> LAFOND Eric | Q22: 26541 | R22: Autre cadre (secteur privé) | T22: Non
A23: 42318.715 | B23: 84 | C23: Auvergne - Rhône-Alpes | D23: 69M | E23: Métropole de Lyon | F23: 3 | G23: 7 | H23: LISTE FRONT NATIONAL PRÉS | I23: Liste Front National présentée par Marine LE PEN | J23: LFN | K23: OUI | L23: 1 | M23: M | N23: BOUDOT | O23: Christophe | P23: =IFERROR(__xludf.DUMMYFUNCTION("JOIN("" "",N23:O23)"),"BOUDOT Christophe") -> BOUDOT Christophe | Q23: 25422 | R23: Industriel-Chef entreprise | T23: Oui
A24: 42318.715 | B24: 84 | C24: Auvergne - Rhône-Alpes | D24: 42 | E24: Loire | F24: 4 | G24: 8 | H24: L'HUMAIN D'ABORD, AVEC LA | I24: L'Humain d'abord, avec la gauche républicaine et sociale | J24: LCOM | K24: OUI | L24: 1 | M24: F | N24: CUKIERMAN | O24: Cécile | P24: =IFERROR(__xludf.DUMMYFUNCTION("JOIN("" "",N24:O24)"),"CUKIERMAN Cécile") -> CUKIERMAN Cécile | Q24: 27876 | R24: Professeur du secondaire et techn. | S24: SEN | T24: Oui
A25: 42318.715 | B25: 84 | C25: Auvergne - Rhône-Alpes | D25: 38 | E25: Isère | F25: 5 | G25: 2 | H25: LUTTE OUVRIERE - FAIRE EN | I25: Lutte ouvrière - Faire entendre le camp des travailleurs | J25: LEXG | K25: OUI | L25: 1 | M25: F | N25: GOMEZ | O25: Chantal | P25: =IFERROR(__xludf.DUMMYFUNCTION("JOIN("" "",N25:O25)"),"GOMEZ Chantal") -> GOMEZ Chantal | Q25: 20563 | R25: Fonctionnaire de catégorie C | T25: Non
A26: 42318.715 | B26: 84 | C26: Auvergne - Rhône-Alpes | D26: 43 | E26: Haute-Loire | F26: 6 | G26: 9 | H26: WAUQUIEZ 2015, UN NOUVEAU | I26: WAUQUIEZ 2015, un nouveau souffle pour notre région LE GRAND RASSEMBLEMENT de la DROITE et du CENTRE | J26: LUD | K26: OUI | L26: 1 | M26: M | N26: WAUQUIEZ | O26: Laurent | P26: =IFERROR(__xludf.DUMMYFUNCTION("JOIN("" "",N26:O26)"),"WAUQUIEZ Laurent") -> WAUQUIEZ Laurent | Q26: 27496 | R26: Autre profession | S26: DEP | T26: Non
A27: 42318.715 | B27: 84 | C27: Auvergne - Rhône-Alpes | D27: 69D | E27: Rhône hors métropole de Lyon | F27: 8 | G27: 5 | H27: LE RASSEMBLEMENT CITOYEN, | I27: LE RASSEMBLEMENT CITOYEN, ECOLOGIQUE ET SOLIDAIRE | J27: LVEG | K27: OUI | L27: 1 | M27: M | N27: KOHLHAAS | O27: Jean-Charles | P27: =IFERROR(__xludf.DUMMYFUNCTION("JOIN("" "",N27:O27)"),"KOHLHAAS Jean-Charles") -> KOHLHAAS Jean-Charles | Q27: 23649 | R27: Salarié du secteur médical | T27: Oui
A28: 42318.715 | B28: 84 | C28: Auvergne - Rhône-Alpes | D28: 69D | E28: Rhône hors métropole de Lyon | F28: 9 | G28: 4 | H28: DEBOUT LA FRANCE AVEC NIC | I28: DEBOUT LA FRANCE AVEC NICOLAS DUPONT-AIGNAN | J28: LDLF | K28: OUI | L28: 1 | M28: M | N28: RAMBAUD | O28: Gerbert | P28: =IFERROR(__xludf.DUMMYFUNCTION("JOIN("" "",N28:O28)"),"RAMBAUD Gerbert") -> RAMBAUD Gerbert | Q28: 23304 | R28: Avocat | T28: Non
A29: 42318.715 | B29: 84 | C29: Auvergne - Rhône-Alpes | D29: 69M | E29: Métropole de Lyon | F29: 10 | G29: 6 | H29: NOUS, C'EST LA RÉGION | I29: NOUS, C'EST LA RÉGION | J29: LUG | K29: OUI | L29: 1 | M29: M | N29: QUEYRANNE | O29: Jean-Jack | P29: =IFERROR(__xludf.DUMMYFUNCTION("JOIN("" "",N29:O29)"),"QUEYRANNE Jean-Jack") -> QUEYRANNE Jean-Jack | Q29: 16743 | R29: Retraité de l'enseignement | S29: PCR | T29: Oui
A30: 42318.715 | B30: 27 | C30: Bourgogne - Franche-Comté | D30: 25 | E30: Doubs | F30: 1 | G30: 6 | H30: FRONT NATIONAL | I30: LISTE FRONT NATIONAL PRÉSENTÉE PAR MARINE LE PEN | J30: LFN | K30: OUI | L30: 1 | M30: F | N30: MONTEL | O30: Sophie | P30: =IFERROR(__xludf.DUMMYFUNCTION("JOIN("" "",N30:O30)"),"MONTEL Sophie") -> MONTEL Sophie | Q30: 25529 | R30: Autre cadre (secteur privé) | S30: RPE | T30: Oui
A31: 42318.715 | B31: 27 | C31: Bourgogne - Franche-Comté | D31: 58 | E31: Nièvre | F31: 2 | G31: 5 | H31: UPR | I31: L'UPR avec François ASSELINEAU - LE PARTI QUI MONTE malgré le silence des médias | J31: LDIV | K31: OUI | L31: 1 | M31: M | N31: GALLOIS | O31: Charles-Henri | P31: =IFERROR(__xludf.DUMMYFUNCTION("JOIN("" "",N31:O31)"),"GALLOIS Charles-Henri") -> GALLOIS Charles-Henri | Q31: 32447 | R31: Autre cadre (secteur privé) | T31: Non
A32: 42318.715 | B32: 27 | C32: Bourgogne - Franche-Comté | D32: 21 | E32: Côte-d'Or | F32: 3 | G32: 8 | H32: REGION GRAND | I32: LA REGION EN GRAND | J32: LUD | K32: OUI | L32: 1 | M32: M | N32: SAUVADET | O32: François | P32: =IFERROR(__xludf.DUMMYFUNCTION("JOIN("" "",N32:O32)"),"SAUVADET François") -> SAUVADET François | Q32: 19469 | R32: Permanent politique | S32: DEP,PCD | T32: Non
A33: 42318.715 | B33: 27 | C33: Bourgogne - Franche-Comté | D33: 58 | E33: Nièvre | F33: 4 | G33: 11 | H33: AEI BFC | I33: ALLIANCE ECOLOGISTE INDEPENDANTE DE BOURGOGNE ET FRANCHE-COMTE | J33: LECO | K33: OUI | L33: 1 | M33: M | N33: GONZALEZ | O33: Julien | P33: =IFERROR(__xludf.DUMMYFUNCTION("JOIN("" "",N33:O33)"),"GONZALEZ Julien") -> GONZALEZ Julien | Q33: 27753 | R33: Journaliste et autre média | T33: Non
A34: 42318.715 | B34: 27 | C34: Bourgogne - Franche-Comté | D34: 25 | E34: Doubs | F34: 5 | G34: 9 | H34: ÉCOLOGISTES BFC | I34: LES ÉCOLOGISTES DE BOURGOGNE FRANCHE-COMTÉ | J34: LVEC | K34: OUI | L34: 1 | M34: F | N34: PRUDHOMME | O34: Cécile | P34: =IFERROR(__xludf.DUMMYFUNCTION("JOIN("" "",N34:O34)"),"PRUDHOMME Cécile") -> PRUDHOMME Cécile | Q34: 27804 | R34: Permanent politique | T34: Non
A35: 42318.715 | B35: 27 | C35: Bourgogne - Franche-Comté | D35: 71 | E35: Saône-et-Loire | F35: 6 | G35: 7 | H35: ALTERNATIVE GAUCHE | I35: L'ALTERNATIVE À GAUCHE | J35: LFG | K35: OUI | L35: 1 | M35: F | N35: VERMOREL | O35: Nathalie | P35: =IFERROR(__xludf.DUMMYFUNCTION("JOIN("" "",N35:O35)"),"VERMOREL Nathalie") -> VERMOREL Nathalie | Q35: 22088 | R35: Assistante sociale | T35: Oui
A36: 42318.715 | B36: 27 | C36: Bourgogne - Franche-Comté | D36: 21 | E36: Côte-d'Or | F36: 7 | G36: 4 | H36: LUTTE OUVRIERE | I36: LUTTE OUVRIERE - FAIRE ENTENDRE LE CAMP DES TRAVAILLEURS | J36: LEXG | K36: OUI | L36: 2 | M36: F | N36: ROCHER | O36: Claire | P36: =IFERROR(__xludf.DUMMYFUNCTION("JOIN("" "",N36:O36)"),"ROCHER Claire") -> ROCHER Claire | Q36: 28760 | R36: Fonctionnaire de catégorie B | T36: Non
A37: 42318.715 | B37: 27 | C37: Bourgogne - Franche-Comté | D37: 71 | E37: Saône-et-Loire | F37: 8 | G37: 3 | H37: DEBOUT LA FRANCE | I37: DEBOUT LA FRANCE AVEC NICOLAS DUPONT-AIGNAN | J37: LDLF | K37: OUI | L37: 1 | M37: M | N37: THIÉBAUT | O37: Maxime | P37: =IFERROR(__xludf.DUMMYFUNCTION("JOIN("" "",N37:O37)"),"THIÉBAUT Maxime") -> THIÉBAUT Maxime | Q37: 33250 | R37: Conseiller juridique | T37: Non
A38: 42318.715 | B38: 27 | C38: Bourgogne - Franche-Comté | D38: 90 | E38: Territoire de Belfort | F38: 9 | G38: 10 | H38: 3 MILLIONS GRUDLER | I38: 3 Millions de raisons avec Christophe GRUDLER | J38: LMDM | K38: OUI | L38: 1 | M38: M | N38: GRUDLER | O38: Christophe | P38: =IFERROR(__xludf.DUMMYFUNCTION("JOIN("" "",N38:O38)"),"GRUDLER Christophe") -> GRUDLER Christophe | Q38: 23841 | R38: Industriel-Chef entreprise | T38: Non
A39: 42318.715 | B39: 27 | C39: Bourgogne - Franche-Comté | D39: 25 | E39: Doubs | F39: 10 | G39: 2 | H39: REGION AVANCE | I39: NOTRE REGION D'AVANCE | J39: LUG | K39: OUI | L39: 1 | M39: F | N39: DUFAY | O39: Marie-Guite | P39: =IFERROR(__xludf.DUMMYFUNCTION("JOIN("" "",N39:O39)"),"DUFAY Marie-Guite") -> DUFAY Marie-Guite | Q39: 18039 | R39: Retraité fonct.publique (sf enseig.) | S39: PCR | T39: Oui
A40: 42318.715 | B40: 53 | C40: Bretagne | D40: 35 | E40: Ille-et-Vilaine | F40: 1 | G40: 8 | H40: BRETAGNE EN LUTTES | I40: BRETAGNE EN LUTTES BREIZH O STOURM | J40: LEXG | K40: OUI | L40: 2 | M40: M | N40: ROBLIN | O40: Gael | P40: =IFERROR(__xludf.DUMMYFUNCTION("JOIN("" "",N40:O40)"),"ROBLIN Gael") -> ROBLIN Gael | Q40: 26660 | R40: Sans profession déclarée | T40: Non
...

Sheet resultats
A1: Libellé de la région | B1: N°Liste | C1: Nuance Liste | D1: Libellé Abrégé Liste | E1: Libellé Etendu Liste | F1: Nom Tête de Liste | G1: Voix
A2: Alsace - Champagne-Ardenne - Lorraine | B2: 1 | C2: LVEC | D2: EUROPE ECOLOGIE LES VERTS | E2: ÉCOLOGISTES, SOLIDAIRES ET CITOYENS | F2: BÉLIER Sandrine | G2: 119091
A3: Alsace - Champagne-Ardenne - Lorraine | B3: 2 | C3: LFG | D3: LFG | E3: Nos vies d'abord ! | F3: PERON Patrick | G3: 57165
A4: Alsace - Champagne-Ardenne - Lorraine | B4: 3 | C4: LDLF | D4: DEBOUT LA FRANCE | E4: DEBOUT LA FRANCE AVEC NICOLAS DUPONT-AIGNAN | F4: JACOBELLI Laurent | G4: 84886
A5: Alsace - Champagne-Ardenne - Lorraine | B5: 4 | C5: LUG | D5: PARTI SOCIALISTE | E5: + FORTE, + PROCHE, NOTRE REGION AVEC JEAN-PIERRE MASSERET | F5: MASSERET Jean-Pierre | G5: 286390
A6: Alsace - Champagne-Ardenne - Lorraine | B6: 5 | C6: LFN | D6: FRONT NATIONAL | E6: LISTE FRONT NATIONAL PRESENTEE PAR MARINE LE PEN | F6: PHILIPPOT Florian | G6: 641234
A7: Alsace - Champagne-Ardenne - Lorraine | B7: 6 | C7: LDIV | D7: UPR | E7: L'UPR, avec FRANÇOIS ASSELINEAU - LE PARTI QUI MONTE malgré le silence des médias | F7: WENTZEL David | G7: 19171
A8: Alsace - Champagne-Ardenne - Lorraine | B8: 7 | C8: LEXG | D8: LUTTE OUVRIERE | E8: Lutte ouvrière - Faire entendre le camp des travailleurs | F8: WOSTYN Julien | G8: 26347
A9: Alsace - Champagne-Ardenne - Lorraine | B9: 8 | C9: LREG | D9: LISTE RÉGIONALISTE | E9: Non à l'ACAL, Oui à nos régions ! | F9: TROUILLET Jean-Georges | G9: 84147
A10: Alsace - Champagne-Ardenne - Lorraine | B10: 9 | C10: LUD | D10: LLR | E10: Unissons nos énergies avec Philippe RICHERT | F10: RICHERT Philippe | G10: 459212
A11: Aquitaine - Limousin - Poitou-Charentes | B11: 1 | C11: LDVG | D11: NOUVELLE DONNE | E11: NOUVELLE DONNE : REPRENEZ LA MAIN ! | F11: PEREIRA Nicolas | G11: 24964
A12: Aquitaine - Limousin - Poitou-Charentes | B12: 2 | C12: LUG | D12: PLUS FORTS, PLUS SOLIDAIR | E12: PLUS FORTS, PLUS SOLIDAIRES, ENSEMBLE | F12: ROUSSET Alain | G12: 628667
A13: Aquitaine - Limousin - Poitou-Charentes | B13: 3 | C13: LUD | D13: GENERATION NOUVELLE REGIO | E13: GENERATION NOUVELLE REGION | F13: CALMELS Virginie | G13: 562500
... A168: Provence-Alpes-Côte d'Azur | B168: 10 | C168: LDVG | D168: NOUVELLE DONNE | E168: POUR UNE NOUVELLE DONNE REGIONALE | F168: JARNY Cyril | G168: 11276

Sheet 1_rapprochement
A1: Libellé de la région | B1: N°Liste | C1: Nuance Liste | D1: Libellé Abrégé Liste | E1: Libellé Etendu Liste | F1: Nom Tête de Liste | G1: sexe | H1: Voix
A2: Alsace - Champagne-Ardenne - Lorraine | B2: 1 | C2: LVEC | D2: EUROPE ECOLOGIE LES VERTS | E2: ÉCOLOGISTES, SOLIDAIRES ET CITOYENS | F2: BÉLIER Sandrine | G2: =IFERROR(__xludf.DUMMYFUNCTION("FILTER(candidats!M:M,candidats!P:P=F2)"),"F") -> F | H2: 119091
A3: Alsace - Champagne-Ardenne - Lorraine | B3: 2 | C3: LFG | D3: LFG | E3: Nos vies d'abord ! | F3: PERON Patrick | G3: =IFERROR(__xludf.DUMMYFUNCTION("FILTER(candidats!M:M,candidats!P:P=F3)"),"M") -> M
A4: Alsace - Champagne-Ardenne - Lorraine | B4: 3 | C4: LDLF | D4: DEBOUT LA FRANCE | E4: DEBOUT LA FRANCE AVEC NICOLAS DUPONT-AIGNAN | F4: JACOBELLI Laurent | G4: =IFERROR(__xludf.DUMMYFUNCTION("FILTER(candidats!M:M,candidats!P:P=F4)"),"M") -> M | H4: 84886
A5: Alsace - Champagne-Ardenne - Lorraine | B5: 4 | C5: LUG | D5: PARTI SOCIALISTE | E5: + FORTE, + PROCHE, NOTRE REGION AVEC JEAN-PIERRE MASSERET | F5: MASSERET Jean-Pierre | G5: =IFERROR(__xludf.DUMMYFUNCTION("FILTER(candidats!M:M,candidats!P:P=F5)"),"M") -> M | H5: 286390
A6: Alsace - Champagne-Ardenne - Lorraine | B6: 5 | C6: LFN | D6: FRONT NATIONAL | E6: LISTE FRONT NATIONAL PRESENTEE PAR MARINE LE PEN | F6: PHILIPPOT Florian | G6: =IFERROR(__xludf.DUMMYFUNCTION("FILTER(candidats!M:M,candidats!P:P=F6)"),"M") -> M | H6: 641234
A7: Alsace - Champagne-Ardenne - Lorraine | B7: 6 | C7: LDIV | D7: UPR | E7: L'UPR, avec FRANÇOIS ASSELINEAU - LE PARTI QUI MONTE malgré le silence des médias | F7: WENTZEL David | G7: =IFERROR(__xludf.DUMMYFUNCTION("FILTER(candidats!M:M,candidats!P:P=F7)"),"M") -> M | H7: 19171
A8: Alsace - Champagne-Ardenne - Lorraine | B8: 7 | C8: LEXG | D8: LUTTE OUVRIERE | E8: Lutte ouvrière - Faire entendre le camp des travailleurs | F8: WOSTYN Julien | G8: =IFERROR(__xludf.DUMMYFUNCTION("FILTER(candidats!M:M,candidats!P:P=F8)"),"M") -> M | H8: 26347
A9: Alsace - Champagne-Ardenne - Lorraine | B9: 8 | C9: LREG | D9: LISTE RÉGIONALISTE | E9: Non à l'ACAL, Oui à nos régions ! | F9: TROUILLET Jean-Georges | G9: =IFERROR(__xludf.DUMMYFUNCTION("FILTER(candidats!M:M,candidats!P:P=F9)"),"M") -> M | H9: 84147
A10: Alsace - Champagne-Ardenne - Lorraine | B10: 9 | C10: LUD | D10: LLR | E10: Unissons nos énergies avec Philippe RICHERT | F10: RICHERT Philippe | G10: =IFERROR(__xludf.DUMMYFUNCTION("FILTER(candidats!M:M,candidats!P:P=F10)"),"M") -> M | H10: 459212
A11: Aquitaine - Limousin - Poitou-Charentes | B11: 1 | C11: LDVG | D11: NOUVELLE DONNE | E11: NOUVELLE DONNE : REPRENEZ LA MAIN ! | F11: PEREIRA Nicolas | G11: =IFERROR(__xludf.DUMMYFUNCTION("FILTER(candidats!M:M,candidats!P:P=F11)"),"M") -> M | H11: 24964
A12: Aquitaine - Limousin - Poitou-Charentes | B12: 2 | C12: LUG | D12: PLUS FORTS, PLUS SOLIDAIR | E12: PLUS FORTS, PLUS SOLIDAIRES, ENSEMBLE | F12: ROUSSET Alain | G12: =IFERROR(__xludf.DUMMYFUNCTION("FILTER(candidats!M:M,candidats!P:P=F12)"),"M") -> M | H12: 628667
A13: Aquitaine - Limousin - Poitou-Charentes | B13: 3 | C13: LUD | D13: GENERATION NOUVELLE REGIO | E13: GENERATION NOUVELLE REGION | F13: CALMELS Virginie | G13: =IFERROR(__xludf.DUMMYFUNCTION("FILTER(candidats!M:M,candidats!P:P=F13)"),"F") -> F | H13: 562500
A14: Aquitaine - Limousin - Poitou-Charentes | B14: 4 | C14: LFG | D14: L'HUMAIN D'ABORD ! | E14: L'HUMAIN D'ABORD ! | F14: DARTIGOLLES Olivier | G14: =IFERROR(__xludf.DUMMYFUNCTION("FILTER(candidats!M:M,candidats!P:P=F14)"),"M") -> M | H14: 100380
A15: Aquitaine - Limousin - Poitou-Charentes | B15: 5 | C15: LDIV | D15: L'UPR | E15: L'UPR AVEC FRANCOIS ASSELINEAU - LE PARTI QUI MONTE MALGRE LE SILENCE DES MEDIAS | F15: DOUET William | G15: =IFERROR(__xludf.DUMMYFUNCTION("FILTER(candidats!M:M,candidats!P:P=F15)"),"M") -> M | H15: 19050
A16: Aquitaine - Limousin - Poitou-Charentes | B16: 6 | C16: LDVG | D16: FAISONS ENSEMBLE | E16: FAISONS ENSEMBLE | F16: BOUSSION Joseph | G16: =IFERROR(__xludf.DUMMYFUNCTION("FILTER(candidats!M:M,candidats!P:P=F16)"),"M") -> M | H16: 38315
A17: Aquitaine - Limousin - Poitou-Charentes | B17: 7 | C17: LVEC | D17: OSONS MIEUX | E17: OSONS MIEUX AVEC FRANÇOISE COUTANT - LISTE ECOLOGISTE ET CITOYENNE | F17: COUTANT Françoise | G17: =IFERROR(__xludf.DUMMYFUNCTION("FILTER(candidats!M:M,candidats!P:P=F17)"),"F") -> F | H17: 115782
A18: Aquitaine - Limousin - Poitou-Charentes | B18: 8 | C18: LFN | D18: LISTE FRONT NATIONAL | E18: LISTE FRONT NATIONAL PRESENTEE PAR MARINE LE PEN | F18: COLOMBIER Jacques | G18: =IFERROR(__xludf.DUMMYFUNCTION("FILTER(candidats!M:M,candidats!P:P=F18)"),"M") -> M | H18: 480621
A19: Aquitaine - Limousin - Poitou-Charentes | B19: 9 | C19: LDLF | D19: DEBOUT LA FRANCE | E19: DEBOUT LA FRANCE AVEC NICOLAS DUPONT AIGNAN | F19: SETZE Yvon | G19: =IFERROR(__xludf.DUMMYFUNCTION("FILTER(candidats!M:M,candidats!P:P=F19)"),"M") -> M | H19: 69276
A20: Aquitaine - Limousin - Poitou-Charentes | B20: 10 | C20: LEXG | D20: LUTTE OUVRIERE | E20: LUTTE OUVRIERE - FAIRE ENTENDRE LE CAMP DES TRAVAILLEURS | F20: PERCHET Guillaume | G20: =IFERROR(__xludf.DUMMYFUNCTION("FILTER(candidats!M:M,candidats!P:P=F20)"),"M") -> M | H20: 29206
A21: Auvergne - Rhône-Alpes | B21: 1 | C21: LDIV | D21: L'UPR, AVEC FRANÇOIS ASSE | E21: L'UPR, avec François ASSELINEAU - LE PARTI QUI MONTE malgré le silence des médias | F21: FÉDÈLE Alain | G21: =IFERROR(__xludf.DUMMYFUNCTION("FILTER(candidats!M:M,candidats!P:P=F21)"),"M") -> M | H21: 21723
A22: Auvergne - Rhône-Alpes | B22: 2 | C22: LDVD | D22: 100% CITOYEN | E22: 100% CITOYEN | F22: LAFOND Eric | G22: =IFERROR(__xludf.DUMMYFUNCTION("FILTER(candidats!M:M,candidats!P:P=F22)"),"M") -> M | H22: 39187
A23: Auvergne - Rhône-Alpes | B23: 3 | C23: LFN | D23: LISTE FRONT NATIONAL PRÉS | E23: Liste Front National présentée par Marine LE PEN | F23: BOUDOT Christophe | G23: =IFERROR(__xludf.DUMMYFUNCTION("FILTER(candidats!M:M,candidats!P:P=F23)"),"M") -> M | H23: 639923
A24: Auvergne - Rhône-Alpes | B24: 4 | C24: LCOM | D24: L'HUMAIN D'ABORD, AVEC LA | E24: L'Humain d'abord, avec la gauche républicaine et sociale | F24: CUKIERMAN Cécile | G24: =IFERROR(__xludf.DUMMYFUNCTION("FILTER(candidats!M:M,candidats!P:P=F24)"),"F") -> F | H24: 135274
A25: Auvergne - Rhône-Alpes | B25: 5 | C25: LEXG | D25: LUTTE OUVRIERE - FAIRE EN | E25: Lutte ouvrière - Faire entendre le camp des travailleurs | F25: GOMEZ Chantal | G25: =IFERROR(__xludf.DUMMYFUNCTION("FILTER(candidats!M:M,candidats!P:P=F25)"),"F") -> F | H25: 31359
A26: Auvergne - Rhône-Alpes | B26: 6 | C26: LUD | D26: WAUQUIEZ 2015, UN NOUVEAU | E26: WAUQUIEZ 2015, un nouveau souffle pour notre région LE GRAND RASSEMBLEMENT de la DROITE et du CENTRE | F26: WAUQUIEZ Laurent | G26: =IFERROR(__xludf.DUMMYFUNCTION("FILTER(candidats!M:M,candidats!P:P=F26)"),"M") -> M | H26: 795661
A27: Auvergne - Rhône-Alpes | B27: 8 | C27: LVEG | D27: LE RASSEMBLEMENT CITOYEN, | E27: LE RASSEMBLEMENT CITOYEN, ECOLOGIQUE ET SOLIDAIRE | F27: KOHLHAAS Jean-Charles | G27: =IFERROR(__xludf.DUMMYFUNCTION("FILTER(candidats!M:M,candidats!P:P=F27)"),"M") -> M | H27: 173038
A28: Auvergne - Rhône-Alpes | B28: 9 | C28: LDLF | D28: DEBOUT LA FRANCE AVEC NIC | E28: DEBOUT LA FRANCE AVEC NICOLAS DUPONT-AIGNAN | F28: RAMBAUD Gerbert | G28: =IFERROR(__xludf.DUMMYFUNCTION("FILTER(candidats!M:M,candidats!P:P=F28)"),"M") -> M | H28: 71538
A29: Auvergne - Rhône-Alpes | B29: 10 | C29: LUG | D29: NOUS, C'EST LA RÉGION | E29: NOUS, C'EST LA RÉGION | F29: QUEYRANNE Jean-Jack | G29: =IFERROR(__xludf.DUMMYFUNCTION("FILTER(candidats!M:M,candidats!P:P=F29)"),"M") -> M | H29: 600112
A30: Bourgogne - Franche-Comté | B30: 1 | C30: LFN | D30: FRONT NATIONAL | E30: LISTE FRONT NATIONAL PRÉSENTÉE PAR MARINE LE PEN | F30: MONTEL Sophie | G30: =IFERROR(__xludf.DUMMYFUNCTION("FILTER(candidats!M:M,candidats!P:P=F30)"),"F") -> F | H30: 303143
A31: Bourgogne - Franche-Comté | B31: 2 | C31: LDIV | D31: UPR | E31: L'UPR avec François ASSELINEAU - LE PARTI QUI MONTE malgré le silence des médias | F31: GALLOIS Charles-Henri | G31: =IFERROR(__xludf.DUMMYFUNCTION("FILTER(candidats!M:M,candidats!P:P=F31)"),"M") -> M | H31: 8835
A32: Bourgogne - Franche-Comté | B32: 3 | C32: LUD | D32: REGION GRAND | E32: LA REGION EN GRAND | F32: SAUVADET François | G32: =IFERROR(__xludf.DUMMYFUNCTION("FILTER(candidats!M:M,candidats!P:P=F32)"),"M") -> M | H32: 231069
A33: Bourgogne - Franche-Comté | B33: 4 | C33: LECO | D33: AEI BFC | E33: ALLIANCE ECOLOGISTE INDEPENDANTE DE BOURGOGNE ET FRANCHE-COMTE | F33: GONZALEZ Julien | G33: =IFERROR(__xludf.DUMMYFUNCTION("FILTER(candidats!M:M,candidats!P:P=F33)"),"M") -> M | H33: 20616
A34: Bourgogne - Franche-Comté | B34: 5 | C34: LVEC | D34: ÉCOLOGISTES BFC | E34: LES ÉCOLOGISTES DE BOURGOGNE FRANCHE-COMTÉ | F34: PRUDHOMME Cécile | G34: =IFERROR(__xludf.DUMMYFUNCTION("FILTER(candidats!M:M,candidats!P:P=F34)"),"F") -> F | H34: 37707
A35: Bourgogne - Franche-Comté | B35: 6 | C35: LFG | D35: ALTERNATIVE GAUCHE | E35: L'ALTERNATIVE À GAUCHE | F35: VERMOREL Nathalie | G35: =IFERROR(__xludf.DUMMYFUNCTION("FILTER(candidats!M:M,candidats!P:P=F35)"),"F") -> F | H35: 44471
A36: Bourgogne - Franche-Comté | B36: 7 | C36: LEXG | D36: LUTTE OUVRIERE | E36: LUTTE OUVRIERE - FAIRE ENTENDRE LE CAMP DES TRAVAILLEURS | F36: ROCHER Claire | G36: =IFERROR(__xludf.DUMMYFUNCTION("FILTER(candidats!M:M,candidats!P:P=F36)"),"F") -> F | H36: 14518
A37: Bourgogne - Franche-Comté | B37: 8 | C37: LDLF | D37: DEBOUT LA FRANCE | E37: DEBOUT LA FRANCE AVEC NICOLAS DUPONT-AIGNAN | F37: THIÉBAUT Maxime | G37: =IFERROR(__xludf.DUMMYFUNCTION("FILTER(candidats!M:M,candidats!P:P=F37)"),"M") -> M | H37: 49802
A38: Bourgogne - Franche-Comté | B38: 9 | C38: LMDM | D38: 3 MILLIONS GRUDLER | E38: 3 Millions de raisons avec Christophe GRUDLER | F38: GRUDLER Christophe | G38: =IFERROR(__xludf.DUMMYFUNCTION("FILTER(candidats!M:M,candidats!P:P=F38)"),"M") -> M | H38: 31431
A39: Bourgogne - Franche-Comté | B39: 10 | C39: LUG | D39: REGION AVANCE | E39: NOTRE REGION D'AVANCE | F39: DUFAY Marie-Guite | G39: =IFERROR(__xludf.DUMMYFUNCTION("FILTER(candidats!M:M,candidats!P:P=F39)"),"F") -> F | H39: 221376
A40: Bretagne | B40: 1 | C40: LEXG | D40: BRETAGNE EN LUTTES | E40: BRETAGNE EN LUTTES BREIZH O STOURM | F40: ROBLIN Gael | G40: =IFERROR(__xludf.DUMMYFUNCTION("FILTER(candidats!M:M,candidats!P:P=F40)"),"M") -> M | H40: 7465
...

Sheet 2_analyse

Sheet 3_analyse
C1: sexe_gagnant
C2: =IFERROR(__xludf.DUMMYFUNCTION("filter('1_rapprochement'!G:G,'1_rapprochement'!H:H=B2)"),"M") -> M
C3: =IFERROR(__xludf.DUMMYFUNCTION("filter('1_rapprochement'!G:G,'1_rapprochement'!H:H=B3)"),"M") -> M
C4: =IFERROR(__xludf.DUMMYFUNCTION("filter('1_rapprochement'!G:G,'1_rapprochement'!H:H=B4)"),"M") -> M
C5: =IFERROR(__xludf.DUMMYFUNCTION("filter('1_rapprochement'!G:G,'1_rapprochement'!H:H=B5)"),"F") -> F
C6: =IFERROR(__xludf.DUMMYFUNCTION("filter('1_rapprochement'!G:G,'1_rapprochement'!H:H=B6)"),"M") -> M
C7: =IFERROR(__xludf.DUMMYFUNCTION("filter('1_rapprochement'!G:G,'1_rapprochement'!H:H=B7)"),"M") -> M
C8: =IFERROR(__xludf.DUMMYFUNCTION("filter('1_rapprochement'!G:G,'1_rapprochement'!H:H=B8)"),"M") -> M
C9: =IFERROR(__xludf.DUMMYFUNCTION("filter('1_rapprochement'!G:G,'1_rapprochement'!H:H=B9)"),"M") -> M
C10: =IFERROR(__xludf.DUMMYFUNCTION("filter('1_rapprochement'!G:G,'1_rapprochement'!H:H=B10)"),"M") -> M
C11: =IFERROR(__xludf.DUMMYFUNCTION("filter('1_rapprochement'!G:G,'1_rapprochement'!H:H=B11)"),"F") -> F
C12: =IFERROR(__xludf.DUMMYFUNCTION("filter('1_rapprochement'!G:G,'1_rapprochement'!H:H=B12)"),"M") -> M
C13: =IFERROR(__xludf.DUMMYFUNCTION("filter('1_rapprochement'!G:G,'1_rapprochement'!H:H=B13)"),"M") -> M
C14: =IFERROR(__xludf.DUMMYFUNCTION("filter('1_rapprochement'!G:G,'1_rapprochement'!H:H=B14)"),"M") -> M
C15: =IFERROR(__xludf.DUMMYFUNCTION("filter('1_rapprochement'!G:G,'1_rapprochement'!H:H=B15)"),"F") -> F
C16: =IFERROR(__xludf.DUMMYFUNCTION("filter('1_rapprochement'!G:G,'1_rapprochement'!H:H=B16)"),"M") -> M
C17: =IFERROR(__xludf.DUMMYFUNCTION("filter('1_rapprochement'!G:G,'1_rapprochement'!H:H=B17)"),"M") -> M
C18: =IFERROR(__xludf.DUMMYFUNCTION("filter('1_rapprochement'!G:G,'1_rapprochement'!H:H=B18)"),"F") -> F

Sheet 4_edition
A1: Libellé de la région | B1: nouveau nom | C1: geographie | D1: N°Liste | E1: Nuance Liste | F1: Couleur | G1: Libellé Abrégé Liste | H1: Libellé Etendu Liste | I1: Nom Tête de Liste | J1: sexe | K1: Voix
A2: Alsace - Champagne-Ardenne - Lorraine | B2: =IFERROR(__xludf.DUMMYFUNCTION("FILTER('5_categorisation'!C:C,'5_categorisation'!A:A=A2)"),"Grand Est") -> Grand Est | C2: =IFS(A2='5_categorisation'!$A$2,'5_categorisation'!$B$2,A2='5_categorisation'!$A$3,'5_categorisation'!$B$3,A2='5_categorisation'!$A$4,'5_categorisation'!$B$4,A2='5_categorisation'!$A$5,'5_categorisation'!$B$5,A2='5_categorisation'!$A$6,'5_categorisation'!$B$6,A2='5_categorisation'!$A$7,'5_categorisation'!$B$7,A2='5_categorisation'!$A$8,'5_categorisation'!$B$8,A2='5_categorisation'!$A$9,'5_categorisation'!$B$9,A2='5_categorisation'!$A10,'5_categorisation'!$B$10,A2='5_categorisation'!$A$12,'5_categorisation'!$B$12,A2='5_categorisation'!$A$12,'5_categorisation'!$B$12,A2='5_categorisation'!$A$13,'5_categorisation'!$B$13,A2='5_categorisation'!$A$14,'5_categorisation'!$B$14,A2='5_categorisation'!$A$15,'5_categorisation'!$B$15,A2='5_categorisation'!$A$16,'5_categorisation'!$B$16,A2='5_categorisation'!$A$17,'5_categorisation'!$B$17,A2='5_categorisation'!$A$11,'5_categorisation'!$B$11) -> est | D2: 1 | E2: LVEC | F2: =ifs(E2='5_categorisation'!$D$2,'5_categorisation'!$F$2,E2='5_categorisation'!$D$3,'5_categorisation'!$F$3,E2='5_categorisation'!$D$4,'5_categorisation'!$F$4,E2='5_categorisation'!$D$5,'5_categorisation'!$F$5,E2='5_categorisation'!$D$6,'5_categorisation'!$F$6,E2='5_categorisation'!$D$7,'5_categorisation'!$F$7,E2='5_categorisation'!$D$8,'5_categorisation'!$F$8,E2='5_categorisation'!$D$9,'5_categorisation'!$F$9,E2='5_categorisation'!$D$10,'5_categorisation'!$F$10,E2='5_categorisation'!$D$11,'5_categorisation'!$F$11,E2='5_categorisation'!$D$12,'5_categorisation'!$F$12,E2='5_categorisation'!$D$13,'5_categorisation'!$F$13,E2='5_categorisation'!$D$14,'5_categorisation'!$F$14,E2='5_categorisation'!$D$15,'5_categorisation'!$F$15,E2='5_categorisation'!$D$16,'5_categorisation'!$F$16,E2='5_categorisation'!$D$17,'5_categorisation'!$F$17,E2='5_categorisation'!$D$18,'5_categorisation'!$F$18,E2='5_categorisation'!$D$19,'5_categorisation'!$F$19,E2='5_categorisation'!$D$20,'5_categorisation'!$F$20,E2='5_categorisation'!$D$21,'5_categorisation'!$F$21,E2='5_categorisation'!$D$22,'5_categorisation'!$F$22) -> gauche | G2: EUROPE ECOLOGIE LES VERTS | H2: ÉCOLOGISTES, SOLIDAIRES ET CITOYENS | I2: BÉLIER Sandrine | J2: =IFERROR(__xludf.DUMMYFUNCTION("FILTER(candidats!M:M,candidats!P:P=I2)"),"F") -> F | K2: 119091
A3: Alsace - Champagne-Ardenne - Lorraine | B3: =IFERROR(__xludf.DUMMYFUNCTION("FILTER('5_categorisation'!C:C,'5_categorisation'!A:A=A3)"),"Grand Est") -> Grand Est | C3: =IFS(A3='5_categorisation'!$A$2,'5_categorisation'!$B$2,A3='5_categorisation'!$A$3,'5_categorisation'!$B$3,A3='5_categorisation'!$A$4,'5_categorisation'!$B$4,A3='5_categorisation'!$A$5,'5_categorisation'!$B$5,A3='5_categorisation'!$A$6,'5_categorisation'!$B$6,A3='5_categorisation'!$A$7,'5_categorisation'!$B$7,A3='5_categorisation'!$A$8,'5_categorisation'!$B$8,A3='5_categorisation'!$A$9,'5_categorisation'!$B$9,A3='5_categorisation'!$A11,'5_categorisation'!$B$10,A3='5_categorisation'!$A$12,'5_categorisation'!$B$12,A3='5_categorisation'!$A$12,'5_categorisation'!$B$12,A3='5_categorisation'!$A$13,'5_categorisation'!$B$13,A3='5_categorisation'!$A$14,'5_categorisation'!$B$14,A3='5_categorisation'!$A$15,'5_categorisation'!$B$15,A3='5_categorisation'!$A$16,'5_categorisation'!$B$16,A3='5_categorisation'!$A$17,'5_categorisation'!$B$17,A3='5_categorisation'!$A$11,'5_categorisation'!$B$11) -> est | D3: 2 | E3: LFG | F3: =ifs(E3='5_categorisation'!$D$2,'5_categorisation'!$F$2,E3='5_categorisation'!$D$3,'5_categorisation'!$F$3,E3='5_categorisation'!$D$4,'5_categorisation'!$F$4,E3='5_categorisation'!$D$5,'5_categorisation'!$F$5,E3='5_categorisation'!$D$6,'5_categorisation'!$F$6,E3='5_categorisation'!$D$7,'5_categorisation'!$F$7,E3='5_categorisation'!$D$8,'5_categorisation'!$F$8,E3='5_categorisation'!$D$9,'5_categorisation'!$F$9,E3='5_categorisation'!$D$10,'5_categorisation'!$F$10,E3='5_categorisation'!$D$11,'5_categorisation'!$F$11,E3='5_categorisation'!$D$12,'5_categorisation'!$F$12,E3='5_categorisation'!$D$13,'5_categorisation'!$F$13,E3='5_categorisation'!$D$14,'5_categorisation'!$F$14,E3='5_categorisation'!$D$15,'5_categorisation'!$F$15,E3='5_categorisation'!$D$16,'5_categorisation'!$F$16,E3='5_categorisation'!$D$17,'5_categorisation'!$F$17,E3='5_categorisation'!$D$18,'5_categorisation'!$F$18,E3='5_categorisation'!$D$19,'5_categorisation'!$F$19,E3='5_categorisation'!$D$20,'5_categorisation'!$F$20,E3='5_categorisation'!$D$21,'5_categorisation'!$F$21,E3='5_categorisation'!$D$22,'5_categorisation'!$F$22) -> gauche | G3: LFG | H3: Nos vies d'abord ! | I3: PERON Patrick | J3: =IFERROR(__xludf.DUMMYFUNCTION("FILTER(candidats!M:M,candidats!P:P=I3)"),"M") -> M
A4: Alsace - Champagne-Ardenne - Lorraine | B4: =IFERROR(__xludf.DUMMYFUNCTION("FILTER('5_categorisation'!C:C,'5_categorisation'!A:A=A4)"),"Grand Est") -> Grand Est | C4: =IFS(A4='5_categorisation'!$A$2,'5_categorisation'!$B$2,A4='5_categorisation'!$A$3,'5_categorisation'!$B$3,A4='5_categorisation'!$A$4,'5_categorisation'!$B$4,A4='5_categorisation'!$A$5,'5_categorisation'!$B$5,A4='5_categorisation'!$A$6,'5_categorisation'!$B$6,A4='5_categorisation'!$A$7,'5_categorisation'!$B$7,A4='5_categorisation'!$A$8,'5_categorisation'!$B$8,A4='5_categorisation'!$A$9,'5_categorisation'!$B$9,A4='5_categorisation'!$A12,'5_categorisation'!$B$10,A4='5_categorisation'!$A$12,'5_categorisation'!$B$12,A4='5_categorisation'!$A$12,'5_categorisation'!$B$12,A4='5_categorisation'!$A$13,'5_categorisation'!$B$13,A4='5_categorisation'!$A$14,'5_categorisation'!$B$14,A4='5_categorisation'!$A$15,'5_categorisation'!$B$15,A4='5_categorisation'!$A$16,'5_categorisation'!$B$16,A4='5_categorisation'!$A$17,'5_categorisation'!$B$17,A4='5_categorisation'!$A$11,'5_categorisation'!$B$11) -> est | D4: 3 | E4: LDLF | F4: =ifs(E4='5_categorisation'!$D$2,'5_categorisation'!$F$2,E4='5_categorisation'!$D$3,'5_categorisation'!$F$3,E4='5_categorisation'!$D$4,'5_categorisation'!$F$4,E4='5_categorisation'!$D$5,'5_categorisation'!$F$5,E4='5_categorisation'!$D$6,'5_categorisation'!$F$6,E4='5_categorisation'!$D$7,'5_categorisation'!$F$7,E4='5_categorisation'!$D$8,'5_categorisation'!$F$8,E4='5_categorisation'!$D$9,'5_categorisation'!$F$9,E4='5_categorisation'!$D$10,'5_categorisation'!$F$10,E4='5_categorisation'!$D$11,'5_categorisation'!$F$11,E4='5_categorisation'!$D$12,'5_categorisation'!$F$12,E4='5_categorisation'!$D$13,'5_categorisation'!$F$13,E4='5_categorisation'!$D$14,'5_categorisation'!$F$14,E4='5_categorisation'!$D$15,'5_categorisation'!$F$15,E4='5_categorisation'!$D$16,'5_categorisation'!$F$16,E4='5_categorisation'!$D$17,'5_categorisation'!$F$17,E4='5_categorisation'!$D$18,'5_categorisation'!$F$18,E4='5_categorisation'!$D$19,'5_categorisation'!$F$19,E4='5_categorisation'!$D$20,'5_categorisation'!$F$20,E4='5_categorisation'!$D$21,'5_categorisation'!$F$21,E4='5_categorisation'!$D$22,'5_categorisation'!$F$22) -> droite | G4: DEBOUT LA FRANCE | H4: DEBOUT LA FRANCE AVEC NICOLAS DUPONT-AIGNAN | I4: JACOBELLI Laurent | J4: =IFERROR(__xludf.DUMMYFUNCTION("FILTER(candidats!M:M,candidats!P:P=I4)"),"M") -> M | K4: 84886
A5: Alsace - Champagne-Ardenne - Lorraine | B5: =IFERROR(__xludf.DUMMYFUNCTION("FILTER('5_categorisation'!C:C,'5_categorisation'!A:A=A5)"),"Grand Est") -> Grand Est | C5: =IFS(A5='5_categorisation'!$A$2,'5_categorisation'!$B$2,A5='5_categorisation'!$A$3,'5_categorisation'!$B$3,A5='5_categorisation'!$A$4,'5_categorisation'!$B$4,A5='5_categorisation'!$A$5,'5_categorisation'!$B$5,A5='5_categorisation'!$A$6,'5_categorisation'!$B$6,A5='5_categorisation'!$A$7,'5_categorisation'!$B$7,A5='5_categorisation'!$A$8,'5_categorisation'!$B$8,A5='5_categorisation'!$A$9,'5_categorisation'!$B$9,A5='5_categorisation'!$A13,'5_categorisation'!$B$10,A5='5_categorisation'!$A$12,'5_categorisation'!$B$12,A5='5_categorisation'!$A$12,'5_categorisation'!$B$12,A5='5_categorisation'!$A$13,'5_categorisation'!$B$13,A5='5_categorisation'!$A$14,'5_categorisation'!$B$14,A5='5_categorisation'!$A$15,'5_categorisation'!$B$15,A5='5_categorisation'!$A$16,'5_categorisation'!$B$16,A5='5_categorisation'!$A$17,'5_categorisation'!$B$17,A5='5_categorisation'!$A$11,'5_categorisation'!$B$11) -> est | D5: 4 | E5: LUG | F5: =ifs(E5='5_categorisation'!$D$2,'5_categorisation'!$F$2,E5='5_categorisation'!$D$3,'5_categorisation'!$F$3,E5='5_categorisation'!$D$4,'5_categorisation'!$F$4,E5='5_categorisation'!$D$5,'5_categorisation'!$F$5,E5='5_categorisation'!$D$6,'5_categorisation'!$F$6,E5='5_categorisation'!$D$7,'5_categorisation'!$F$7,E5='5_categorisation'!$D$8,'5_categorisation'!$F$8,E5='5_categorisation'!$D$9,'5_categorisation'!$F$9,E5='5_categorisation'!$D$10,'5_categorisation'!$F$10,E5='5_categorisation'!$D$11,'5_categorisation'!$F$11,E5='5_categorisation'!$D$12,'5_categorisation'!$F$12,E5='5_categorisation'!$D$13,'5_categorisation'!$F$13,E5='5_categorisation'!$D$14,'5_categorisation'!$F$14,E5='5_categorisation'!$D$15,'5_categorisation'!$F$15,E5='5_categorisation'!$D$16,'5_categorisation'!$F$16,E5='5_categorisation'!$D$17,'5_categorisation'!$F$17,E5='5_categorisation'!$D$18,'5_categorisation'!$F$18,E5='5_categorisation'!$D$19,'5_categorisation'!$F$19,E5='5_categorisation'!$D$20,'5_categorisation'!$F$20,E5='5_categorisation'!$D$21,'5_categorisation'!$F$21,E5='5_categorisation'!$D$22,'5_categorisation'!$F$22) -> gauche | G5: PARTI SOCIALISTE | H5: + FORTE, + PROCHE, NOTRE REGION AVEC JEAN-PIERRE MASSERET | I5: MASSERET Jean-Pierre | J5: =IFERROR(__xludf.DUMMYFUNCTION("FILTER(candidats!M:M,candidats!P:P=I5)"),"M") -> M | K5: 286390
A6: Alsace - Champagne-Ardenne - Lorraine | B6: =IFERROR(__xludf.DUMMYFUNCTION("FILTER('5_categorisation'!C:C,'5_categorisation'!A:A=A6)"),"Grand Est") -> Grand Est | C6: =IFS(A6='5_categorisation'!$A$2,'5_categorisation'!$B$2,A6='5_categorisation'!$A$3,'5_categorisation'!$B$3,A6='5_categorisation'!$A$4,'5_categorisation'!$B$4,A6='5_categorisation'!$A$5,'5_categorisation'!$B$5,A6='5_categorisation'!$A$6,'5_categorisation'!$B$6,A6='5_categorisation'!$A$7,'5_categorisation'!$B$7,A6='5_categorisation'!$A$8,'5_categorisation'!$B$8,A6='5_categorisation'!$A$9,'5_categorisation'!$B$9,A6='5_categorisation'!$A14,'5_categorisation'!$B$10,A6='5_categorisation'!$A$12,'5_categorisation'!$B$12,A6='5_categorisation'!$A$12,'5_categorisation'!$B$12,A6='5_categorisation'!$A$13,'5_categorisation'!$B$13,A6='5_categorisation'!$A$14,'5_categorisation'!$B$14,A6='5_categorisation'!$A$15,'5_categorisation'!$B$15,A6='5_categorisation'!$A$16,'5_categorisation'!$B$16,A6='5_categorisation'!$A$17,'5_categorisation'!$B$17,A6='5_categorisation'!$A$11,'5_categorisation'!$B$11) -> est | D6: 5 | E6: LFN | F6: =ifs(E6='5_categorisation'!$D$2,'5_categorisation'!$F$2,E6='5_categorisation'!$D$3,'5_categorisation'!$F$3,E6='5_categorisation'!$D$4,'5_categorisation'!$F$4,E6='5_categorisation'!$D$5,'5_categorisation'!$F$5,E6='5_categorisation'!$D$6,'5_categorisation'!$F$6,E6='5_categorisation'!$D$7,'5_categorisation'!$F$7,E6='5_categorisation'!$D$8,'5_categorisation'!$F$8,E6='5_categorisation'!$D$9,'5_categorisation'!$F$9,E6='5_categorisation'!$D$10,'5_categorisation'!$F$10,E6='5_categorisation'!$D$11,'5_categorisation'!$F$11,E6='5_categorisation'!$D$12,'5_categorisation'!$F$12,E6='5_categorisation'!$D$13,'5_categorisation'!$F$13,E6='5_categorisation'!$D$14,'5_categorisation'!$F$14,E6='5_categorisation'!$D$15,'5_categorisation'!$F$15,E6='5_categorisation'!$D$16,'5_categorisation'!$F$16,E6='5_categorisation'!$D$17,'5_categorisation'!$F$17,E6='5_categorisation'!$D$18,'5_categorisation'!$F$18,E6='5_categorisation'!$D$19,'5_categorisation'!$F$19,E6='5_categorisation'!$D$20,'5_categorisation'!$F$20,E6='5_categorisation'!$D$21,'5_categorisation'!$F$21,E6='5_categorisation'!$D$22,'5_categorisation'!$F$22) -> droite | G6: FRONT NATIONAL | H6: LISTE FRONT NATIONAL PRESENTEE PAR MARINE LE PEN | I6: PHILIPPOT Florian | J6: =IFERROR(__xludf.DUMMYFUNCTION("FILTER(candidats!M:M,candidats!P:P=I6)"),"M") -> M | K6: 641234
A7: Alsace - Champagne-Ardenne - Lorraine | B7: =IFERROR(__xludf.DUMMYFUNCTION("FILTER('5_categorisation'!C:C,'5_categorisation'!A:A=A7)"),"Grand Est") -> Grand Est | C7: =IFS(A7='5_categorisation'!$A$2,'5_categorisation'!$B$2,A7='5_categorisation'!$A$3,'5_categorisation'!$B$3,A7='5_categorisation'!$A$4,'5_categorisation'!$B$4,A7='5_categorisation'!$A$5,'5_categorisation'!$B$5,A7='5_categorisation'!$A$6,'5_categorisation'!$B$6,A7='5_categorisation'!$A$7,'5_categorisation'!$B$7,A7='5_categorisation'!$A$8,'5_categorisation'!$B$8,A7='5_categorisation'!$A$9,'5_categorisation'!$B$9,A7='5_categorisation'!$A15,'5_categorisation'!$B$10,A7='5_categorisation'!$A$12,'5_categorisation'!$B$12,A7='5_categorisation'!$A$12,'5_categorisation'!$B$12,A7='5_categorisation'!$A$13,'5_categorisation'!$B$13,A7='5_categorisation'!$A$14,'5_categorisation'!$B$14,A7='5_categorisation'!$A$15,'5_categorisation'!$B$15,A7='5_categorisation'!$A$16,'5_categorisation'!$B$16,A7='5_categorisation'!$A$17,'5_categorisation'!$B$17,A7='5_categorisation'!$A$11,'5_categorisation'!$B$11) -> est | D7: 6 | E7: LDIV | F7: =ifs(E7='5_categorisation'!$D$2,'5_categorisation'!$F$2,E7='5_categorisation'!$D$3,'5_categorisation'!$F$3,E7='5_categorisation'!$D$4,'5_categorisation'!$F$4,E7='5_categorisation'!$D$5,'5_categorisation'!$F$5,E7='5_categorisation'!$D$6,'5_categorisation'!$F$6,E7='5_categorisation'!$D$7,'5_categorisation'!$F$7,E7='5_categorisation'!$D$8,'5_categorisation'!$F$8,E7='5_categorisation'!$D$9,'5_categorisation'!$F$9,E7='5_categorisation'!$D$10,'5_categorisation'!$F$10,E7='5_categorisation'!$D$11,'5_categorisation'!$F$11,E7='5_categorisation'!$D$12,'5_categorisation'!$F$12,E7='5_categorisation'!$D$13,'5_categorisation'!$F$13,E7='5_categorisation'!$D$14,'5_categorisation'!$F$14,E7='5_categorisation'!$D$15,'5_categorisation'!$F$15,E7='5_categorisation'!$D$16,'5_categorisation'!$F$16,E7='5_categorisation'!$D$17,'5_categorisation'!$F$17,E7='5_categorisation'!$D$18,'5_categorisation'!$F$18,E7='5_categorisation'!$D$19,'5_categorisation'!$F$19,E7='5_categorisation'!$D$20,'5_categorisation'!$F$20,E7='5_categorisation'!$D$21,'5_categorisation'!$F$21,E7='5_categorisation'!$D$22,'5_categorisation'!$F$22) -> autre | G7: UPR | H7: L'UPR, avec FRANÇOIS ASSELINEAU - LE PARTI QUI MONTE malgré le silence des médias | I7: WENTZEL David | J7: =IFERROR(__xludf.DUMMYFUNCTION("FILTER(candidats!M:M,candidats!P:P=I7)"),"M") -> M | K7: 19171
A8: Alsace - Champagne-Ardenne - Lorraine | B8: =IFERROR(__xludf.DUMMYFUNCTION("FILTER('5_categorisation'!C:C,'5_categorisation'!A:A=A8)"),"Grand Est") -> Grand Est | C8: =IFS(A8='5_categorisation'!$A$2,'5_categorisation'!$B$2,A8='5_categorisation'!$A$3,'5_categorisation'!$B$3,A8='5_categorisation'!$A$4,'5_categorisation'!$B$4,A8='5_categorisation'!$A$5,'5_categorisation'!$B$5,A8='5_categorisation'!$A$6,'5_categorisation'!$B$6,A8='5_categorisation'!$A$7,'5_categorisation'!$B$7,A8='5_categorisation'!$A$8,'5_categorisation'!$B$8,A8='5_categorisation'!$A$9,'5_categorisation'!$B$9,A8='5_categorisation'!$A16,'5_categorisation'!$B$10,A8='5_categorisation'!$A$12,'5_categorisation'!$B$12,A8='5_categorisation'!$A$12,'5_categorisation'!$B$12,A8='5_categorisation'!$A$13,'5_categorisation'!$B$13,A8='5_categorisation'!$A$14,'5_categorisation'!$B$14,A8='5_categorisation'!$A$15,'5_categorisation'!$B$15,A8='5_categorisation'!$A$16,'5_categorisation'!$B$16,A8='5_categorisation'!$A$17,'5_categorisation'!$B$17,A8='5_categorisation'!$A$11,'5_categorisation'!$B$11) -> est | D8: 7 | E8: LEXG | F8: =ifs(E8='5_categorisation'!$D$2,'5_categorisation'!$F$2,E8='5_categorisation'!$D$3,'5_categorisation'!$F$3,E8='5_categorisation'!$D$4,'5_categorisation'!$F$4,E8='5_categorisation'!$D$5,'5_categorisation'!$F$5,E8='5_categorisation'!$D$6,'5_categorisation'!$F$6,E8='5_categorisation'!$D$7,'5_categorisation'!$F$7,E8='5_categorisation'!$D$8,'5_categorisation'!$F$8,E8='5_categorisation'!$D$9,'5_categorisation'!$F$9,E8='5_categorisation'!$D$10,'5_categorisation'!$F$10,E8='5_categorisation'!$D$11,'5_categorisation'!$F$11,E8='5_categorisation'!$D$12,'5_categorisation'!$F$12,E8='5_categorisation'!$D$13,'5_categorisation'!$F$13,E8='5_categorisation'!$D$14,'5_categorisation'!$F$14,E8='5_categorisation'!$D$15,'5_categorisation'!$F$15,E8='5_categorisation'!$D$16,'5_categorisation'!$F$16,E8='5_categorisation'!$D$17,'5_categorisation'!$F$17,E8='5_categorisation'!$D$18,'5_categorisation'!$F$18,E8='5_categorisation'!$D$19,'5_categorisation'!$F$19,E8='5_categorisation'!$D$20,'5_categorisation'!$F$20,E8='5_categorisation'!$D$21,'5_categorisation'!$F$21,E8='5_categorisation'!$D$22,'5_categorisation'!$F$22) -> gauche | G8: LUTTE OUVRIERE | H8: Lutte ouvrière - Faire entendre le camp des travailleurs | I8: WOSTYN Julien | J8: =IFERROR(__xludf.DUMMYFUNCTION("FILTER(candidats!M:M,candidats!P:P=I8)"),"M") -> M | K8: 26347
A9: Alsace - Champagne-Ardenne - Lorraine | B9: =IFERROR(__xludf.DUMMYFUNCTION("FILTER('5_categorisation'!C:C,'5_categorisation'!A:A=A9)"),"Grand Est") -> Grand Est | C9: =IFS(A9='5_categorisation'!$A$2,'5_categorisation'!$B$2,A9='5_categorisation'!$A$3,'5_categorisation'!$B$3,A9='5_categorisation'!$A$4,'5_categorisation'!$B$4,A9='5_categorisation'!$A$5,'5_categorisation'!$B$5,A9='5_categorisation'!$A$6,'5_categorisation'!$B$6,A9='5_categorisation'!$A$7,'5_categorisation'!$B$7,A9='5_categorisation'!$A$8,'5_categorisation'!$B$8,A9='5_categorisation'!$A$9,'5_categorisation'!$B$9,A9='5_categorisation'!$A17,'5_categorisation'!$B$10,A9='5_categorisation'!$A$12,'5_categorisation'!$B$12,A9='5_categorisation'!$A$12,'5_categorisation'!$B$12,A9='5_categorisation'!$A$13,'5_categorisation'!$B$13,A9='5_categorisation'!$A$14,'5_categorisation'!$B$14,A9='5_categorisation'!$A$15,'5_categorisation'!$B$15,A9='5_categorisation'!$A$16,'5_categorisation'!$B$16,A9='5_categorisation'!$A$17,'5_categorisation'!$B$17,A9='5_categorisation'!$A$11,'5_categorisation'!$B$11) -> est | D9: 8 | E9: LREG | F9: =ifs(E9='5_categorisation'!$D$2,'5_categorisation'!$F$2,E9='5_categorisation'!$D$3,'5_categorisation'!$F$3,E9='5_categorisation'!$D$4,'5_categorisation'!$F$4,E9='5_categorisation'!$D$5,'5_categorisation'!$F$5,E9='5_categorisation'!$D$6,'5_categorisation'!$F$6,E9='5_categorisation'!$D$7,'5_categorisation'!$F$7,E9='5_categorisation'!$D$8,'5_categorisation'!$F$8,E9='5_categorisation'!$D$9,'5_categorisation'!$F$9,E9='5_categorisation'!$D$10,'5_categorisation'!$F$10,E9='5_categorisation'!$D$11,'5_categorisation'!$F$11,E9='5_categorisation'!$D$12,'5_categorisation'!$F$12,E9='5_categorisation'!$D$13,'5_categorisation'!$F$13,E9='5_categorisation'!$D$14,'5_categorisation'!$F$14,E9='5_categorisation'!$D$15,'5_categorisation'!$F$15,E9='5_categorisation'!$D$16,'5_categorisation'!$F$16,E9='5_categorisation'!$D$17,'5_categorisation'!$F$17,E9='5_categorisation'!$D$18,'5_categorisation'!$F$18,E9='5_categorisation'!$D$19,'5_categorisation'!$F$19,E9='5_categorisation'!$D$20,'5_categorisation'!$F$20,E9='5_categorisation'!$D$21,'5_categorisation'!$F$21,E9='5_categorisation'!$D$22,'5_categorisation'!$F$22) -> autre | G9: LISTE RÉGIONALISTE | H9: Non à l'ACAL, Oui à nos régions ! | I9: TROUILLET Jean-Georges | J9: =IFERROR(__xludf.DUMMYFUNCTION("FILTER(candidats!M:M,candidats!P:P=I9)"),"M") -> M | K9: 84147
A10: Alsace - Champagne-Ardenne - Lorraine | B10: =IFERROR(__xludf.DUMMYFUNCTION("FILTER('5_categorisation'!C:C,'5_categorisation'!A:A=A10)"),"Grand Est") -> Grand Est | C10: =IFS(A10='5_categorisation'!$A$2,'5_categorisation'!$B$2,A10='5_categorisation'!$A$3,'5_categorisation'!$B$3,A10='5_categorisation'!$A$4,'5_categorisation'!$B$4,A10='5_categorisation'!$A$5,'5_categorisation'!$B$5,A10='5_categorisation'!$A$6,'5_categorisation'!$B$6,A10='5_categorisation'!$A$7,'5_categorisation'!$B$7,A10='5_categorisation'!$A$8,'5_categorisation'!$B$8,A10='5_categorisation'!$A$9,'5_categorisation'!$B$9,A10='5_categorisation'!$A18,'5_categorisation'!$B$10,A10='5_categorisation'!$A$12,'5_categorisation'!$B$12,A10='5_categorisation'!$A$12,'5_categorisation'!$B$12,A10='5_categorisation'!$A$13,'5_categorisation'!$B$13,A10='5_categorisation'!$A$14,'5_categorisation'!$B$14,A10='5_categorisation'!$A$15,'5_categorisation'!$B$15,A10='5_categorisation'!$A$16,'5_categorisation'!$B$16,A10='5_categorisation'!$A$17,'5_categorisation'!$B$17,A10='5_categorisation'!$A$11,'5_categorisation'!$B$11) -> est | D10: 9 | E10: LUD | F10: =ifs(E10='5_categorisation'!$D$2,'5_categorisation'!$F$2,E10='5_categorisation'!$D$3,'5_categorisation'!$F$3,E10='5_categorisation'!$D$4,'5_categorisation'!$F$4,E10='5_categorisation'!$D$5,'5_categorisation'!$F$5,E10='5_categorisation'!$D$6,'5_categorisation'!$F$6,E10='5_categorisation'!$D$7,'5_categorisation'!$F$7,E10='5_categorisation'!$D$8,'5_categorisation'!$F$8,E10='5_categorisation'!$D$9,'5_categorisation'!$F$9,E10='5_categorisation'!$D$10,'5_categorisation'!$F$10,E10='5_categorisation'!$D$11,'5_categorisation'!$F$11,E10='5_categorisation'!$D$12,'5_categorisation'!$F$12,E10='5_categorisation'!$D$13,'5_categorisation'!$F$13,E10='5_categorisation'!$D$14,'5_categorisation'!$F$14,E10='5_categorisation'!$D$15,'5_categorisation'!$F$15,E10='5_categorisation'!$D$16,'5_categorisation'!$F$16,E10='5_categorisation'!$D$17,'5_categorisation'!$F$17,E10='5_categorisation'!$D$18,'5_categorisation'!$F$18,E10='5_categorisation'!$D$19,'5_categorisation'!$F$19,E10='5_categorisation'!$D$20,'5_categorisation'!$F$20,E10='5_categorisation'!$D$21,'5_categorisation'!$F$21,E10='5_categorisation'!$D$22,'5_categorisation'!$F$22) -> droite | G10: LLR | H10: Unissons nos énergies avec Philippe RICHERT | I10: RICHERT Philippe | J10: =IFERROR(__xludf.DUMMYFUNCTION("FILTER(candidats!M:M,candidats!P:P=I10)"),"M") -> M | K10: 459212
A11: Aquitaine - Limousin - Poitou-Charentes | B11: =IFERROR(__xludf.DUMMYFUNCTION("FILTER('5_categorisation'!C:C,'5_categorisation'!A:A=A11)"),"Nouvelle-Aquitaine") -> Nouvelle-Aquitaine | C11: =IFS(A11='5_categorisation'!$A$2,'5_categorisation'!$B$2,A11='5_categorisation'!$A$3,'5_categorisation'!$B$3,A11='5_categorisation'!$A$4,'5_categorisation'!$B$4,A11='5_categorisation'!$A$5,'5_categorisation'!$B$5,A11='5_categorisation'!$A$6,'5_categorisation'!$B$6,A11='5_categorisation'!$A$7,'5_categorisation'!$B$7,A11='5_categorisation'!$A$8,'5_categorisation'!$B$8,A11='5_categorisation'!$A$9,'5_categorisation'!$B$9,A11='5_categorisation'!$A19,'5_categorisation'!$B$10,A11='5_categorisation'!$A$12,'5_categorisation'!$B$12,A11='5_categorisation'!$A$12,'5_categorisation'!$B$12,A11='5_categorisation'!$A$13,'5_categorisation'!$B$13,A11='5_categorisation'!$A$14,'5_categorisation'!$B$14,A11='5_categorisation'!$A$15,'5_categorisation'!$B$15,A11='5_categorisation'!$A$16,'5_categorisation'!$B$16,A11='5_categorisation'!$A$17,'5_categorisation'!$B$17,A11='5_categorisation'!$A$11,'5_categorisation'!$B$11) -> ouest | D11: 1 | E11: LDVG | F11: =ifs(E11='5_categorisation'!$D$2,'5_categorisation'!$F$2,E11='5_categorisation'!$D$3,'5_categorisation'!$F$3,E11='5_categorisation'!$D$4,'5_categorisation'!$F$4,E11='5_categorisation'!$D$5,'5_categorisation'!$F$5,E11='5_categorisation'!$D$6,'5_categorisation'!$F$6,E11='5_categorisation'!$D$7,'5_categorisation'!$F$7,E11='5_categorisation'!$D$8,'5_categorisation'!$F$8,E11='5_categorisation'!$D$9,'5_categorisation'!$F$9,E11='5_categorisation'!$D$10,'5_categorisation'!$F$10,E11='5_categorisation'!$D$11,'5_categorisation'!$F$11,E11='5_categorisation'!$D$12,'5_categorisation'!$F$12,E11='5_categorisation'!$D$13,'5_categorisation'!$F$13,E11='5_categorisation'!$D$14,'5_categorisation'!$F$14,E11='5_categorisation'!$D$15,'5_categorisation'!$F$15,E11='5_categorisation'!$D$16,'5_categorisation'!$F$16,E11='5_categorisation'!$D$17,'5_categorisation'!$F$17,E11='5_categorisation'!$D$18,'5_categorisation'!$F$18,E11='5_categorisation'!$D$19,'5_categorisation'!$F$19,E11='5_categorisation'!$D$20,'5_categorisation'!$F$20,E11='5_categorisation'!$D$21,'5_categorisation'!$F$21,E11='5_categorisation'!$D$22,'5_categorisation'!$F$22) -> gauche | G11: NOUVELLE DONNE | H11: NOUVELLE DONNE : REPRENEZ LA MAIN ! | I11: PEREIRA Nicolas | J11: =IFERROR(__xludf.DUMMYFUNCTION("FILTER(candidats!M:M,candidats!P:P=I11)"),"M") -> M | K11: 24964
A12: Aquitaine - Limousin - Poitou-Charentes | B12: =IFERROR(__xludf.DUMMYFUNCTION("FILTER('5_categorisation'!C:C,'5_categorisation'!A:A=A12)"),"Nouvelle-Aquitaine") -> Nouvelle-Aquitaine | C12: =IFS(A12='5_categorisation'!$A$2,'5_categorisation'!$B$2,A12='5_categorisation'!$A$3,'5_categorisation'!$B$3,A12='5_categorisation'!$A$4,'5_categorisation'!$B$4,A12='5_categorisation'!$A$5,'5_categorisation'!$B$5,A12='5_categorisation'!$A$6,'5_categorisation'!$B$6,A12='5_categorisation'!$A$7,'5_categorisation'!$B$7,A12='5_categorisation'!$A$8,'5_categorisation'!$B$8,A12='5_categorisation'!$A$9,'5_categorisation'!$B$9,A12='5_categorisation'!$A20,'5_categorisation'!$B$10,A12='5_categorisation'!$A$12,'5_categorisation'!$B$12,A12='5_categorisation'!$A$12,'5_categorisation'!$B$12,A12='5_categorisation'!$A$13,'5_categorisation'!$B$13,A12='5_categorisation'!$A$14,'5_categorisation'!$B$14,A12='5_categorisation'!$A$15,'5_categorisation'!$B$15,A12='5_categorisation'!$A$16,'5_categorisation'!$B$16,A12='5_categorisation'!$A$17,'5_categorisation'!$B$17,A12='5_categorisation'!$A$11,'5_categorisation'!$B$11) -> ouest | D12: 2 | E12: LUG | F12: =ifs(E12='5_categorisation'!$D$2,'5_categorisation'!$F$2,E12='5_categorisation'!$D$3,'5_categorisation'!$F$3,E12='5_categorisation'!$D$4,'5_categorisation'!$F$4,E12='5_categorisation'!$D$5,'5_categorisation'!$F$5,E12='5_categorisation'!$D$6,'5_categorisation'!$F$6,E12='5_categorisation'!$D$7,'5_categorisation'!$F$7,E12='5_categorisation'!$D$8,'5_categorisation'!$F$8,E12='5_categorisation'!$D$9,'5_categorisation'!$F$9,E12='5_categorisation'!$D$10,'5_categorisation'!$F$10,E12='5_categorisation'!$D$11,'5_categorisation'!$F$11,E12='5_categorisation'!$D$12,'5_categorisation'!$F$12,E12='5_categorisation'!$D$13,'5_categorisation'!$F$13,E12='5_categorisation'!$D$14,'5_categorisation'!$F$14,E12='5_categorisation'!$D$15,'5_categorisation'!$F$15,E12='5_categorisation'!$D$16,'5_categorisation'!$F$16,E12='5_categorisation'!$D$17,'5_categorisation'!$F$17,E12='5_categorisation'!$D$18,'5_categorisation'!$F$18,E12='5_categorisation'!$D$19,'5_categorisation'!$F$19,E12='5_categorisation'!$D$20,'5_categorisation'!$F$20,E12='5_categorisation'!$D$21,'5_categorisation'!$F$21,E12='5_categorisation'!$D$22,'5_categorisation'!$F$22) -> gauche | G12: PLUS FORTS, PLUS SOLIDAIR | H12: PLUS FORTS, PLUS SOLIDAIRES, ENSEMBLE | I12: ROUSSET Alain | J12: =IFERROR(__xludf.DUMMYFUNCTION("FILTER(candidats!M:M,candidats!P:P=I12)"),"M") -> M | K12: 628667
