Workbook

Sheet openrefine_asso2016-2017
A1: Année | B1: nom des bénéficiaires | C1: Montant du fonds de concours ou de la subvention (numéraire) | D1: Prestations en nature
A2: 2016 | B2: OPERA NATIONAL DE BORDEAUX | C2: 16167670 | E2: =MATCH(B2,'Copy of webscraper_bordeauxasso'!B:B,0) -> #N/A
A3: 2016 | B3: ASSOCIATION DES CENTRES D'ANIMATION DE QUARTIERS DE BORDEAUX - ACAQB | C3: 8060927.5 | D3: Communication, locaux, équipements sportifs, | E3: =MATCH(B3,'Copy of webscraper_bordeauxasso'!B:B,0) -> #N/A
A4: 2016 | B4: CCAS DE BORDEAUX | C4: 7912204 | E4: =MATCH(B4,'Copy of webscraper_bordeauxasso'!B:B,0) -> #N/A
A5: 2016 | B5: ECOLE D'ENSEIGNEMENT SUPERIEUR D'ART DE BORDEAUX - ESAB | C5: 3120000 | E5: =MATCH(B5,'Copy of webscraper_bordeauxasso'!B:B,0) -> #N/A
A6: 2016 | B6: ASSOCIATION PITCHOUN | C6: 1735000 | D6: Locaux | E6: =MATCH(B6,'Copy of webscraper_bordeauxasso'!B:B,0) -> #N/A
A7: 2016 | B7: THEATRE NATIONAL DE BORDEAUX EN AQUITAINE - TNBA | C7: 1646816 | D7: Communication, locaux | E7: =MATCH(B7,'Copy of webscraper_bordeauxasso'!B:B,0) -> #N/A
A8: 2016 | B8: ASSOCIATION PETITE ENFANCE ENFANCE ET FAMILLE - APEEF | C8: 1578403 | D8: Locaux, matériel pour manifestations | E8: =MATCH(B8,'Copy of webscraper_bordeauxasso'!B:B,0) -> #N/A
A9: 2016 | B9: UNION SAINT-BRUNO | C9: 1537650 | D9: Locaux, équipements sportifs, matériel pour | E9: =MATCH(B9,'Copy of webscraper_bordeauxasso'!B:B,0) -> #N/A
A10: 2016 | B10: SPORTING CHANTECLER BORDEAUX NORD LE LAC | C10: 1128560 | D10: Locaux, équipements sportifs, matériel pour | E10: =MATCH(B10,'Copy of webscraper_bordeauxasso'!B:B,0) -> #N/A
A11: 2016 | B11: AVANT GARDE ET JEANNE D'ARC DE BORDEAUX CAUDERAN - AGJA BORDEAUX CAUDERAN | C11: 1089439 | D11: Locaux, équipements sportifs, matériel pour | E11: =MATCH(B11,'Copy of webscraper_bordeauxasso'!B:B,0) -> #N/A
A12: 2016 | B12: UNION SPORTIVE LES CHARTRONS | C12: 896350 | D12: Locaux, équipements sportifs, matériel pour | E12: =MATCH(B12,'Copy of webscraper_bordeauxasso'!B:B,0) -> #N/A
A13: 2016 | B13: LES JEUNES DE SAINT AUGUSTIN - JSA | C13: 892663 | D13: Locaux, équipements sportifs, matériel pour | E13: =MATCH(B13,'Copy of webscraper_bordeauxasso'!B:B,0) -> #N/A
A14: 2016 | B14: UNION SAINT JEAN - MAISON DE QUARTIER | C14: 879983 | D14: Locaux, équipements sportifs, matériel pour | E14: =MATCH(B14,'Copy of webscraper_bordeauxasso'!B:B,0) -> #N/A
A15: 2016 | B15: STADE BORDELAIS - ASPTT | C15: 819458 | D15: Locaux, équipements sportifs, matériel pour | E15: =MATCH(B15,'Copy of webscraper_bordeauxasso'!B:B,0) -> #N/A
A16: 2016 | B16: ARC EN REVE | C16: 752250 | D16: Communication, matériel pour manifestations, locaux | E16: =MATCH(B16,'Copy of webscraper_bordeauxasso'!B:B,0) -> #N/A
A17: 2016 | B17: MAISON DE L'EMPLOI, DE L'INSERTION ECONOMIQUE ET DE L'ENTREPRISE DE BORDEAUX | C17: 678000 | E17: =MATCH(B17,'Copy of webscraper_bordeauxasso'!B:B,0) -> #N/A
A18: 2016 | B18: CLUB PYRENEES AQUITAINE, ASSOCIATION SPORTIVE, EDUCATIVE ET CULTURELLE | C18: 634600 | D18: Locaux, équipements sportifs, matériel pour | E18: =MATCH(B18,'Copy of webscraper_bordeauxasso'!B:B,0) -> #N/A
A19: 2016 | B19: P'TIT BOUT'CHOU | C19: 567000 | D19: Matériel pour manifestations | E19: =MATCH(B19,'Copy of webscraper_bordeauxasso'!B:B,0) -> #N/A
A20: 2016 | B20: ASSOCIATION BRINS D'EVEIL | C20: 532800 | E20: =MATCH(B20,'Copy of webscraper_bordeauxasso'!B:B,0) -> #N/A
A21: 2016 | B21: ASSOCIATION DE GESTION ET D'ANIMATION DES CRECHES C.S.F. (AGEAC/CSF) | C21: 512833.33 | E21: =MATCH(B21,'Copy of webscraper_bordeauxasso'!B:B,0) -> #N/A
A22: 2016 | B22: MISSION LOCALE BORDEAUX AVENIR JEUNES | C22: 494000 | D22: Locaux, matériel pour manifestations | E22: =MATCH(B22,'Copy of webscraper_bordeauxasso'!B:B,0) -> #N/A
A23: 2016 | B23: GP INTENCITE CENTRE SOCIAL ET CULTUREL DU GRAND PARC | C23: 492222 | D23: Locaux, matériel pour manifestations | E23: =MATCH(B23,'Copy of webscraper_bordeauxasso'!B:B,0) -> #N/A
A24: 2016 | B24: INTERLUDE | C24: 478850 | D24: Locaux, matériel pour manifestations | E24: =MATCH(B24,'Copy of webscraper_bordeauxasso'!B:B,0) -> #N/A
A25: 2016 | B25: CENTRE SOCIAL ET FAMILIAL BORDEAUX NORD | C25: 461165 | D25: Locaux, équipements sportifs, matériel pour | E25: =MATCH(B25,'Copy of webscraper_bordeauxasso'!B:B,0) -> #N/A
A26: 2016 | B26: AMICALE LAIQUE DAVID JOHNSTON LAGRANGE ALBERT BARRAUD NAUJAC | C26: 450195 | D26: Equipements sportifs | E26: =MATCH(B26,'Copy of webscraper_bordeauxasso'!B:B,0) -> #N/A
A27: 2016 | B27: SASP UNION BORDEAUX BEGLES | C27: 450000 | D27: Matériel pour manifestations | E27: =MATCH(B27,'Copy of webscraper_bordeauxasso'!B:B,0) -> #N/A
A28: 2016 | B28: FOYER FRATERNEL | C28: 426565 | D28: Locaux, matériel pour manifestations | E28: =MATCH(B28,'Copy of webscraper_bordeauxasso'!B:B,0) -> #N/A
A29: 2016 | B29: FESTIVAL DES ARTS DE BORDEAUX | C29: 402000 | D29: Communication, locaux | E29: =MATCH(B29,'Copy of webscraper_bordeauxasso'!B:B,0) -> #N/A
A30: 2016 | B30: ASSOCIATION DU COMITE DES OEUVRES SOCIALES DES MUNICIPAUX DE BORDEAUX - ACOSMB | C30: 380000 | D30: Matériel pour manifestations | E30: =MATCH(B30,'Copy of webscraper_bordeauxasso'!B:B,0) -> #N/A
A31: 2016 | B31: POLE D'ENSEIGNEMENT SUPERIEUR DE LA MUSIQUE ET DE LA DANSE DE BORDEAUX AQUITAINE - PESMD | C31: 357672 | D31: Locaux | E31: =MATCH(B31,'Copy of webscraper_bordeauxasso'!B:B,0) -> #N/A
A32: 2016 | B32: AUTEUIL PETITE ENFANCE | C32: 347000 | E32: =MATCH(B32,'Copy of webscraper_bordeauxasso'!B:B,0) -> #N/A
A33: 2016 | B33: LES COQS ROUGES | C33: 343924 | D33: Equipements sportifs, matériel pour manifestations | E33: =MATCH(B33,'Copy of webscraper_bordeauxasso'!B:B,0) -> #N/A
A34: 2016 | B34: BORDEAUX GRANDS EVENEMENTS (BGE) | C34: 339500 | D34: Communication, locaux | E34: =MATCH(B34,'Copy of webscraper_bordeauxasso'!B:B,0) -> #N/A
A35: 2016 | B35: GESTION DU CENTRE DE LOISIRS DE LA POSTE ALEMA | C35: 334000 | E35: =MATCH(B35,'Copy of webscraper_bordeauxasso'!B:B,0) -> #N/A
A36: 2016 | B36: ASSOCIATION PETITS BOUCHONS | C36: 311500 | E36: =MATCH(B36,'Copy of webscraper_bordeauxasso'!B:B,0) -> #N/A
A37: 2016 | B37: ASSOCIATION POUR L'INNOVATION EN MATIERE D'INTEGRATION | C37: 300000 | E37: =MATCH(B37,'Copy of webscraper_bordeauxasso'!B:B,0) -> #N/A
A38: 2016 | B38: BOXERS DE BORDEAUX | C38: 283000 | E38: =MATCH(B38,'Copy of webscraper_bordeauxasso'!B:B,0) -> #N/A
A39: 2016 | B39: SASP JSA BORDEAUX METROPOLE | C39: 280000 | D39: Matériel pour manifestations | E39: =MATCH(B39,'Copy of webscraper_bordeauxasso'!B:B,0) -> #N/A
A40: 2016 | B40: CLUB ATHLETIQUE MUNICIPAL DE BORDEAUX - CAM | C40: 243834 | D40: Locaux, équipements sportifs, matériel pour | E40: =MATCH(B40,'Copy of webscraper_bordeauxasso'!B:B,0) -> #N/A
...

Sheet Pivot Table 1

Sheet Copy of webscraper_bordeauxasso
A1: web-scraper-start-url | B1: nom | C1: description | D1: adresse | E1: code postal | F1: telephone | G1: president | H1: site web | I1: categorie
A2: https://assos.bordeaux.fr/association/detail/1857 | B2: PERCAL TANGO | C2: Promouvoir la culture argentine à travers la musique, la danse, le théâtre. Création et vente des spectacles vivants. | D2: 86 Cours Victor Hugo | E2: 33000 | F2: 05 40 05 22 45 | G2: null | H2: null | I2: null
A3: https://assos.bordeaux.fr/association/detail/634 | B3: ARTISANS DU MONDE BORDEAUX - ADM | C3: Promouvoir le commerce équitable afin de permettre aux producteurs de pays ou régions défavorisés de vivre dignement de leur travail et être acteur de leur développement. Permettre aux consommateurs d'être informés sur les dysfonctionnements du commerce international. Contribuer à changer les mécanismes du commerce international | D3: 30 rue du Parlement Saint Pierre | E3: 33000 | F3: 05 56 44 23 33 | G3: null | H3: admbordeaux.org | I3: Entraide, solidarité, humanitaire
A4: https://assos.bordeaux.fr/association/detail/955 | B4: CERCLE PHILATÉLIQUE BORDEAUX AQUITAINE - CPBA | C4: Association philatélique (collection de timbres) et marcophile (marques postales) atteignant une dizaine d'années d'existence forte de 160 membres actifs. Cette association est ouverte à tous les philatélistes débutants ou confirmés, de tous les âges. Ses adhérents ont la possibilité de se réunir pour échanger et chercher des pièces manquantes à leurs collections, 4 samedis par mois. | D4: 8 Rue de Blois Chez M. Langella | E4: 33600 | F4: 05 56 07 24 64 | G4: Gérard Langella | H4: null | I4: Loisirs
A5: https://assos.bordeaux.fr/association/detail/588 | B5: ALLO AMIANTE | C5: Défense des victimes de l'amiante et des victimes de maladies professionnelles faisant suite à une exposition aux autres agents cancérigènes ; prévention chez les particuliers et éradication de l'amiante | D5: 5 place, Amédée St Germain | E5: 33800 | F5: 05 56 91 60 69 | G5: Georges ARNAUDEAU | H5: null | I5: Santé, bien-être
A6: https://assos.bordeaux.fr/association/detail/680 | B6: CENTRE ACCUEIL CONSULTATION INFORMATION SEXUALITÉ - CACIS | C6: Dans une démarche d’éducation populaire, le CACIS se donne pour finalité de permettre à toute personne, jeune ou adulte, de trouver les moyens de vivre sa sexualité dans notre société et d’agir contre toute forme d’exclusion liée à la santé, à la sexualité et au genre. | D6: Place de l'Europe BP 44 | E6: 33030 | F6: 05 56 39 11 69 | G6: Brigitte Tandonnet | H6: cacis-pro.fr | I6: Santé, bien-être
A7: https://assos.bordeaux.fr/association/detail/1132 | B7: HANDI CAP NOUVELLE AQUITAINE - HCNA | C7: Handi CAP Nouvelle Aquitaine est une association loi 1901 qui a pour objet d'informer les personnes touchées et concernées par le handicap ou la perte d'autonomie sur les loisirs accessibles des secteurs du tourisme, de la culture, du sport présents en Nouvelle Aquitaine. Elle fait coopérer les partenaires de ces secteurs pour collecter et organiser la diffusion de ces informations. | D7: 436 av de Verdun | E7: 33700 | F7: 05 56 12 39 39 | G7: Patrick TREINS | H7: null | I7: null
A8: https://assos.bordeaux.fr/association/detail/1394 | B8: ASSOCIATION DES SAHRAOUIS À BORDEAUX - ASB | C8: Notre association a pour but de faire connaitre et reconnaître le peuple du Sahara Occidental, son histoire, sa culture, sa vie, son territoire et ses ressources auprès de l'opinion française et internationale. Mais aussi de soutenir les sahraouis dans les difficultés matérielles quotidiennes et dans la lutte pacifique vers la résolution du problème de décolonisation de leur pays. | D8: 9 bis cours Edouard Vaillant | E8: 33300 | F8: 06 05 90 55 41 | G8: Mohamed Salem Mohamed Brahim | H8: null | I8: Culture
A9: https://assos.bordeaux.fr/association/detail/1820 | B9: LES CRAYONNEUSES | C9: Action de médiation artistique, culturelle, bien-être. Création d'ouvrages et objets papiers. | D9: 3 chemin du Grand Port | E9: 33880 | F9: 06 87 19 99 02 | G9: null | H9: lescrayonneuses.com | I9: Santé, bien-être
A10: https://assos.bordeaux.fr/association/detail/515 | B10: OPÉRA BASTIDE - OB | C10: la compagnie Opéra Bastide représentait initialement un espace de création où l'apprentissage du métier se fait immédiatement par la scène, au contact du public, en dehors du cadre institutionnel. | D10: BP 24 BP 24 | E10: 33034 | F10: 06 58 52 19 58 | G10: null | H10: null | I10: Culture
A11: https://assos.bordeaux.fr/association/detail/713 | B11: ASSOCIATION DES AMIS D’ELIANE LAVAIL - AMIDEL | D11: pas d'adresse | G11: null | H11: null | I11: null
A12: https://assos.bordeaux.fr/association/detail/615 | B12: MAM'AN LES TI'BATEAUX | C12: L’objet de l’association de maison d’assistant(e)s maternel(le)s est le suivant : Création, ouverture et gestion d'une maison d'assistant(e)s maternel(le)s (M.A.M.) avec un projet de mixité dans l'accueil d'enfants non porteurs de handicaps âgés de deux mois et demi à quatre ans et d'enfants porteurs de handicaps ou atteints d'une maladie chronique âgés de deux mois et demi à six ans. | D12: 06 Place Philippe Lebon | E12: 33300 | F12: 06 79 08 95 93 | G12: Christine MOUNIER | I12: Education - Enfance - Jeunesse - Vie étudiante
A13: https://assos.bordeaux.fr/association/detail/1405 | B13: WINE WILD WEST | C13: L'association Wine Wild West a pour objet : l’organisation et la promotion d’un rassemblement annuel de danseurs de west coast swing en région bordelaise dénommé Wine Wild West. Ce rassemblement est un festival qui comprend des cours de danse et soirées de west coast swing. De plus le festival propose des découvertes œnologiques et de spécialités Bordelaises. | D13: 10 impasse Manes Chez Mme Dubernet | E13: 33110 | F13: 06 52 06 18 13 | G13: null | H13: www.winewildwest-bordeaux.fr | I13: Culture
A14: https://assos.bordeaux.fr/association/detail/1194 | B14: UNION SAINT-BRUNO - USB | C14: Favoriser la pratique du sport sous toutes ses formes au titre du loisir et/ou de la compétition. | D14: 49 rue Brizard | E14: 33000 | F14: 05 56 96 33 53 | G14: null | H14: www.saint-bruno.org | I14: Sport
A15: https://assos.bordeaux.fr/association/detail/1053 | B15: BXA - ESPRIT VOILE - BXA EV | C15: Proposer la découverte et le perfectionnement à la voile au départ de Bordeaux sur l'estuaire de la Gironde avec le voilier habitable de l’association (7,5 m ESTE 24). Développer, promouvoir et favoriser des activités à caractère culturel et sportif dans le domaine du nautisme avec comme champ d’action les bassins à flot de Bordeaux, la ville de Bordeaux et au delà. | D15: Bld Alfred DANEY Quai ouest Bassin à flot n° 2 | E15: 33300 | F15: 07 69 17 50 70 | G15: null | H15: www.bxaespritvoile.fr | I15: Sport
A16: https://assos.bordeaux.fr/association/detail/567 | B16: ASSOCIATION PARLECOUTER | C16: Enseigner l'apprentissage d'outils de communication bienveillante et respectueuse, basés sur l'écoute active, profonde et sans jugement, sur le développement de l'empathie, pour une meilleure compréhension de l'autre et de soi. L'association vise à créer des conditions favorables à l'éducation et l'accompagnement des enfants / adolescents, à instaurer des relations plus sereines en famille et en société. | D16: 11 rue du Palais Gallien, Appt A314 | E16: 33000 | F16: 06 78 66 97 33 | G16: null | H16: parlecouter.wixsite.com/bordeaux | I16: Education - Enfance - Jeunesse - Vie étudiante
A17: https://assos.bordeaux.fr/association/detail/1441 | B17: AIDOMI | C17: AIDOMI est une association d'aide et de soins à domicile organisée en Service Polyvalent d'Aide et de Soins à Domicile (SPASAD). Nos services accompagnent 24h /24h les personnes vulnérables et les proches aidants dans le maintien à domicile à travers des missions d'aide à domicile (entretien du domicile, préparation des repas, accompagnement à la vie sociale) et des soins infirmiers et d'hygiène. | D17: 22 rue professeur lannelongue | E17: 33300 | F17: 05 56 01 91 91 | G17: null | H17: aidomi.fr | I17: Santé, bien-être
A18: https://assos.bordeaux.fr/association/detail/796 | B18: ASSOCIATION FRANCO-JAPONAISE D'ÉCHANGES CULTURELS RIVAGES - RIVAGES | C18: L'association à pour but de développer les relations culturelles franco-japonaises pour un enrichissement mutuel par des actions de diffusion de la culture, du savoir faire et de l'art japonais (exposition, conférences, cours, pratiques artistiques et de bien être). | D18: 47 rue Jean Soula | E18: 33000 | F18: 05 47 29 56 30 | G18: null | H18: www.association-rivages.org | I18: Santé, bien-être
A19: https://assos.bordeaux.fr/association/detail/1317 | B19: PROMOFEMMES | C19: Insertion sociale, professionnelle, culturelle et citoyenne des femmes d’origine étrangère et de leur famille | D19: 10 rue Carpenteyre | E19: 33800 | F19: 05 56 94 64 07 | G19: null | H19: www.promofemmes.org | I19: Entraide, solidarité, humanitaire
A20: https://assos.bordeaux.fr/association/detail/1258 | B20: LE FESTIN | C20: Depuis près de trente ans, la revue le festin permet à un large public de découvrir les richesses artistiques du Sud-Ouest. Elle est aujourd’hui reconnue comme la première publication culturelle et touristique de la région. Du local à l’universel, des monuments historiques à la création la plus contemporaine, la revue trimestrielle défend en effet une vision dynamique et originale de la culture. | D20: 176 rue Achard Zone d'activités Achard - Bât F1 | E20: 33300 | F20: 05 56 69 72 46 | G20: null | H20: null | I20: Culture
A21: https://assos.bordeaux.fr/association/detail/1227 | B21: LES DETRITIVORES - DTTV | D21: pas d'adresse | G21: null | H21: null | I21: null
A22: https://assos.bordeaux.fr/association/detail/711 | B22: FRÈRES DES HOMMES - FDH | C22: La Pépinière de la solidarité internationale (créée par Frères des Hommes) est un dispositif d’accueil et d’accompagnement ouvert à tous ceux qui veulent mener un projet de solidarité internationale. Il s’adresse également à ceux qui souhaitent accompagner un ou plusieurs porteurs de projet dans leur démarche en devenant tuteur bénévole. | D22: 2 rue de Savoie 75006 Paris | E22: 33 | F22: 01 55 42 62 62 | G22: null | H22: www.fdh.org | I22: Entraide, solidarité, humanitaire
A23: https://assos.bordeaux.fr/association/detail/974 | B23: PHILOSPHÈRES | C23: Ouvrir un espace de réflexion philosophique aux enfants, adolescents, adultes : la proposition s’adresse à tous et s’inscrit dans une démarche culturelle durable et solidaire. Ateliers à visée philosophique pour enfants, pour adultes, événements sur la place publique, projet éditorial sur la mémoire, cinéphilo, écriture & poésie... La philosophie est un « terreau » qui favorise une existence harmonieuse pour tous. | D23: 6 rue Gaspard philippe | E23: 33800 | F23: 06 77 60 53 90 | G23: null | H23: www.philospheres.org | I23: Vivre ensemble, vie quotidienne
A24: https://assos.bordeaux.fr/association/detail/1199 | B24: UNION BORDEAUX MÉTROPOLE - UBM | C24: La présente association, sans but lucratif, a pour objet la pratique et l'organisation de toutes activités sportives, éducatives, culturelles, de loisirs, bien-être, gastronomiques. L’association est ouverte aux agents de la Mairie de Bordeaux, de la Métropole de Bordeaux (EPCI), et des communes membres de la Métropole, actifs et retraités ainsi qu’à leurs ayants droit et extérieurs (article 5). | D24: Hôtel de Bordeaux métropole Esplanade Charles de Gaulle | E24: 33045 | F24: 05 57 20 70 56 | G24: MARC JOKIEL | H24: null | I24: Loisirs
A25: https://assos.bordeaux.fr/association/detail/862 | B25: LES BALADES ALTERNATIVES | C25: L'Alternative Urbaine Bordeaux propose des balades pédestres alternatives à impact positif pour le territoire. D'une part, elles sortent des sentiers touristiques habituels en mettant en valeur des quartiers dits "populaires" ; D'autre part parce que ces balades sont animées par des "éclaireurs urbains" en insertion professionnelle que nous formons et rémunérons dans le cadre d'une activité tremplin vers l'emploi. | D25: 40 rue Laffiteau Chez Astrolabe | E25: 33800 | F25: 07 67 65 24 84 | G25: null | H25: bordeaux.alternative-urbaine.com | I25: Culture
A26: https://assos.bordeaux.fr/association/detail/1503 | B26: TEST 1809 | C26: Association test | D26: Rue Claude Bonnier | E26: 33000 | F26: 05 10 10 34 64 | G26: null | H26: null | I26: Vivre ensemble, vie quotidienne
A27: https://assos.bordeaux.fr/association/detail/598 | B27: ASSOCIATION ODYSSÉE | C27: Contribuer à l'engagement et à la participation de tous, pour renforcer la citoyenneté européenne et l'émergence de « citoyens du monde » Donner des clés de lecture pour appréhender la diversité et la complexité du monde actuel et développer l'apprentissage interculturel en promouvant et en mettant en œuvre des échanges européens et internationaux Faciliter le vivre ensemble et le travailler ensemble | D27: 5 rue Marengo | E27: 33000 | F27: 06 09 46 33 14 | G27: Elisabeth SILVA | H27: www.associationodyssee.fr | I27: Education - Enfance - Jeunesse - Vie étudiante
A28: https://assos.bordeaux.fr/association/detail/782 | B28: LA CLÉ DES ONDES | C28: Ouverte à toutes et tous, la Clé des Ondes est la radio qui se mouille pour qu'il fasse beau. Elle se fait l'écho du mouvement culturel, social, associatif, environnemental. D'ici et d'ailleurs, de toutes les couleurs, de toutes les nationalités, de toutes les musiques, de tout ce qui bouge, elle ouvre ses micros aux sans-voix. Elle s'écoute sur le 90.10 en FM et sur lacdo.org. | D28: 71 cours Edouard Vaillant | E28: 33300 | F28: 05 56 39 87 57 | G28: Gilbert Hanna | H28: www.lacdo.org | I28: Vivre ensemble, vie quotidienne
A29: https://assos.bordeaux.fr/association/detail/1042 | B29: OPTIMOMES LOISIRS | C29: Favoriser l'esprit de découverte chez les jeunes en leur proposant des programmes d'activités variées (Culture, sport, nature et science) ; promouvoir la pratique des activités sportives, artistiques, scientifiques et de nature en proposant la création de structures accueils ( écoles élémentaires/maternelles,CE) ; promouvoir grâce à des pratiques ludiques, la découverte de l'environnement auprès des enfants. | D29: 10 rue de la Moulinatte | E29: 33130 | F29: 05 56 85 53 14 | G29: null | H29: optimomesloisirs.com | I29: Education - Enfance - Jeunesse - Vie étudiante
A30: https://assos.bordeaux.fr/association/detail/1275 | B30: ATELIER D'ÉCO SOLIDAIRE - ADS | C30: La Recyclerie créative de Bordeaux est depuis 2010 un des leviers de l’innovation sociale territoriale dans la réutilisation de matières, objets et mobilier dont les usagers, les entreprises et les collectivités veulent se débarrasser. Par le travail croisé de salariés, de bénévoles de tous âges et de stagiaires de tous horizons, elle alimente une expérimentation concrète et et prône un retour au « bon sens ». | D30: 7 rue la Motte Picquet | E30: 33300 | F30: 05 56 10 46 19 | G30: null | H30: null | I30: Cadre de vie environnement
A31: https://assos.bordeaux.fr/association/detail/626 | B31: HÉLIOS EVENEMENTS - O S G | C31: Cette association a pour but de promouvoir et de développer les pratiques musicales : par la production de spectacles vivants les "Mini concerts'' comprenant la participation de l’orchestre symphonique de Gironde et de son activité de diffusion d’artistes ; par l’édition de supports informatifs et pédagogiques ; par l’organisation d’actions de formation musicale en favorisant les pratiques amateurs | D31: 2 rue Frédéric Bastiat | E31: 33100 | F31: 06 11 10 03 77 | G31: null | H31: orchestresymphoniquedegironde.fr | I31: Culture
A32: https://assos.bordeaux.fr/association/detail/1410 | B32: RIRE EN-JE - CLUB DE RIRE BX | C32: Amélioration du mieux être et des relations humaines notamment en faisant connaitre la méthode du Rire sans raison du Dr Kataria afin d'apporter de la joie de vivre, de la bonne humeur, et du bien être ; en connectant les personnes à travers le rire ; en trouvant du bonheur à rendre les gens heureux et en apportant de l'amour inconditionnel. | D32: 36 allée Haussmann | E32: 33300 | F32: 06 12 29 51 96 | G32: Pascale Senon | I32: Santé, bien-être
A33: https://assos.bordeaux.fr/association/detail/1576 | B33: ASSOCIATION FRANÇAISE DE RUGBY SUBAQUATIQUE - AFRS | C33: Développer la pratique du rugby subaquatique en France et favoriser la participation à des compétitions nationales et internationales. | D33: Rue Kléber | E33: 33800 | F33: 06 24 40 80 30 | G33: Anaïs De Chaumont | H33: null | I33: Sport
A34: https://assos.bordeaux.fr/association/detail/1734 | B34: LA CASSETTE | C34: La Cassette promeut I'art & la culture, crée des échanges sociaux & culturels, organise du spectacle vivant, des expositions, aide & conseille à la production musicale et le spectacle, conseille les lieux de diffusion à la programmation, résidence artistiques, accompagnement à l'enregistrement audio, accompagnement à la réalisation de vidéos, développement de projets artistiques... | D34: 55 rue Galin | E34: 33100 | F34: 06 84 31 45 04 | G34: milos ares asian teran | H34: null | I34: Culture
A35: https://assos.bordeaux.fr/association/detail/555 | B35: PRATIKABLE - PTK | C35: L'association Pratikable a pour but de valoriser et promouvoir le handicap à travers les sports de glisse et les sports à sensation. | D35: 13 Rue Charles Perrault | E35: 33370 | F35: 06 45 86 91 69 | G35: Wilfried Panatier | H35: www.pratikable.com | I35: Sport
A36: https://assos.bordeaux.fr/association/detail/1182 | B36: CULTIVER L'ÉQUILIBRE | C36: Accompagner, transmettre et promouvoir auprès de tout public différentes pratiques et techniques ayant pour objectif d’améliorer la santé (état de bien-être total physique, mental et social) et de permettre le développement personnel des personnes. Créer une dynamique de partage, d’échange et de mise en réseau de différents professionnels proposant ces pratiques. | D36: 147 avenue de Labarde | E36: 33300 | F36: 06 62 44 90 99 | G36: null | I36: Santé, bien-être
A37: https://assos.bordeaux.fr/association/detail/949 | B37: MOUVEMENT LE CRI | C37: Le Cri a pour objet de lutter contre toute forme de violences en particulier celles liées au système prostitutionnel. Elle se fixe une triple mission de prévention, d’information et de médiation. | D37: 58, rue Schoelcher | E37: 33300 | F37: 05 56 39 05 96 | G37: null | H37: null | I37: null
A38: https://assos.bordeaux.fr/association/detail/668 | B38: FÉDÉRATION DES RADIOS ASSOCIATIVES DE LA GIRONDE - FEDERA 33 | C38: Établir des échanges entre les radios, par des rencontres avec thème (échange de programmes, nouvelles technologies et numérique, gestion administrative, fonction employeur, droits d’auteur…) et en créer les outils de mise en œuvre. Aider les radios à la constitution des nombreux dossiers administratifs. Intervenir auprès de radios en difficulté par le conseil auprès de leurs instances dirigeantes. | D38: 153 rue David Johnston | E38: 33000 | F38: 06 52 84 62 80 | G38: Nicole Teyssier | H38: www.federa33.org/la-federa33 | I38: Culture
A39: https://assos.bordeaux.fr/association/detail/511 | B39: CALIXTE COEUR DE BASTIDE | C39: l association a pour but de créer et développer des animations et événements ,mener des réflexions,pour dynamiser la place CALIXTE CAMELLE et son quartier,en renforçant le lien social.De part son objet, l association peut être emmenée à exercer des activités économiques. | D39: le pti salon 60 rue bonnefin | E39: 33100 | F39: 06 61 18 87 34 | G39: null | H39: Facebook Facebook | I39: Vivre ensemble, vie quotidienne
A40: https://assos.bordeaux.fr/association/detail/982 | B40: LES PINSONS | C40: L'association Les Pinsons gère l'Institut Pinsons (première structure passerelle d'accueil des 2/6 ans inspirée de l'approche éducative et pédagogique de Reggio Emilia et du modèle scandinave de la petite enfance) et les ateliers Let's (le meilleur des pédagogies actives - Montessori, Reggio, Fröbel - associés à nos ateliers ludo-éducatifs : Code et robotique, cuisine, jardinage, jeux de société, arts plastiques...) | D40: 6 rue Jean Bedouret | E40: 33100 | F40: 06 95 48 28 48 | G40: Adeline Charneau | H40: www.institutpinsons.com | I40: Education - Enfance - Jeunesse - Vie étudiante
...
